[2024-07-27T13:25:48.979+0000] {local_task_job_runner.py:120} INFO - ::group::Pre task execution logs
[2024-07-27T13:25:49.142+0000] {taskinstance.py:2076} INFO - Dependencies all met for dep_context=non-requeueable deps ti=<TaskInstance: ETL_SofaScore_Matchday_daily.crawl_match_lineups scheduled__2023-08-01T00:00:00+00:00 [queued]>
[2024-07-27T13:25:49.175+0000] {taskinstance.py:2076} INFO - Dependencies all met for dep_context=requeueable deps ti=<TaskInstance: ETL_SofaScore_Matchday_daily.crawl_match_lineups scheduled__2023-08-01T00:00:00+00:00 [queued]>
[2024-07-27T13:25:49.177+0000] {taskinstance.py:2306} INFO - Starting attempt 1 of 2
[2024-07-27T13:25:50.201+0000] {taskinstance.py:2330} INFO - Executing <Task(PythonOperator): crawl_match_lineups> on 2023-08-01 00:00:00+00:00
[2024-07-27T13:25:50.256+0000] {warnings.py:110} WARNING - /home/***/.local/lib/python3.12/site-packages/***/task/task_runner/standard_task_runner.py:61: DeprecationWarning: This process (pid=151) is multi-threaded, use of fork() may lead to deadlocks in the child.
  pid = os.fork()

[2024-07-27T13:25:50.276+0000] {standard_task_runner.py:63} INFO - Started process 181 to run task
[2024-07-27T13:25:50.342+0000] {standard_task_runner.py:90} INFO - Running: ['***', 'tasks', 'run', 'ETL_SofaScore_Matchday_daily', 'crawl_match_lineups', 'scheduled__2023-08-01T00:00:00+00:00', '--job-id', '280', '--raw', '--subdir', 'DAGS_FOLDER/crawl_dags.py', '--cfg-path', '/tmp/tmpz_0wkm2v']
[2024-07-27T13:25:50.428+0000] {standard_task_runner.py:91} INFO - Job 280: Subtask crawl_match_lineups
[2024-07-27T13:25:51.512+0000] {task_command.py:426} INFO - Running <TaskInstance: ETL_SofaScore_Matchday_daily.crawl_match_lineups scheduled__2023-08-01T00:00:00+00:00 [running]> on host fde3e54b98e9
[2024-07-27T13:25:52.609+0000] {taskinstance.py:2648} INFO - Exporting env vars: AIRFLOW_CTX_DAG_EMAIL='nguyenmduc2407@gmail.com' AIRFLOW_CTX_DAG_OWNER='***' AIRFLOW_CTX_DAG_ID='ETL_SofaScore_Matchday_daily' AIRFLOW_CTX_TASK_ID='crawl_match_lineups' AIRFLOW_CTX_EXECUTION_DATE='2023-08-01T00:00:00+00:00' AIRFLOW_CTX_TRY_NUMBER='1' AIRFLOW_CTX_DAG_RUN_ID='scheduled__2023-08-01T00:00:00+00:00'
[2024-07-27T13:25:52.652+0000] {taskinstance.py:430} INFO - ::endgroup::
[2024-07-27T13:25:54.525+0000] {logging_mixin.py:188} INFO - Failed to fetch data for match ID 2. Status code: 404
[2024-07-27T13:25:56.868+0000] {logging_mixin.py:188} INFO - Failed to fetch data for match ID 0. Status code: 404
[2024-07-27T13:25:58.807+0000] {logging_mixin.py:188} INFO - Failed to fetch data for match ID 2. Status code: 404
[2024-07-27T13:26:00.865+0000] {logging_mixin.py:188} INFO - Failed to fetch data for match ID 3. Status code: 404
[2024-07-27T13:26:02.884+0000] {logging_mixin.py:188} INFO - Failed to fetch data for match ID -. Status code: 404
[2024-07-27T13:26:04.642+0000] {logging_mixin.py:188} INFO - Failed to fetch data for match ID 0. Status code: 404
[2024-07-27T13:26:06.634+0000] {logging_mixin.py:188} INFO - Failed to fetch data for match ID 8. Status code: 404
[2024-07-27T13:26:08.815+0000] {logging_mixin.py:188} INFO - Failed to fetch data for match ID -. Status code: 404
[2024-07-27T13:26:10.717+0000] {logging_mixin.py:188} INFO - Failed to fetch data for match ID 0. Status code: 404
[2024-07-27T13:26:12.726+0000] {logging_mixin.py:188} INFO - Failed to fetch data for match ID 1. Status code: 404
[2024-07-27T13:26:13.735+0000] {logging_mixin.py:188} INFO -   match_id  status_code
0        2          404
1        0          404
2        2          404
3        3          404
4        -          404
5        0          404
6        8          404
7        -          404
8        0          404
9        1          404
[2024-07-27T13:26:13.738+0000] {python.py:237} INFO - Done. Returned value was: None
[2024-07-27T13:26:13.739+0000] {taskinstance.py:441} INFO - ::group::Post task execution logs
[2024-07-27T13:26:13.748+0000] {taskinstance.py:1206} INFO - Marking task as SUCCESS. dag_id=ETL_SofaScore_Matchday_daily, task_id=crawl_match_lineups, run_id=scheduled__2023-08-01T00:00:00+00:00, execution_date=20230801T000000, start_date=20240727T132549, end_date=20240727T132613
[2024-07-27T13:26:13.784+0000] {local_task_job_runner.py:240} INFO - Task exited with return code 0
[2024-07-27T13:26:13.816+0000] {taskinstance.py:3498} INFO - 0 downstream tasks scheduled from follow-on schedule check
[2024-07-27T13:26:13.870+0000] {local_task_job_runner.py:222} INFO - ::endgroup::
[2024-07-27T15:20:01.866+0000] {local_task_job_runner.py:120} INFO - ::group::Pre task execution logs
[2024-07-27T15:20:02.078+0000] {taskinstance.py:2076} INFO - Dependencies all met for dep_context=non-requeueable deps ti=<TaskInstance: ETL_SofaScore_Matchday_daily.crawl_match_lineups scheduled__2023-08-01T00:00:00+00:00 [queued]>
[2024-07-27T15:20:02.192+0000] {taskinstance.py:2076} INFO - Dependencies all met for dep_context=requeueable deps ti=<TaskInstance: ETL_SofaScore_Matchday_daily.crawl_match_lineups scheduled__2023-08-01T00:00:00+00:00 [queued]>
[2024-07-27T15:20:02.200+0000] {taskinstance.py:2306} INFO - Starting attempt 1 of 2
[2024-07-27T15:20:03.241+0000] {taskinstance.py:2330} INFO - Executing <Task(PythonOperator): crawl_match_lineups> on 2023-08-01 00:00:00+00:00
[2024-07-27T15:20:03.328+0000] {warnings.py:110} WARNING - /home/***/.local/lib/python3.12/site-packages/***/task/task_runner/standard_task_runner.py:61: DeprecationWarning: This process (pid=1779) is multi-threaded, use of fork() may lead to deadlocks in the child.
  pid = os.fork()

[2024-07-27T15:20:03.345+0000] {standard_task_runner.py:63} INFO - Started process 1806 to run task
[2024-07-27T15:20:03.361+0000] {standard_task_runner.py:90} INFO - Running: ['***', 'tasks', 'run', 'ETL_SofaScore_Matchday_daily', 'crawl_match_lineups', 'scheduled__2023-08-01T00:00:00+00:00', '--job-id', '344', '--raw', '--subdir', 'DAGS_FOLDER/crawl_dags.py', '--cfg-path', '/tmp/tmpbh8_kdym']
[2024-07-27T15:20:03.385+0000] {standard_task_runner.py:91} INFO - Job 344: Subtask crawl_match_lineups
[2024-07-27T15:20:06.613+0000] {task_command.py:426} INFO - Running <TaskInstance: ETL_SofaScore_Matchday_daily.crawl_match_lineups scheduled__2023-08-01T00:00:00+00:00 [running]> on host fde3e54b98e9
[2024-07-27T15:20:07.471+0000] {taskinstance.py:2648} INFO - Exporting env vars: AIRFLOW_CTX_DAG_EMAIL='nguyenmduc2407@gmail.com' AIRFLOW_CTX_DAG_OWNER='***' AIRFLOW_CTX_DAG_ID='ETL_SofaScore_Matchday_daily' AIRFLOW_CTX_TASK_ID='crawl_match_lineups' AIRFLOW_CTX_EXECUTION_DATE='2023-08-01T00:00:00+00:00' AIRFLOW_CTX_TRY_NUMBER='1' AIRFLOW_CTX_DAG_RUN_ID='scheduled__2023-08-01T00:00:00+00:00'
[2024-07-27T15:20:07.481+0000] {taskinstance.py:430} INFO - ::endgroup::
[2024-07-27T15:20:08.789+0000] {logging_mixin.py:188} INFO - Failed to fetch data for match ID 2. Status code: 404
[2024-07-27T15:20:10.649+0000] {logging_mixin.py:188} INFO - Failed to fetch data for match ID 0. Status code: 404
[2024-07-27T15:20:12.663+0000] {logging_mixin.py:188} INFO - Failed to fetch data for match ID 2. Status code: 404
[2024-07-27T15:20:14.838+0000] {logging_mixin.py:188} INFO - Failed to fetch data for match ID 3. Status code: 404
[2024-07-27T15:20:16.744+0000] {logging_mixin.py:188} INFO - Failed to fetch data for match ID -. Status code: 404
[2024-07-27T15:20:18.646+0000] {logging_mixin.py:188} INFO - Failed to fetch data for match ID 0. Status code: 404
[2024-07-27T15:20:20.592+0000] {logging_mixin.py:188} INFO - Failed to fetch data for match ID 8. Status code: 404
[2024-07-27T15:20:22.498+0000] {logging_mixin.py:188} INFO - Failed to fetch data for match ID -. Status code: 404
[2024-07-27T15:20:24.469+0000] {logging_mixin.py:188} INFO - Failed to fetch data for match ID 0. Status code: 404
[2024-07-27T15:20:26.375+0000] {logging_mixin.py:188} INFO - Failed to fetch data for match ID 1. Status code: 404
[2024-07-27T15:20:27.384+0000] {logging_mixin.py:188} INFO -   match_id  status_code
0        2          404
1        0          404
2        2          404
3        3          404
4        -          404
5        0          404
6        8          404
7        -          404
8        0          404
9        1          404
[2024-07-27T15:20:27.472+0000] {logging_mixin.py:188} INFO - Data has been written to the database.
[2024-07-27T15:20:27.474+0000] {python.py:237} INFO - Done. Returned value was: None
[2024-07-27T15:20:27.476+0000] {taskinstance.py:441} INFO - ::group::Post task execution logs
[2024-07-27T15:20:27.487+0000] {taskinstance.py:1206} INFO - Marking task as SUCCESS. dag_id=ETL_SofaScore_Matchday_daily, task_id=crawl_match_lineups, run_id=scheduled__2023-08-01T00:00:00+00:00, execution_date=20230801T000000, start_date=20240727T152002, end_date=20240727T152027
[2024-07-27T15:20:27.519+0000] {local_task_job_runner.py:240} INFO - Task exited with return code 0
[2024-07-27T15:20:27.546+0000] {taskinstance.py:3498} INFO - 0 downstream tasks scheduled from follow-on schedule check
[2024-07-27T15:20:27.548+0000] {local_task_job_runner.py:222} INFO - ::endgroup::
[2024-07-27T16:43:08.206+0000] {local_task_job_runner.py:120} INFO - ::group::Pre task execution logs
[2024-07-27T16:43:08.293+0000] {taskinstance.py:2076} INFO - Dependencies all met for dep_context=non-requeueable deps ti=<TaskInstance: ETL_SofaScore_Matchday_daily.crawl_match_lineups scheduled__2023-08-01T00:00:00+00:00 [queued]>
[2024-07-27T16:43:08.314+0000] {taskinstance.py:2076} INFO - Dependencies all met for dep_context=requeueable deps ti=<TaskInstance: ETL_SofaScore_Matchday_daily.crawl_match_lineups scheduled__2023-08-01T00:00:00+00:00 [queued]>
[2024-07-27T16:43:08.315+0000] {taskinstance.py:2306} INFO - Starting attempt 1 of 2
[2024-07-27T16:43:10.036+0000] {taskinstance.py:2330} INFO - Executing <Task(PythonOperator): crawl_match_lineups> on 2023-08-01 00:00:00+00:00
[2024-07-27T16:43:10.046+0000] {warnings.py:110} WARNING - /home/***/.local/lib/python3.12/site-packages/***/task/task_runner/standard_task_runner.py:61: DeprecationWarning: This process (pid=3019) is multi-threaded, use of fork() may lead to deadlocks in the child.
  pid = os.fork()

[2024-07-27T16:43:10.048+0000] {standard_task_runner.py:63} INFO - Started process 3049 to run task
[2024-07-27T16:43:10.048+0000] {standard_task_runner.py:90} INFO - Running: ['***', 'tasks', 'run', 'ETL_SofaScore_Matchday_daily', 'crawl_match_lineups', 'scheduled__2023-08-01T00:00:00+00:00', '--job-id', '404', '--raw', '--subdir', 'DAGS_FOLDER/crawl_dags.py', '--cfg-path', '/tmp/tmphj5kx0wb']
[2024-07-27T16:43:10.051+0000] {standard_task_runner.py:91} INFO - Job 404: Subtask crawl_match_lineups
[2024-07-27T16:43:10.116+0000] {task_command.py:426} INFO - Running <TaskInstance: ETL_SofaScore_Matchday_daily.crawl_match_lineups scheduled__2023-08-01T00:00:00+00:00 [running]> on host fde3e54b98e9
[2024-07-27T16:43:10.255+0000] {taskinstance.py:2648} INFO - Exporting env vars: AIRFLOW_CTX_DAG_EMAIL='nguyenmduc2407@gmail.com' AIRFLOW_CTX_DAG_OWNER='***' AIRFLOW_CTX_DAG_ID='ETL_SofaScore_Matchday_daily' AIRFLOW_CTX_TASK_ID='crawl_match_lineups' AIRFLOW_CTX_EXECUTION_DATE='2023-08-01T00:00:00+00:00' AIRFLOW_CTX_TRY_NUMBER='1' AIRFLOW_CTX_DAG_RUN_ID='scheduled__2023-08-01T00:00:00+00:00'
[2024-07-27T16:43:10.257+0000] {taskinstance.py:430} INFO - ::endgroup::
[2024-07-27T16:43:10.285+0000] {taskinstance.py:441} INFO - ::group::Post task execution logs
[2024-07-27T16:43:10.286+0000] {taskinstance.py:2905} ERROR - Task failed with exception
Traceback (most recent call last):
  File "/home/airflow/.local/lib/python3.12/site-packages/airflow/models/taskinstance.py", line 465, in _execute_task
    result = _execute_callable(context=context, **execute_callable_kwargs)
             ^^^^^^^^^^^^^^^^^^^^^^^^^^^^^^^^^^^^^^^^^^^^^^^^^^^^^^^^^^^^^
  File "/home/airflow/.local/lib/python3.12/site-packages/airflow/models/taskinstance.py", line 432, in _execute_callable
    return execute_callable(context=context, **execute_callable_kwargs)
           ^^^^^^^^^^^^^^^^^^^^^^^^^^^^^^^^^^^^^^^^^^^^^^^^^^^^^^^^^^^^
  File "/home/airflow/.local/lib/python3.12/site-packages/airflow/models/baseoperator.py", line 400, in wrapper
    return func(self, *args, **kwargs)
           ^^^^^^^^^^^^^^^^^^^^^^^^^^^
  File "/home/airflow/.local/lib/python3.12/site-packages/airflow/operators/python.py", line 235, in execute
    return_value = self.execute_callable()
                   ^^^^^^^^^^^^^^^^^^^^^^^
  File "/home/airflow/.local/lib/python3.12/site-packages/airflow/operators/python.py", line 252, in execute_callable
    return self.python_callable(*self.op_args, **self.op_kwargs)
           ^^^^^^^^^^^^^^^^^^^^^^^^^^^^^^^^^^^^^^^^^^^^^^^^^^^^^
  File "/opt/airflow/dags/crawl_dags.py", line 376, in crawl_match_lineups
    date = kwargs['date']
           ~~~~~~^^^^^^^^
TypeError: tuple indices must be integers or slices, not str
[2024-07-27T16:43:10.307+0000] {taskinstance.py:1206} INFO - Marking task as UP_FOR_RETRY. dag_id=ETL_SofaScore_Matchday_daily, task_id=crawl_match_lineups, run_id=scheduled__2023-08-01T00:00:00+00:00, execution_date=20230801T000000, start_date=20240727T164308, end_date=20240727T164310
[2024-07-27T16:43:10.327+0000] {warnings.py:110} WARNING - /home/***/.local/lib/python3.12/site-packages/***/utils/email.py:154: RemovedInAirflow3Warning: Fetching SMTP credentials from configuration variables will be deprecated in a future release. Please set credentials using a connection instead.
  send_mime_email(e_from=mail_from, e_to=recipients, mime_msg=msg, conn_id=conn_id, dryrun=dryrun)

[2024-07-27T16:43:10.328+0000] {configuration.py:1050} WARNING - section/key [smtp/smtp_user] not found in config
[2024-07-27T16:43:10.329+0000] {email.py:271} INFO - Email alerting: attempt 1
[2024-07-27T16:43:10.339+0000] {configuration.py:1050} WARNING - section/key [smtp/smtp_user] not found in config
[2024-07-27T16:43:10.340+0000] {email.py:271} INFO - Email alerting: attempt 1
[2024-07-27T16:43:10.342+0000] {taskinstance.py:879} ERROR - Failed to send email to: nguyenmduc2407@gmail.com
Traceback (most recent call last):
  File "/home/airflow/.local/lib/python3.12/site-packages/airflow/models/taskinstance.py", line 2479, in _run_raw_task
    self._execute_task_with_callbacks(context, test_mode, session=session)
  File "/home/airflow/.local/lib/python3.12/site-packages/airflow/models/taskinstance.py", line 2676, in _execute_task_with_callbacks
    result = self._execute_task(context, task_orig)
             ^^^^^^^^^^^^^^^^^^^^^^^^^^^^^^^^^^^^^^
  File "/home/airflow/.local/lib/python3.12/site-packages/airflow/models/taskinstance.py", line 2701, in _execute_task
    return _execute_task(self, context, task_orig)
           ^^^^^^^^^^^^^^^^^^^^^^^^^^^^^^^^^^^^^^^
  File "/home/airflow/.local/lib/python3.12/site-packages/airflow/models/taskinstance.py", line 465, in _execute_task
    result = _execute_callable(context=context, **execute_callable_kwargs)
             ^^^^^^^^^^^^^^^^^^^^^^^^^^^^^^^^^^^^^^^^^^^^^^^^^^^^^^^^^^^^^
  File "/home/airflow/.local/lib/python3.12/site-packages/airflow/models/taskinstance.py", line 432, in _execute_callable
    return execute_callable(context=context, **execute_callable_kwargs)
           ^^^^^^^^^^^^^^^^^^^^^^^^^^^^^^^^^^^^^^^^^^^^^^^^^^^^^^^^^^^^
  File "/home/airflow/.local/lib/python3.12/site-packages/airflow/models/baseoperator.py", line 400, in wrapper
    return func(self, *args, **kwargs)
           ^^^^^^^^^^^^^^^^^^^^^^^^^^^
  File "/home/airflow/.local/lib/python3.12/site-packages/airflow/operators/python.py", line 235, in execute
    return_value = self.execute_callable()
                   ^^^^^^^^^^^^^^^^^^^^^^^
  File "/home/airflow/.local/lib/python3.12/site-packages/airflow/operators/python.py", line 252, in execute_callable
    return self.python_callable(*self.op_args, **self.op_kwargs)
           ^^^^^^^^^^^^^^^^^^^^^^^^^^^^^^^^^^^^^^^^^^^^^^^^^^^^^
  File "/opt/airflow/dags/crawl_dags.py", line 376, in crawl_match_lineups
    date = kwargs['date']
           ~~~~~~^^^^^^^^
TypeError: tuple indices must be integers or slices, not str

During handling of the above exception, another exception occurred:

Traceback (most recent call last):
  File "/home/airflow/.local/lib/python3.12/site-packages/airflow/models/taskinstance.py", line 1063, in _email_alert
    send_email(task.email, subject, html_content)
  File "/home/airflow/.local/lib/python3.12/site-packages/airflow/utils/email.py", line 80, in send_email
    return backend(
           ^^^^^^^^
  File "/home/airflow/.local/lib/python3.12/site-packages/airflow/utils/email.py", line 154, in send_email_smtp
    send_mime_email(e_from=mail_from, e_to=recipients, mime_msg=msg, conn_id=conn_id, dryrun=dryrun)
  File "/home/airflow/.local/lib/python3.12/site-packages/airflow/utils/email.py", line 273, in send_mime_email
    smtp_conn = _get_smtp_connection(smtp_host, smtp_port, smtp_timeout, smtp_ssl)
                ^^^^^^^^^^^^^^^^^^^^^^^^^^^^^^^^^^^^^^^^^^^^^^^^^^^^^^^^^^^^^^^^^^
  File "/home/airflow/.local/lib/python3.12/site-packages/airflow/utils/email.py", line 317, in _get_smtp_connection
    return smtplib.SMTP(host=host, port=port, timeout=timeout)
           ^^^^^^^^^^^^^^^^^^^^^^^^^^^^^^^^^^^^^^^^^^^^^^^^^^^
  File "/usr/local/lib/python3.12/smtplib.py", line 255, in __init__
    (code, msg) = self.connect(host, port)
                  ^^^^^^^^^^^^^^^^^^^^^^^^
  File "/usr/local/lib/python3.12/smtplib.py", line 341, in connect
    self.sock = self._get_socket(host, port, self.timeout)
                ^^^^^^^^^^^^^^^^^^^^^^^^^^^^^^^^^^^^^^^^^^
  File "/usr/local/lib/python3.12/smtplib.py", line 312, in _get_socket
    return socket.create_connection((host, port), timeout,
           ^^^^^^^^^^^^^^^^^^^^^^^^^^^^^^^^^^^^^^^^^^^^^^^
  File "/usr/local/lib/python3.12/socket.py", line 852, in create_connection
    raise exceptions[0]
  File "/usr/local/lib/python3.12/socket.py", line 837, in create_connection
    sock.connect(sa)
ConnectionRefusedError: [Errno 111] Connection refused

During handling of the above exception, another exception occurred:

Traceback (most recent call last):
  File "/home/airflow/.local/lib/python3.12/site-packages/airflow/models/taskinstance.py", line 877, in _handle_failure
    task_instance.email_alert(error, failure_context["task"])
  File "/home/airflow/.local/lib/python3.12/site-packages/airflow/models/taskinstance.py", line 3163, in email_alert
    _email_alert(task_instance=self, exception=exception, task=task)
  File "/home/airflow/.local/lib/python3.12/site-packages/airflow/models/taskinstance.py", line 1065, in _email_alert
    send_email(task.email, subject, html_content_err)
  File "/home/airflow/.local/lib/python3.12/site-packages/airflow/utils/email.py", line 80, in send_email
    return backend(
           ^^^^^^^^
  File "/home/airflow/.local/lib/python3.12/site-packages/airflow/utils/email.py", line 154, in send_email_smtp
    send_mime_email(e_from=mail_from, e_to=recipients, mime_msg=msg, conn_id=conn_id, dryrun=dryrun)
  File "/home/airflow/.local/lib/python3.12/site-packages/airflow/utils/email.py", line 273, in send_mime_email
    smtp_conn = _get_smtp_connection(smtp_host, smtp_port, smtp_timeout, smtp_ssl)
                ^^^^^^^^^^^^^^^^^^^^^^^^^^^^^^^^^^^^^^^^^^^^^^^^^^^^^^^^^^^^^^^^^^
  File "/home/airflow/.local/lib/python3.12/site-packages/airflow/utils/email.py", line 317, in _get_smtp_connection
    return smtplib.SMTP(host=host, port=port, timeout=timeout)
           ^^^^^^^^^^^^^^^^^^^^^^^^^^^^^^^^^^^^^^^^^^^^^^^^^^^
  File "/usr/local/lib/python3.12/smtplib.py", line 255, in __init__
    (code, msg) = self.connect(host, port)
                  ^^^^^^^^^^^^^^^^^^^^^^^^
  File "/usr/local/lib/python3.12/smtplib.py", line 341, in connect
    self.sock = self._get_socket(host, port, self.timeout)
                ^^^^^^^^^^^^^^^^^^^^^^^^^^^^^^^^^^^^^^^^^^
  File "/usr/local/lib/python3.12/smtplib.py", line 312, in _get_socket
    return socket.create_connection((host, port), timeout,
           ^^^^^^^^^^^^^^^^^^^^^^^^^^^^^^^^^^^^^^^^^^^^^^^
  File "/usr/local/lib/python3.12/socket.py", line 852, in create_connection
    raise exceptions[0]
  File "/usr/local/lib/python3.12/socket.py", line 837, in create_connection
    sock.connect(sa)
ConnectionRefusedError: [Errno 111] Connection refused
[2024-07-27T16:43:10.369+0000] {standard_task_runner.py:110} ERROR - Failed to execute job 404 for task crawl_match_lineups (tuple indices must be integers or slices, not str; 3049)
[2024-07-27T16:43:10.384+0000] {local_task_job_runner.py:240} INFO - Task exited with return code 1
[2024-07-27T16:43:10.411+0000] {taskinstance.py:3498} INFO - 0 downstream tasks scheduled from follow-on schedule check
[2024-07-27T16:43:10.415+0000] {local_task_job_runner.py:222} INFO - ::endgroup::
