[2024-07-27T15:09:12.247+0000] {local_task_job_runner.py:120} INFO - ::group::Pre task execution logs
[2024-07-27T15:09:12.306+0000] {taskinstance.py:2076} INFO - Dependencies all met for dep_context=non-requeueable deps ti=<TaskInstance: ETL_SofaScore_Matchday_daily.crawl_shotmap scheduled__2023-07-31T00:00:00+00:00 [queued]>
[2024-07-27T15:09:12.325+0000] {taskinstance.py:2076} INFO - Dependencies all met for dep_context=requeueable deps ti=<TaskInstance: ETL_SofaScore_Matchday_daily.crawl_shotmap scheduled__2023-07-31T00:00:00+00:00 [queued]>
[2024-07-27T15:09:12.326+0000] {taskinstance.py:2306} INFO - Starting attempt 2 of 3
[2024-07-27T15:09:13.079+0000] {taskinstance.py:2330} INFO - Executing <Task(PythonOperator): crawl_shotmap> on 2023-07-31 00:00:00+00:00
[2024-07-27T15:09:13.110+0000] {warnings.py:110} WARNING - /home/***/.local/lib/python3.12/site-packages/***/task/task_runner/standard_task_runner.py:61: DeprecationWarning: This process (pid=1592) is multi-threaded, use of fork() may lead to deadlocks in the child.
  pid = os.fork()

[2024-07-27T15:09:13.113+0000] {standard_task_runner.py:63} INFO - Started process 1606 to run task
[2024-07-27T15:09:13.123+0000] {standard_task_runner.py:90} INFO - Running: ['***', 'tasks', 'run', 'ETL_SofaScore_Matchday_daily', 'crawl_shotmap', 'scheduled__2023-07-31T00:00:00+00:00', '--job-id', '323', '--raw', '--subdir', 'DAGS_FOLDER/crawl_dags.py', '--cfg-path', '/tmp/tmpihd5nofp']
[2024-07-27T15:09:13.127+0000] {standard_task_runner.py:91} INFO - Job 323: Subtask crawl_shotmap
[2024-07-27T15:09:13.283+0000] {task_command.py:426} INFO - Running <TaskInstance: ETL_SofaScore_Matchday_daily.crawl_shotmap scheduled__2023-07-31T00:00:00+00:00 [running]> on host fde3e54b98e9
[2024-07-27T15:09:13.469+0000] {taskinstance.py:2648} INFO - Exporting env vars: AIRFLOW_CTX_DAG_EMAIL='nguyenmduc2407@gmail.com' AIRFLOW_CTX_DAG_OWNER='***' AIRFLOW_CTX_DAG_ID='ETL_SofaScore_Matchday_daily' AIRFLOW_CTX_TASK_ID='crawl_shotmap' AIRFLOW_CTX_EXECUTION_DATE='2023-07-31T00:00:00+00:00' AIRFLOW_CTX_TRY_NUMBER='2' AIRFLOW_CTX_DAG_RUN_ID='scheduled__2023-07-31T00:00:00+00:00'
[2024-07-27T15:09:13.472+0000] {taskinstance.py:430} INFO - ::endgroup::
[2024-07-27T15:09:14.537+0000] {logging_mixin.py:188} INFO - Failed to fetch data for match ID 2. Status code: 404
[2024-07-27T15:09:16.497+0000] {logging_mixin.py:188} INFO - Failed to fetch data for match ID 0. Status code: 404
[2024-07-27T15:09:18.399+0000] {logging_mixin.py:188} INFO - Failed to fetch data for match ID 2. Status code: 404
[2024-07-27T15:09:20.347+0000] {logging_mixin.py:188} INFO - Failed to fetch data for match ID 3. Status code: 404
[2024-07-27T15:09:22.321+0000] {logging_mixin.py:188} INFO - Failed to fetch data for match ID -. Status code: 404
[2024-07-27T15:09:24.475+0000] {logging_mixin.py:188} INFO - Failed to fetch data for match ID 0. Status code: 404
[2024-07-27T15:09:26.689+0000] {logging_mixin.py:188} INFO - Failed to fetch data for match ID 7. Status code: 404
[2024-07-27T15:09:28.868+0000] {logging_mixin.py:188} INFO - Failed to fetch data for match ID -. Status code: 404
[2024-07-27T15:09:30.775+0000] {logging_mixin.py:188} INFO - Failed to fetch data for match ID 3. Status code: 404
[2024-07-27T15:09:32.735+0000] {logging_mixin.py:188} INFO - Failed to fetch data for match ID 1. Status code: 404
[2024-07-27T15:09:33.750+0000] {logging_mixin.py:188} INFO -   match_id  status_code
0        2          404
1        0          404
2        2          404
3        3          404
4        -          404
5        0          404
6        7          404
7        -          404
8        3          404
9        1          404
[2024-07-27T15:09:33.851+0000] {logging_mixin.py:188} INFO - Data has been written to the database.
[2024-07-27T15:09:33.854+0000] {python.py:237} INFO - Done. Returned value was: None
[2024-07-27T15:09:33.856+0000] {taskinstance.py:441} INFO - ::group::Post task execution logs
[2024-07-27T15:09:33.865+0000] {taskinstance.py:1206} INFO - Marking task as SUCCESS. dag_id=ETL_SofaScore_Matchday_daily, task_id=crawl_shotmap, run_id=scheduled__2023-07-31T00:00:00+00:00, execution_date=20230731T000000, start_date=20240727T150912, end_date=20240727T150933
[2024-07-27T15:09:33.923+0000] {local_task_job_runner.py:240} INFO - Task exited with return code 0
[2024-07-27T15:09:33.942+0000] {taskinstance.py:3498} INFO - 1 downstream tasks scheduled from follow-on schedule check
[2024-07-27T15:09:33.945+0000] {local_task_job_runner.py:222} INFO - ::endgroup::
[2024-07-27T15:55:33.763+0000] {local_task_job_runner.py:120} INFO - ::group::Pre task execution logs
[2024-07-27T15:55:33.821+0000] {taskinstance.py:2076} INFO - Dependencies all met for dep_context=non-requeueable deps ti=<TaskInstance: ETL_SofaScore_Matchday_daily.crawl_shotmap scheduled__2023-07-31T00:00:00+00:00 [queued]>
[2024-07-27T15:55:33.838+0000] {taskinstance.py:2076} INFO - Dependencies all met for dep_context=requeueable deps ti=<TaskInstance: ETL_SofaScore_Matchday_daily.crawl_shotmap scheduled__2023-07-31T00:00:00+00:00 [queued]>
[2024-07-27T15:55:33.839+0000] {taskinstance.py:2306} INFO - Starting attempt 2 of 3
[2024-07-27T15:55:33.998+0000] {taskinstance.py:2330} INFO - Executing <Task(PythonOperator): crawl_shotmap> on 2023-07-31 00:00:00+00:00
[2024-07-27T15:55:34.005+0000] {warnings.py:110} WARNING - /home/***/.local/lib/python3.12/site-packages/***/task/task_runner/standard_task_runner.py:61: DeprecationWarning: This process (pid=2308) is multi-threaded, use of fork() may lead to deadlocks in the child.
  pid = os.fork()

[2024-07-27T15:55:34.007+0000] {standard_task_runner.py:63} INFO - Started process 2310 to run task
[2024-07-27T15:55:34.006+0000] {standard_task_runner.py:90} INFO - Running: ['***', 'tasks', 'run', 'ETL_SofaScore_Matchday_daily', 'crawl_shotmap', 'scheduled__2023-07-31T00:00:00+00:00', '--job-id', '363', '--raw', '--subdir', 'DAGS_FOLDER/crawl_dags.py', '--cfg-path', '/tmp/tmp6xu92y0h']
[2024-07-27T15:55:34.009+0000] {standard_task_runner.py:91} INFO - Job 363: Subtask crawl_shotmap
[2024-07-27T15:55:34.059+0000] {task_command.py:426} INFO - Running <TaskInstance: ETL_SofaScore_Matchday_daily.crawl_shotmap scheduled__2023-07-31T00:00:00+00:00 [running]> on host fde3e54b98e9
[2024-07-27T15:55:34.141+0000] {taskinstance.py:2648} INFO - Exporting env vars: AIRFLOW_CTX_DAG_EMAIL='nguyenmduc2407@gmail.com' AIRFLOW_CTX_DAG_OWNER='***' AIRFLOW_CTX_DAG_ID='ETL_SofaScore_Matchday_daily' AIRFLOW_CTX_TASK_ID='crawl_shotmap' AIRFLOW_CTX_EXECUTION_DATE='2023-07-31T00:00:00+00:00' AIRFLOW_CTX_TRY_NUMBER='2' AIRFLOW_CTX_DAG_RUN_ID='scheduled__2023-07-31T00:00:00+00:00'
[2024-07-27T15:55:34.143+0000] {taskinstance.py:430} INFO - ::endgroup::
[2024-07-27T15:55:34.168+0000] {taskinstance.py:441} INFO - ::group::Post task execution logs
[2024-07-27T15:55:34.169+0000] {taskinstance.py:2905} ERROR - Task failed with exception
Traceback (most recent call last):
  File "/home/airflow/.local/lib/python3.12/site-packages/airflow/models/taskinstance.py", line 465, in _execute_task
    result = _execute_callable(context=context, **execute_callable_kwargs)
             ^^^^^^^^^^^^^^^^^^^^^^^^^^^^^^^^^^^^^^^^^^^^^^^^^^^^^^^^^^^^^
  File "/home/airflow/.local/lib/python3.12/site-packages/airflow/models/taskinstance.py", line 432, in _execute_callable
    return execute_callable(context=context, **execute_callable_kwargs)
           ^^^^^^^^^^^^^^^^^^^^^^^^^^^^^^^^^^^^^^^^^^^^^^^^^^^^^^^^^^^^
  File "/home/airflow/.local/lib/python3.12/site-packages/airflow/models/baseoperator.py", line 400, in wrapper
    return func(self, *args, **kwargs)
           ^^^^^^^^^^^^^^^^^^^^^^^^^^^
  File "/home/airflow/.local/lib/python3.12/site-packages/airflow/operators/python.py", line 235, in execute
    return_value = self.execute_callable()
                   ^^^^^^^^^^^^^^^^^^^^^^^
  File "/home/airflow/.local/lib/python3.12/site-packages/airflow/operators/python.py", line 252, in execute_callable
    return self.python_callable(*self.op_args, **self.op_kwargs)
           ^^^^^^^^^^^^^^^^^^^^^^^^^^^^^^^^^^^^^^^^^^^^^^^^^^^^^
  File "/opt/airflow/dags/crawl_dags.py", line 362, in crawl_shotmap
    match_ids, _ = ti.xcom_pull(task_ids='crawl_data')
    ^^^^^^^^^^^^
TypeError: cannot unpack non-iterable NoneType object
[2024-07-27T15:55:34.181+0000] {taskinstance.py:1206} INFO - Marking task as UP_FOR_RETRY. dag_id=ETL_SofaScore_Matchday_daily, task_id=crawl_shotmap, run_id=scheduled__2023-07-31T00:00:00+00:00, execution_date=20230731T000000, start_date=20240727T155533, end_date=20240727T155534
[2024-07-27T15:55:34.196+0000] {warnings.py:110} WARNING - /home/***/.local/lib/python3.12/site-packages/***/utils/email.py:154: RemovedInAirflow3Warning: Fetching SMTP credentials from configuration variables will be deprecated in a future release. Please set credentials using a connection instead.
  send_mime_email(e_from=mail_from, e_to=recipients, mime_msg=msg, conn_id=conn_id, dryrun=dryrun)

[2024-07-27T15:55:34.197+0000] {configuration.py:1050} WARNING - section/key [smtp/smtp_user] not found in config
[2024-07-27T15:55:34.198+0000] {email.py:271} INFO - Email alerting: attempt 1
[2024-07-27T15:55:34.206+0000] {configuration.py:1050} WARNING - section/key [smtp/smtp_user] not found in config
[2024-07-27T15:55:34.206+0000] {email.py:271} INFO - Email alerting: attempt 1
[2024-07-27T15:55:34.207+0000] {taskinstance.py:879} ERROR - Failed to send email to: nguyenmduc2407@gmail.com
Traceback (most recent call last):
  File "/home/airflow/.local/lib/python3.12/site-packages/airflow/models/taskinstance.py", line 2479, in _run_raw_task
    self._execute_task_with_callbacks(context, test_mode, session=session)
  File "/home/airflow/.local/lib/python3.12/site-packages/airflow/models/taskinstance.py", line 2676, in _execute_task_with_callbacks
    result = self._execute_task(context, task_orig)
             ^^^^^^^^^^^^^^^^^^^^^^^^^^^^^^^^^^^^^^
  File "/home/airflow/.local/lib/python3.12/site-packages/airflow/models/taskinstance.py", line 2701, in _execute_task
    return _execute_task(self, context, task_orig)
           ^^^^^^^^^^^^^^^^^^^^^^^^^^^^^^^^^^^^^^^
  File "/home/airflow/.local/lib/python3.12/site-packages/airflow/models/taskinstance.py", line 465, in _execute_task
    result = _execute_callable(context=context, **execute_callable_kwargs)
             ^^^^^^^^^^^^^^^^^^^^^^^^^^^^^^^^^^^^^^^^^^^^^^^^^^^^^^^^^^^^^
  File "/home/airflow/.local/lib/python3.12/site-packages/airflow/models/taskinstance.py", line 432, in _execute_callable
    return execute_callable(context=context, **execute_callable_kwargs)
           ^^^^^^^^^^^^^^^^^^^^^^^^^^^^^^^^^^^^^^^^^^^^^^^^^^^^^^^^^^^^
  File "/home/airflow/.local/lib/python3.12/site-packages/airflow/models/baseoperator.py", line 400, in wrapper
    return func(self, *args, **kwargs)
           ^^^^^^^^^^^^^^^^^^^^^^^^^^^
  File "/home/airflow/.local/lib/python3.12/site-packages/airflow/operators/python.py", line 235, in execute
    return_value = self.execute_callable()
                   ^^^^^^^^^^^^^^^^^^^^^^^
  File "/home/airflow/.local/lib/python3.12/site-packages/airflow/operators/python.py", line 252, in execute_callable
    return self.python_callable(*self.op_args, **self.op_kwargs)
           ^^^^^^^^^^^^^^^^^^^^^^^^^^^^^^^^^^^^^^^^^^^^^^^^^^^^^
  File "/opt/airflow/dags/crawl_dags.py", line 362, in crawl_shotmap
    match_ids, _ = ti.xcom_pull(task_ids='crawl_data')
    ^^^^^^^^^^^^
TypeError: cannot unpack non-iterable NoneType object

During handling of the above exception, another exception occurred:

Traceback (most recent call last):
  File "/home/airflow/.local/lib/python3.12/site-packages/airflow/models/taskinstance.py", line 1063, in _email_alert
    send_email(task.email, subject, html_content)
  File "/home/airflow/.local/lib/python3.12/site-packages/airflow/utils/email.py", line 80, in send_email
    return backend(
           ^^^^^^^^
  File "/home/airflow/.local/lib/python3.12/site-packages/airflow/utils/email.py", line 154, in send_email_smtp
    send_mime_email(e_from=mail_from, e_to=recipients, mime_msg=msg, conn_id=conn_id, dryrun=dryrun)
  File "/home/airflow/.local/lib/python3.12/site-packages/airflow/utils/email.py", line 273, in send_mime_email
    smtp_conn = _get_smtp_connection(smtp_host, smtp_port, smtp_timeout, smtp_ssl)
                ^^^^^^^^^^^^^^^^^^^^^^^^^^^^^^^^^^^^^^^^^^^^^^^^^^^^^^^^^^^^^^^^^^
  File "/home/airflow/.local/lib/python3.12/site-packages/airflow/utils/email.py", line 317, in _get_smtp_connection
    return smtplib.SMTP(host=host, port=port, timeout=timeout)
           ^^^^^^^^^^^^^^^^^^^^^^^^^^^^^^^^^^^^^^^^^^^^^^^^^^^
  File "/usr/local/lib/python3.12/smtplib.py", line 255, in __init__
    (code, msg) = self.connect(host, port)
                  ^^^^^^^^^^^^^^^^^^^^^^^^
  File "/usr/local/lib/python3.12/smtplib.py", line 341, in connect
    self.sock = self._get_socket(host, port, self.timeout)
                ^^^^^^^^^^^^^^^^^^^^^^^^^^^^^^^^^^^^^^^^^^
  File "/usr/local/lib/python3.12/smtplib.py", line 312, in _get_socket
    return socket.create_connection((host, port), timeout,
           ^^^^^^^^^^^^^^^^^^^^^^^^^^^^^^^^^^^^^^^^^^^^^^^
  File "/usr/local/lib/python3.12/socket.py", line 852, in create_connection
    raise exceptions[0]
  File "/usr/local/lib/python3.12/socket.py", line 837, in create_connection
    sock.connect(sa)
ConnectionRefusedError: [Errno 111] Connection refused

During handling of the above exception, another exception occurred:

Traceback (most recent call last):
  File "/home/airflow/.local/lib/python3.12/site-packages/airflow/models/taskinstance.py", line 877, in _handle_failure
    task_instance.email_alert(error, failure_context["task"])
  File "/home/airflow/.local/lib/python3.12/site-packages/airflow/models/taskinstance.py", line 3163, in email_alert
    _email_alert(task_instance=self, exception=exception, task=task)
  File "/home/airflow/.local/lib/python3.12/site-packages/airflow/models/taskinstance.py", line 1065, in _email_alert
    send_email(task.email, subject, html_content_err)
  File "/home/airflow/.local/lib/python3.12/site-packages/airflow/utils/email.py", line 80, in send_email
    return backend(
           ^^^^^^^^
  File "/home/airflow/.local/lib/python3.12/site-packages/airflow/utils/email.py", line 154, in send_email_smtp
    send_mime_email(e_from=mail_from, e_to=recipients, mime_msg=msg, conn_id=conn_id, dryrun=dryrun)
  File "/home/airflow/.local/lib/python3.12/site-packages/airflow/utils/email.py", line 273, in send_mime_email
    smtp_conn = _get_smtp_connection(smtp_host, smtp_port, smtp_timeout, smtp_ssl)
                ^^^^^^^^^^^^^^^^^^^^^^^^^^^^^^^^^^^^^^^^^^^^^^^^^^^^^^^^^^^^^^^^^^
  File "/home/airflow/.local/lib/python3.12/site-packages/airflow/utils/email.py", line 317, in _get_smtp_connection
    return smtplib.SMTP(host=host, port=port, timeout=timeout)
           ^^^^^^^^^^^^^^^^^^^^^^^^^^^^^^^^^^^^^^^^^^^^^^^^^^^
  File "/usr/local/lib/python3.12/smtplib.py", line 255, in __init__
    (code, msg) = self.connect(host, port)
                  ^^^^^^^^^^^^^^^^^^^^^^^^
  File "/usr/local/lib/python3.12/smtplib.py", line 341, in connect
    self.sock = self._get_socket(host, port, self.timeout)
                ^^^^^^^^^^^^^^^^^^^^^^^^^^^^^^^^^^^^^^^^^^
  File "/usr/local/lib/python3.12/smtplib.py", line 312, in _get_socket
    return socket.create_connection((host, port), timeout,
           ^^^^^^^^^^^^^^^^^^^^^^^^^^^^^^^^^^^^^^^^^^^^^^^
  File "/usr/local/lib/python3.12/socket.py", line 852, in create_connection
    raise exceptions[0]
  File "/usr/local/lib/python3.12/socket.py", line 837, in create_connection
    sock.connect(sa)
ConnectionRefusedError: [Errno 111] Connection refused
[2024-07-27T15:55:34.225+0000] {standard_task_runner.py:110} ERROR - Failed to execute job 363 for task crawl_shotmap (cannot unpack non-iterable NoneType object; 2310)
[2024-07-27T15:55:34.262+0000] {local_task_job_runner.py:240} INFO - Task exited with return code 1
[2024-07-27T15:55:34.286+0000] {taskinstance.py:3498} INFO - 0 downstream tasks scheduled from follow-on schedule check
[2024-07-27T15:55:34.289+0000] {local_task_job_runner.py:222} INFO - ::endgroup::
[2024-07-27T17:26:33.098+0000] {local_task_job_runner.py:120} INFO - ::group::Pre task execution logs
[2024-07-27T17:26:33.155+0000] {taskinstance.py:2076} INFO - Dependencies all met for dep_context=non-requeueable deps ti=<TaskInstance: ETL_SofaScore_Matchday_daily.crawl_shotmap scheduled__2023-07-31T00:00:00+00:00 [queued]>
[2024-07-27T17:26:33.183+0000] {taskinstance.py:2076} INFO - Dependencies all met for dep_context=requeueable deps ti=<TaskInstance: ETL_SofaScore_Matchday_daily.crawl_shotmap scheduled__2023-07-31T00:00:00+00:00 [queued]>
[2024-07-27T17:26:33.185+0000] {taskinstance.py:2306} INFO - Starting attempt 2 of 3
[2024-07-27T17:26:33.703+0000] {taskinstance.py:2330} INFO - Executing <Task(PythonOperator): crawl_shotmap> on 2023-07-31 00:00:00+00:00
[2024-07-27T17:26:33.727+0000] {warnings.py:110} WARNING - /home/***/.local/lib/python3.12/site-packages/***/task/task_runner/standard_task_runner.py:61: DeprecationWarning: This process (pid=3665) is multi-threaded, use of fork() may lead to deadlocks in the child.
  pid = os.fork()

[2024-07-27T17:26:33.733+0000] {standard_task_runner.py:63} INFO - Started process 3680 to run task
[2024-07-27T17:26:33.733+0000] {standard_task_runner.py:90} INFO - Running: ['***', 'tasks', 'run', 'ETL_SofaScore_Matchday_daily', 'crawl_shotmap', 'scheduled__2023-07-31T00:00:00+00:00', '--job-id', '427', '--raw', '--subdir', 'DAGS_FOLDER/crawl_dags.py', '--cfg-path', '/tmp/tmp00qapn75']
[2024-07-27T17:26:33.738+0000] {standard_task_runner.py:91} INFO - Job 427: Subtask crawl_shotmap
[2024-07-27T17:26:33.857+0000] {task_command.py:426} INFO - Running <TaskInstance: ETL_SofaScore_Matchday_daily.crawl_shotmap scheduled__2023-07-31T00:00:00+00:00 [running]> on host fde3e54b98e9
[2024-07-27T17:26:34.068+0000] {taskinstance.py:2648} INFO - Exporting env vars: AIRFLOW_CTX_DAG_EMAIL='nguyenmduc2407@gmail.com' AIRFLOW_CTX_DAG_OWNER='***' AIRFLOW_CTX_DAG_ID='ETL_SofaScore_Matchday_daily' AIRFLOW_CTX_TASK_ID='crawl_shotmap' AIRFLOW_CTX_EXECUTION_DATE='2023-07-31T00:00:00+00:00' AIRFLOW_CTX_TRY_NUMBER='2' AIRFLOW_CTX_DAG_RUN_ID='scheduled__2023-07-31T00:00:00+00:00'
[2024-07-27T17:26:34.074+0000] {taskinstance.py:430} INFO - ::endgroup::
[2024-07-27T17:26:34.123+0000] {taskinstance.py:441} INFO - ::group::Post task execution logs
[2024-07-27T17:26:34.126+0000] {taskinstance.py:2905} ERROR - Task failed with exception
Traceback (most recent call last):
  File "/home/airflow/.local/lib/python3.12/site-packages/airflow/models/taskinstance.py", line 465, in _execute_task
    result = _execute_callable(context=context, **execute_callable_kwargs)
             ^^^^^^^^^^^^^^^^^^^^^^^^^^^^^^^^^^^^^^^^^^^^^^^^^^^^^^^^^^^^^
  File "/home/airflow/.local/lib/python3.12/site-packages/airflow/models/taskinstance.py", line 432, in _execute_callable
    return execute_callable(context=context, **execute_callable_kwargs)
           ^^^^^^^^^^^^^^^^^^^^^^^^^^^^^^^^^^^^^^^^^^^^^^^^^^^^^^^^^^^^
  File "/home/airflow/.local/lib/python3.12/site-packages/airflow/models/baseoperator.py", line 400, in wrapper
    return func(self, *args, **kwargs)
           ^^^^^^^^^^^^^^^^^^^^^^^^^^^
  File "/home/airflow/.local/lib/python3.12/site-packages/airflow/operators/python.py", line 235, in execute
    return_value = self.execute_callable()
                   ^^^^^^^^^^^^^^^^^^^^^^^
  File "/home/airflow/.local/lib/python3.12/site-packages/airflow/operators/python.py", line 252, in execute_callable
    return self.python_callable(*self.op_args, **self.op_kwargs)
           ^^^^^^^^^^^^^^^^^^^^^^^^^^^^^^^^^^^^^^^^^^^^^^^^^^^^^
  File "/opt/airflow/dags/crawl_dags.py", line 396, in crawl_shotmap
    return crawler.shotmap()
           ^^^^^^^^^^^^^^^^^
  File "/opt/airflow/dags/crawl_dags.py", line 42, in shotmap
    matchday = pd.read_id()
               ^^^^^^^^^^
AttributeError: module 'pandas' has no attribute 'read_id'. Did you mean: 'read_hdf'?
[2024-07-27T17:26:34.178+0000] {taskinstance.py:1206} INFO - Marking task as UP_FOR_RETRY. dag_id=ETL_SofaScore_Matchday_daily, task_id=crawl_shotmap, run_id=scheduled__2023-07-31T00:00:00+00:00, execution_date=20230731T000000, start_date=20240727T172633, end_date=20240727T172634
[2024-07-27T17:26:34.204+0000] {warnings.py:110} WARNING - /home/***/.local/lib/python3.12/site-packages/***/utils/email.py:154: RemovedInAirflow3Warning: Fetching SMTP credentials from configuration variables will be deprecated in a future release. Please set credentials using a connection instead.
  send_mime_email(e_from=mail_from, e_to=recipients, mime_msg=msg, conn_id=conn_id, dryrun=dryrun)

[2024-07-27T17:26:34.206+0000] {configuration.py:1050} WARNING - section/key [smtp/smtp_user] not found in config
[2024-07-27T17:26:34.208+0000] {email.py:271} INFO - Email alerting: attempt 1
[2024-07-27T17:26:34.226+0000] {configuration.py:1050} WARNING - section/key [smtp/smtp_user] not found in config
[2024-07-27T17:26:34.227+0000] {email.py:271} INFO - Email alerting: attempt 1
[2024-07-27T17:26:34.233+0000] {taskinstance.py:879} ERROR - Failed to send email to: nguyenmduc2407@gmail.com
Traceback (most recent call last):
  File "/home/airflow/.local/lib/python3.12/site-packages/airflow/models/taskinstance.py", line 2479, in _run_raw_task
    self._execute_task_with_callbacks(context, test_mode, session=session)
  File "/home/airflow/.local/lib/python3.12/site-packages/airflow/models/taskinstance.py", line 2676, in _execute_task_with_callbacks
    result = self._execute_task(context, task_orig)
             ^^^^^^^^^^^^^^^^^^^^^^^^^^^^^^^^^^^^^^
  File "/home/airflow/.local/lib/python3.12/site-packages/airflow/models/taskinstance.py", line 2701, in _execute_task
    return _execute_task(self, context, task_orig)
           ^^^^^^^^^^^^^^^^^^^^^^^^^^^^^^^^^^^^^^^
  File "/home/airflow/.local/lib/python3.12/site-packages/airflow/models/taskinstance.py", line 465, in _execute_task
    result = _execute_callable(context=context, **execute_callable_kwargs)
             ^^^^^^^^^^^^^^^^^^^^^^^^^^^^^^^^^^^^^^^^^^^^^^^^^^^^^^^^^^^^^
  File "/home/airflow/.local/lib/python3.12/site-packages/airflow/models/taskinstance.py", line 432, in _execute_callable
    return execute_callable(context=context, **execute_callable_kwargs)
           ^^^^^^^^^^^^^^^^^^^^^^^^^^^^^^^^^^^^^^^^^^^^^^^^^^^^^^^^^^^^
  File "/home/airflow/.local/lib/python3.12/site-packages/airflow/models/baseoperator.py", line 400, in wrapper
    return func(self, *args, **kwargs)
           ^^^^^^^^^^^^^^^^^^^^^^^^^^^
  File "/home/airflow/.local/lib/python3.12/site-packages/airflow/operators/python.py", line 235, in execute
    return_value = self.execute_callable()
                   ^^^^^^^^^^^^^^^^^^^^^^^
  File "/home/airflow/.local/lib/python3.12/site-packages/airflow/operators/python.py", line 252, in execute_callable
    return self.python_callable(*self.op_args, **self.op_kwargs)
           ^^^^^^^^^^^^^^^^^^^^^^^^^^^^^^^^^^^^^^^^^^^^^^^^^^^^^
  File "/opt/airflow/dags/crawl_dags.py", line 396, in crawl_shotmap
    return crawler.shotmap()
           ^^^^^^^^^^^^^^^^^
  File "/opt/airflow/dags/crawl_dags.py", line 42, in shotmap
    matchday = pd.read_id()
               ^^^^^^^^^^
AttributeError: module 'pandas' has no attribute 'read_id'. Did you mean: 'read_hdf'?

During handling of the above exception, another exception occurred:

Traceback (most recent call last):
  File "/home/airflow/.local/lib/python3.12/site-packages/airflow/models/taskinstance.py", line 1063, in _email_alert
    send_email(task.email, subject, html_content)
  File "/home/airflow/.local/lib/python3.12/site-packages/airflow/utils/email.py", line 80, in send_email
    return backend(
           ^^^^^^^^
  File "/home/airflow/.local/lib/python3.12/site-packages/airflow/utils/email.py", line 154, in send_email_smtp
    send_mime_email(e_from=mail_from, e_to=recipients, mime_msg=msg, conn_id=conn_id, dryrun=dryrun)
  File "/home/airflow/.local/lib/python3.12/site-packages/airflow/utils/email.py", line 273, in send_mime_email
    smtp_conn = _get_smtp_connection(smtp_host, smtp_port, smtp_timeout, smtp_ssl)
                ^^^^^^^^^^^^^^^^^^^^^^^^^^^^^^^^^^^^^^^^^^^^^^^^^^^^^^^^^^^^^^^^^^
  File "/home/airflow/.local/lib/python3.12/site-packages/airflow/utils/email.py", line 317, in _get_smtp_connection
    return smtplib.SMTP(host=host, port=port, timeout=timeout)
           ^^^^^^^^^^^^^^^^^^^^^^^^^^^^^^^^^^^^^^^^^^^^^^^^^^^
  File "/usr/local/lib/python3.12/smtplib.py", line 255, in __init__
    (code, msg) = self.connect(host, port)
                  ^^^^^^^^^^^^^^^^^^^^^^^^
  File "/usr/local/lib/python3.12/smtplib.py", line 341, in connect
    self.sock = self._get_socket(host, port, self.timeout)
                ^^^^^^^^^^^^^^^^^^^^^^^^^^^^^^^^^^^^^^^^^^
  File "/usr/local/lib/python3.12/smtplib.py", line 312, in _get_socket
    return socket.create_connection((host, port), timeout,
           ^^^^^^^^^^^^^^^^^^^^^^^^^^^^^^^^^^^^^^^^^^^^^^^
  File "/usr/local/lib/python3.12/socket.py", line 852, in create_connection
    raise exceptions[0]
  File "/usr/local/lib/python3.12/socket.py", line 837, in create_connection
    sock.connect(sa)
ConnectionRefusedError: [Errno 111] Connection refused

During handling of the above exception, another exception occurred:

Traceback (most recent call last):
  File "/home/airflow/.local/lib/python3.12/site-packages/airflow/models/taskinstance.py", line 877, in _handle_failure
    task_instance.email_alert(error, failure_context["task"])
  File "/home/airflow/.local/lib/python3.12/site-packages/airflow/models/taskinstance.py", line 3163, in email_alert
    _email_alert(task_instance=self, exception=exception, task=task)
  File "/home/airflow/.local/lib/python3.12/site-packages/airflow/models/taskinstance.py", line 1065, in _email_alert
    send_email(task.email, subject, html_content_err)
  File "/home/airflow/.local/lib/python3.12/site-packages/airflow/utils/email.py", line 80, in send_email
    return backend(
           ^^^^^^^^
  File "/home/airflow/.local/lib/python3.12/site-packages/airflow/utils/email.py", line 154, in send_email_smtp
    send_mime_email(e_from=mail_from, e_to=recipients, mime_msg=msg, conn_id=conn_id, dryrun=dryrun)
  File "/home/airflow/.local/lib/python3.12/site-packages/airflow/utils/email.py", line 273, in send_mime_email
    smtp_conn = _get_smtp_connection(smtp_host, smtp_port, smtp_timeout, smtp_ssl)
                ^^^^^^^^^^^^^^^^^^^^^^^^^^^^^^^^^^^^^^^^^^^^^^^^^^^^^^^^^^^^^^^^^^
  File "/home/airflow/.local/lib/python3.12/site-packages/airflow/utils/email.py", line 317, in _get_smtp_connection
    return smtplib.SMTP(host=host, port=port, timeout=timeout)
           ^^^^^^^^^^^^^^^^^^^^^^^^^^^^^^^^^^^^^^^^^^^^^^^^^^^
  File "/usr/local/lib/python3.12/smtplib.py", line 255, in __init__
    (code, msg) = self.connect(host, port)
                  ^^^^^^^^^^^^^^^^^^^^^^^^
  File "/usr/local/lib/python3.12/smtplib.py", line 341, in connect
    self.sock = self._get_socket(host, port, self.timeout)
                ^^^^^^^^^^^^^^^^^^^^^^^^^^^^^^^^^^^^^^^^^^
  File "/usr/local/lib/python3.12/smtplib.py", line 312, in _get_socket
    return socket.create_connection((host, port), timeout,
           ^^^^^^^^^^^^^^^^^^^^^^^^^^^^^^^^^^^^^^^^^^^^^^^
  File "/usr/local/lib/python3.12/socket.py", line 852, in create_connection
    raise exceptions[0]
  File "/usr/local/lib/python3.12/socket.py", line 837, in create_connection
    sock.connect(sa)
ConnectionRefusedError: [Errno 111] Connection refused
[2024-07-27T17:26:34.300+0000] {standard_task_runner.py:110} ERROR - Failed to execute job 427 for task crawl_shotmap (module 'pandas' has no attribute 'read_id'; 3680)
[2024-07-27T17:26:34.357+0000] {local_task_job_runner.py:240} INFO - Task exited with return code 1
[2024-07-27T17:26:34.393+0000] {taskinstance.py:3498} INFO - 0 downstream tasks scheduled from follow-on schedule check
[2024-07-27T17:26:34.397+0000] {local_task_job_runner.py:222} INFO - ::endgroup::
