[2024-07-27T13:25:49.383+0000] {local_task_job_runner.py:120} INFO - ::group::Pre task execution logs
[2024-07-27T13:25:49.990+0000] {taskinstance.py:2076} INFO - Dependencies all met for dep_context=non-requeueable deps ti=<TaskInstance: ETL_SofaScore_Matchday_daily.crawl_match_event scheduled__2023-07-31T00:00:00+00:00 [queued]>
[2024-07-27T13:25:50.103+0000] {taskinstance.py:2076} INFO - Dependencies all met for dep_context=requeueable deps ti=<TaskInstance: ETL_SofaScore_Matchday_daily.crawl_match_event scheduled__2023-07-31T00:00:00+00:00 [queued]>
[2024-07-27T13:25:50.111+0000] {taskinstance.py:2306} INFO - Starting attempt 1 of 2
[2024-07-27T13:25:55.081+0000] {taskinstance.py:2330} INFO - Executing <Task(PythonOperator): crawl_match_event> on 2023-07-31 00:00:00+00:00
[2024-07-27T13:25:55.250+0000] {standard_task_runner.py:90} INFO - Running: ['***', 'tasks', 'run', 'ETL_SofaScore_Matchday_daily', 'crawl_match_event', 'scheduled__2023-07-31T00:00:00+00:00', '--job-id', '283', '--raw', '--subdir', 'DAGS_FOLDER/crawl_dags.py', '--cfg-path', '/tmp/tmp7wx0tose']
[2024-07-27T13:25:55.276+0000] {standard_task_runner.py:91} INFO - Job 283: Subtask crawl_match_event
[2024-07-27T13:25:55.281+0000] {warnings.py:110} WARNING - /home/***/.local/lib/python3.12/site-packages/***/task/task_runner/standard_task_runner.py:61: DeprecationWarning: This process (pid=158) is multi-threaded, use of fork() may lead to deadlocks in the child.
  pid = os.fork()

[2024-07-27T13:25:55.299+0000] {standard_task_runner.py:63} INFO - Started process 184 to run task
[2024-07-27T13:25:55.838+0000] {task_command.py:426} INFO - Running <TaskInstance: ETL_SofaScore_Matchday_daily.crawl_match_event scheduled__2023-07-31T00:00:00+00:00 [running]> on host fde3e54b98e9
[2024-07-27T13:25:56.518+0000] {taskinstance.py:2648} INFO - Exporting env vars: AIRFLOW_CTX_DAG_EMAIL='nguyenmduc2407@gmail.com' AIRFLOW_CTX_DAG_OWNER='***' AIRFLOW_CTX_DAG_ID='ETL_SofaScore_Matchday_daily' AIRFLOW_CTX_TASK_ID='crawl_match_event' AIRFLOW_CTX_EXECUTION_DATE='2023-07-31T00:00:00+00:00' AIRFLOW_CTX_TRY_NUMBER='1' AIRFLOW_CTX_DAG_RUN_ID='scheduled__2023-07-31T00:00:00+00:00'
[2024-07-27T13:25:56.527+0000] {taskinstance.py:430} INFO - ::endgroup::
[2024-07-27T13:25:58.344+0000] {logging_mixin.py:188} INFO - Failed to fetch data for match ID 2. Status code: 404
[2024-07-27T13:26:00.317+0000] {logging_mixin.py:188} INFO - Failed to fetch data for match ID 0. Status code: 404
[2024-07-27T13:26:02.345+0000] {logging_mixin.py:188} INFO - Failed to fetch data for match ID 2. Status code: 404
[2024-07-27T13:26:04.136+0000] {logging_mixin.py:188} INFO - Failed to fetch data for match ID 3. Status code: 404
[2024-07-27T13:26:06.118+0000] {logging_mixin.py:188} INFO - Failed to fetch data for match ID -. Status code: 404
[2024-07-27T13:26:08.043+0000] {logging_mixin.py:188} INFO - Failed to fetch data for match ID 0. Status code: 404
[2024-07-27T13:26:09.794+0000] {logging_mixin.py:188} INFO - Failed to fetch data for match ID 7. Status code: 404
[2024-07-27T13:26:11.707+0000] {logging_mixin.py:188} INFO - Failed to fetch data for match ID -. Status code: 404
[2024-07-27T13:26:13.889+0000] {logging_mixin.py:188} INFO - Failed to fetch data for match ID 3. Status code: 404
[2024-07-27T13:26:15.576+0000] {logging_mixin.py:188} INFO - Failed to fetch data for match ID 1. Status code: 404
[2024-07-27T13:26:16.587+0000] {logging_mixin.py:188} INFO -   match_id  status_code
0        2          404
1        0          404
2        2          404
3        3          404
4        -          404
5        0          404
6        7          404
7        -          404
8        3          404
9        1          404
[2024-07-27T13:26:16.588+0000] {python.py:237} INFO - Done. Returned value was: None
[2024-07-27T13:26:16.590+0000] {taskinstance.py:441} INFO - ::group::Post task execution logs
[2024-07-27T13:26:16.600+0000] {taskinstance.py:1206} INFO - Marking task as SUCCESS. dag_id=ETL_SofaScore_Matchday_daily, task_id=crawl_match_event, run_id=scheduled__2023-07-31T00:00:00+00:00, execution_date=20230731T000000, start_date=20240727T132549, end_date=20240727T132616
[2024-07-27T13:26:16.957+0000] {local_task_job_runner.py:240} INFO - Task exited with return code 0
[2024-07-27T13:26:16.979+0000] {taskinstance.py:3498} INFO - 0 downstream tasks scheduled from follow-on schedule check
[2024-07-27T13:26:17.107+0000] {local_task_job_runner.py:222} INFO - ::endgroup::
[2024-07-27T14:18:17.558+0000] {local_task_job_runner.py:120} INFO - ::group::Pre task execution logs
[2024-07-27T14:18:17.622+0000] {taskinstance.py:2076} INFO - Dependencies all met for dep_context=non-requeueable deps ti=<TaskInstance: ETL_SofaScore_Matchday_daily.crawl_match_event scheduled__2023-07-31T00:00:00+00:00 [queued]>
[2024-07-27T14:18:17.645+0000] {taskinstance.py:2076} INFO - Dependencies all met for dep_context=requeueable deps ti=<TaskInstance: ETL_SofaScore_Matchday_daily.crawl_match_event scheduled__2023-07-31T00:00:00+00:00 [queued]>
[2024-07-27T14:18:17.647+0000] {taskinstance.py:2306} INFO - Starting attempt 1 of 2
[2024-07-27T14:18:18.021+0000] {taskinstance.py:2330} INFO - Executing <Task(PythonOperator): crawl_match_event> on 2023-07-31 00:00:00+00:00
[2024-07-27T14:18:18.034+0000] {standard_task_runner.py:90} INFO - Running: ['***', 'tasks', 'run', 'ETL_SofaScore_Matchday_daily', 'crawl_match_event', 'scheduled__2023-07-31T00:00:00+00:00', '--job-id', '310', '--raw', '--subdir', 'DAGS_FOLDER/crawl_dags.py', '--cfg-path', '/tmp/tmpah4g0ijp']
[2024-07-27T14:18:18.039+0000] {standard_task_runner.py:91} INFO - Job 310: Subtask crawl_match_event
[2024-07-27T14:18:18.040+0000] {warnings.py:110} WARNING - /home/***/.local/lib/python3.12/site-packages/***/task/task_runner/standard_task_runner.py:61: DeprecationWarning: This process (pid=911) is multi-threaded, use of fork() may lead to deadlocks in the child.
  pid = os.fork()

[2024-07-27T14:18:18.042+0000] {standard_task_runner.py:63} INFO - Started process 921 to run task
[2024-07-27T14:18:18.127+0000] {task_command.py:426} INFO - Running <TaskInstance: ETL_SofaScore_Matchday_daily.crawl_match_event scheduled__2023-07-31T00:00:00+00:00 [running]> on host fde3e54b98e9
[2024-07-27T14:18:18.306+0000] {taskinstance.py:2648} INFO - Exporting env vars: AIRFLOW_CTX_DAG_EMAIL='nguyenmduc2407@gmail.com' AIRFLOW_CTX_DAG_OWNER='***' AIRFLOW_CTX_DAG_ID='ETL_SofaScore_Matchday_daily' AIRFLOW_CTX_TASK_ID='crawl_match_event' AIRFLOW_CTX_EXECUTION_DATE='2023-07-31T00:00:00+00:00' AIRFLOW_CTX_TRY_NUMBER='1' AIRFLOW_CTX_DAG_RUN_ID='scheduled__2023-07-31T00:00:00+00:00'
[2024-07-27T14:18:18.308+0000] {taskinstance.py:430} INFO - ::endgroup::
[2024-07-27T14:18:19.311+0000] {logging_mixin.py:188} INFO - Failed to fetch data for match ID 2. Status code: 404
[2024-07-27T14:18:21.109+0000] {logging_mixin.py:188} INFO - Failed to fetch data for match ID 0. Status code: 404
[2024-07-27T14:18:23.066+0000] {logging_mixin.py:188} INFO - Failed to fetch data for match ID 2. Status code: 404
[2024-07-27T14:18:25.024+0000] {logging_mixin.py:188} INFO - Failed to fetch data for match ID 3. Status code: 404
[2024-07-27T14:18:27.209+0000] {logging_mixin.py:188} INFO - Failed to fetch data for match ID -. Status code: 404
[2024-07-27T14:18:29.373+0000] {logging_mixin.py:188} INFO - Failed to fetch data for match ID 0. Status code: 404
[2024-07-27T14:18:31.281+0000] {logging_mixin.py:188} INFO - Failed to fetch data for match ID 7. Status code: 404
[2024-07-27T14:18:33.002+0000] {logging_mixin.py:188} INFO - Failed to fetch data for match ID -. Status code: 404
[2024-07-27T14:18:34.699+0000] {logging_mixin.py:188} INFO - Failed to fetch data for match ID 3. Status code: 404
[2024-07-27T14:18:36.404+0000] {logging_mixin.py:188} INFO - Failed to fetch data for match ID 1. Status code: 404
[2024-07-27T14:18:37.415+0000] {logging_mixin.py:188} INFO -   match_id  status_code
0        2          404
1        0          404
2        2          404
3        3          404
4        -          404
5        0          404
6        7          404
7        -          404
8        3          404
9        1          404
[2024-07-27T14:18:37.628+0000] {logging_mixin.py:188} INFO - Data has been written to the database.
[2024-07-27T14:18:37.630+0000] {python.py:237} INFO - Done. Returned value was: None
[2024-07-27T14:18:37.632+0000] {taskinstance.py:441} INFO - ::group::Post task execution logs
[2024-07-27T14:18:37.644+0000] {taskinstance.py:1206} INFO - Marking task as SUCCESS. dag_id=ETL_SofaScore_Matchday_daily, task_id=crawl_match_event, run_id=scheduled__2023-07-31T00:00:00+00:00, execution_date=20230731T000000, start_date=20240727T141817, end_date=20240727T141837
[2024-07-27T14:18:37.670+0000] {local_task_job_runner.py:240} INFO - Task exited with return code 0
[2024-07-27T14:18:37.696+0000] {taskinstance.py:3498} INFO - 0 downstream tasks scheduled from follow-on schedule check
[2024-07-27T14:18:37.700+0000] {local_task_job_runner.py:222} INFO - ::endgroup::
[2024-07-27T15:19:59.352+0000] {local_task_job_runner.py:120} INFO - ::group::Pre task execution logs
[2024-07-27T15:19:59.457+0000] {taskinstance.py:2076} INFO - Dependencies all met for dep_context=non-requeueable deps ti=<TaskInstance: ETL_SofaScore_Matchday_daily.crawl_match_event scheduled__2023-07-31T00:00:00+00:00 [queued]>
[2024-07-27T15:19:59.520+0000] {taskinstance.py:2076} INFO - Dependencies all met for dep_context=requeueable deps ti=<TaskInstance: ETL_SofaScore_Matchday_daily.crawl_match_event scheduled__2023-07-31T00:00:00+00:00 [queued]>
[2024-07-27T15:19:59.539+0000] {taskinstance.py:2306} INFO - Starting attempt 1 of 2
[2024-07-27T15:20:00.268+0000] {taskinstance.py:2330} INFO - Executing <Task(PythonOperator): crawl_match_event> on 2023-07-31 00:00:00+00:00
[2024-07-27T15:20:00.305+0000] {standard_task_runner.py:90} INFO - Running: ['***', 'tasks', 'run', 'ETL_SofaScore_Matchday_daily', 'crawl_match_event', 'scheduled__2023-07-31T00:00:00+00:00', '--job-id', '335', '--raw', '--subdir', 'DAGS_FOLDER/crawl_dags.py', '--cfg-path', '/tmp/tmpt7j8pvzc']
[2024-07-27T15:20:00.320+0000] {standard_task_runner.py:91} INFO - Job 335: Subtask crawl_match_event
[2024-07-27T15:20:00.286+0000] {warnings.py:110} WARNING - /home/***/.local/lib/python3.12/site-packages/***/task/task_runner/standard_task_runner.py:61: DeprecationWarning: This process (pid=1767) is multi-threaded, use of fork() may lead to deadlocks in the child.
  pid = os.fork()

[2024-07-27T15:20:00.345+0000] {standard_task_runner.py:63} INFO - Started process 1797 to run task
[2024-07-27T15:20:00.687+0000] {task_command.py:426} INFO - Running <TaskInstance: ETL_SofaScore_Matchday_daily.crawl_match_event scheduled__2023-07-31T00:00:00+00:00 [running]> on host fde3e54b98e9
[2024-07-27T15:20:01.224+0000] {taskinstance.py:2648} INFO - Exporting env vars: AIRFLOW_CTX_DAG_EMAIL='nguyenmduc2407@gmail.com' AIRFLOW_CTX_DAG_OWNER='***' AIRFLOW_CTX_DAG_ID='ETL_SofaScore_Matchday_daily' AIRFLOW_CTX_TASK_ID='crawl_match_event' AIRFLOW_CTX_EXECUTION_DATE='2023-07-31T00:00:00+00:00' AIRFLOW_CTX_TRY_NUMBER='1' AIRFLOW_CTX_DAG_RUN_ID='scheduled__2023-07-31T00:00:00+00:00'
[2024-07-27T15:20:01.228+0000] {taskinstance.py:430} INFO - ::endgroup::
[2024-07-27T15:20:02.208+0000] {logging_mixin.py:188} INFO - Failed to fetch data for match ID 2. Status code: 404
[2024-07-27T15:20:04.564+0000] {logging_mixin.py:188} INFO - Failed to fetch data for match ID 0. Status code: 404
[2024-07-27T15:20:07.534+0000] {logging_mixin.py:188} INFO - Failed to fetch data for match ID 2. Status code: 404
[2024-07-27T15:20:09.778+0000] {logging_mixin.py:188} INFO - Failed to fetch data for match ID 3. Status code: 404
[2024-07-27T15:20:11.467+0000] {logging_mixin.py:188} INFO - Failed to fetch data for match ID -. Status code: 404
[2024-07-27T15:20:13.469+0000] {logging_mixin.py:188} INFO - Failed to fetch data for match ID 0. Status code: 404
[2024-07-27T15:20:15.635+0000] {logging_mixin.py:188} INFO - Failed to fetch data for match ID 7. Status code: 404
[2024-07-27T15:20:17.324+0000] {logging_mixin.py:188} INFO - Failed to fetch data for match ID -. Status code: 404
[2024-07-27T15:20:19.074+0000] {logging_mixin.py:188} INFO - Failed to fetch data for match ID 3. Status code: 404
[2024-07-27T15:20:20.973+0000] {logging_mixin.py:188} INFO - Failed to fetch data for match ID 1. Status code: 404
[2024-07-27T15:20:21.992+0000] {logging_mixin.py:188} INFO -   match_id  status_code
0        2          404
1        0          404
2        2          404
3        3          404
4        -          404
5        0          404
6        7          404
7        -          404
8        3          404
9        1          404
[2024-07-27T15:20:22.089+0000] {logging_mixin.py:188} INFO - Data has been written to the database.
[2024-07-27T15:20:22.091+0000] {python.py:237} INFO - Done. Returned value was: None
[2024-07-27T15:20:22.093+0000] {taskinstance.py:441} INFO - ::group::Post task execution logs
[2024-07-27T15:20:22.106+0000] {taskinstance.py:1206} INFO - Marking task as SUCCESS. dag_id=ETL_SofaScore_Matchday_daily, task_id=crawl_match_event, run_id=scheduled__2023-07-31T00:00:00+00:00, execution_date=20230731T000000, start_date=20240727T151959, end_date=20240727T152022
[2024-07-27T15:20:22.161+0000] {local_task_job_runner.py:240} INFO - Task exited with return code 0
[2024-07-27T15:20:22.198+0000] {taskinstance.py:3498} INFO - 0 downstream tasks scheduled from follow-on schedule check
[2024-07-27T15:20:22.202+0000] {local_task_job_runner.py:222} INFO - ::endgroup::
[2024-07-27T15:55:02.541+0000] {local_task_job_runner.py:120} INFO - ::group::Pre task execution logs
[2024-07-27T15:55:02.600+0000] {taskinstance.py:2076} INFO - Dependencies all met for dep_context=non-requeueable deps ti=<TaskInstance: ETL_SofaScore_Matchday_daily.crawl_match_event scheduled__2023-07-31T00:00:00+00:00 [queued]>
[2024-07-27T15:55:02.621+0000] {taskinstance.py:2076} INFO - Dependencies all met for dep_context=requeueable deps ti=<TaskInstance: ETL_SofaScore_Matchday_daily.crawl_match_event scheduled__2023-07-31T00:00:00+00:00 [queued]>
[2024-07-27T15:55:02.633+0000] {taskinstance.py:2306} INFO - Starting attempt 1 of 2
[2024-07-27T15:55:03.251+0000] {taskinstance.py:2330} INFO - Executing <Task(PythonOperator): crawl_match_event> on 2023-07-31 00:00:00+00:00
[2024-07-27T15:55:03.266+0000] {warnings.py:110} WARNING - /home/***/.local/lib/python3.12/site-packages/***/task/task_runner/standard_task_runner.py:61: DeprecationWarning: This process (pid=2286) is multi-threaded, use of fork() may lead to deadlocks in the child.
  pid = os.fork()

[2024-07-27T15:55:03.270+0000] {standard_task_runner.py:63} INFO - Started process 2307 to run task
[2024-07-27T15:55:03.271+0000] {standard_task_runner.py:90} INFO - Running: ['***', 'tasks', 'run', 'ETL_SofaScore_Matchday_daily', 'crawl_match_event', 'scheduled__2023-07-31T00:00:00+00:00', '--job-id', '362', '--raw', '--subdir', 'DAGS_FOLDER/crawl_dags.py', '--cfg-path', '/tmp/tmpwqhgajw_']
[2024-07-27T15:55:03.276+0000] {standard_task_runner.py:91} INFO - Job 362: Subtask crawl_match_event
[2024-07-27T15:55:03.383+0000] {task_command.py:426} INFO - Running <TaskInstance: ETL_SofaScore_Matchday_daily.crawl_match_event scheduled__2023-07-31T00:00:00+00:00 [running]> on host fde3e54b98e9
[2024-07-27T15:55:03.535+0000] {taskinstance.py:2648} INFO - Exporting env vars: AIRFLOW_CTX_DAG_EMAIL='nguyenmduc2407@gmail.com' AIRFLOW_CTX_DAG_OWNER='***' AIRFLOW_CTX_DAG_ID='ETL_SofaScore_Matchday_daily' AIRFLOW_CTX_TASK_ID='crawl_match_event' AIRFLOW_CTX_EXECUTION_DATE='2023-07-31T00:00:00+00:00' AIRFLOW_CTX_TRY_NUMBER='1' AIRFLOW_CTX_DAG_RUN_ID='scheduled__2023-07-31T00:00:00+00:00'
[2024-07-27T15:55:03.541+0000] {taskinstance.py:430} INFO - ::endgroup::
[2024-07-27T15:55:03.587+0000] {taskinstance.py:441} INFO - ::group::Post task execution logs
[2024-07-27T15:55:03.590+0000] {taskinstance.py:2905} ERROR - Task failed with exception
Traceback (most recent call last):
  File "/home/airflow/.local/lib/python3.12/site-packages/airflow/models/taskinstance.py", line 465, in _execute_task
    result = _execute_callable(context=context, **execute_callable_kwargs)
             ^^^^^^^^^^^^^^^^^^^^^^^^^^^^^^^^^^^^^^^^^^^^^^^^^^^^^^^^^^^^^
  File "/home/airflow/.local/lib/python3.12/site-packages/airflow/models/taskinstance.py", line 432, in _execute_callable
    return execute_callable(context=context, **execute_callable_kwargs)
           ^^^^^^^^^^^^^^^^^^^^^^^^^^^^^^^^^^^^^^^^^^^^^^^^^^^^^^^^^^^^
  File "/home/airflow/.local/lib/python3.12/site-packages/airflow/models/baseoperator.py", line 400, in wrapper
    return func(self, *args, **kwargs)
           ^^^^^^^^^^^^^^^^^^^^^^^^^^^
  File "/home/airflow/.local/lib/python3.12/site-packages/airflow/operators/python.py", line 235, in execute
    return_value = self.execute_callable()
                   ^^^^^^^^^^^^^^^^^^^^^^^
  File "/home/airflow/.local/lib/python3.12/site-packages/airflow/operators/python.py", line 252, in execute_callable
    return self.python_callable(*self.op_args, **self.op_kwargs)
           ^^^^^^^^^^^^^^^^^^^^^^^^^^^^^^^^^^^^^^^^^^^^^^^^^^^^^
  File "/opt/airflow/dags/crawl_dags.py", line 370, in crawl_match_event
    _, custom_ids = ti.xcom_pull(task_ids='crawl_data')
    ^^^^^^^^^^^^^
TypeError: cannot unpack non-iterable NoneType object
[2024-07-27T15:55:03.617+0000] {taskinstance.py:1206} INFO - Marking task as UP_FOR_RETRY. dag_id=ETL_SofaScore_Matchday_daily, task_id=crawl_match_event, run_id=scheduled__2023-07-31T00:00:00+00:00, execution_date=20230731T000000, start_date=20240727T155502, end_date=20240727T155503
[2024-07-27T15:55:03.644+0000] {warnings.py:110} WARNING - /home/***/.local/lib/python3.12/site-packages/***/utils/email.py:154: RemovedInAirflow3Warning: Fetching SMTP credentials from configuration variables will be deprecated in a future release. Please set credentials using a connection instead.
  send_mime_email(e_from=mail_from, e_to=recipients, mime_msg=msg, conn_id=conn_id, dryrun=dryrun)

[2024-07-27T15:55:03.646+0000] {configuration.py:1050} WARNING - section/key [smtp/smtp_user] not found in config
[2024-07-27T15:55:03.648+0000] {email.py:271} INFO - Email alerting: attempt 1
[2024-07-27T15:55:03.659+0000] {configuration.py:1050} WARNING - section/key [smtp/smtp_user] not found in config
[2024-07-27T15:55:03.660+0000] {email.py:271} INFO - Email alerting: attempt 1
[2024-07-27T15:55:03.661+0000] {taskinstance.py:879} ERROR - Failed to send email to: nguyenmduc2407@gmail.com
Traceback (most recent call last):
  File "/home/airflow/.local/lib/python3.12/site-packages/airflow/models/taskinstance.py", line 2479, in _run_raw_task
    self._execute_task_with_callbacks(context, test_mode, session=session)
  File "/home/airflow/.local/lib/python3.12/site-packages/airflow/models/taskinstance.py", line 2676, in _execute_task_with_callbacks
    result = self._execute_task(context, task_orig)
             ^^^^^^^^^^^^^^^^^^^^^^^^^^^^^^^^^^^^^^
  File "/home/airflow/.local/lib/python3.12/site-packages/airflow/models/taskinstance.py", line 2701, in _execute_task
    return _execute_task(self, context, task_orig)
           ^^^^^^^^^^^^^^^^^^^^^^^^^^^^^^^^^^^^^^^
  File "/home/airflow/.local/lib/python3.12/site-packages/airflow/models/taskinstance.py", line 465, in _execute_task
    result = _execute_callable(context=context, **execute_callable_kwargs)
             ^^^^^^^^^^^^^^^^^^^^^^^^^^^^^^^^^^^^^^^^^^^^^^^^^^^^^^^^^^^^^
  File "/home/airflow/.local/lib/python3.12/site-packages/airflow/models/taskinstance.py", line 432, in _execute_callable
    return execute_callable(context=context, **execute_callable_kwargs)
           ^^^^^^^^^^^^^^^^^^^^^^^^^^^^^^^^^^^^^^^^^^^^^^^^^^^^^^^^^^^^
  File "/home/airflow/.local/lib/python3.12/site-packages/airflow/models/baseoperator.py", line 400, in wrapper
    return func(self, *args, **kwargs)
           ^^^^^^^^^^^^^^^^^^^^^^^^^^^
  File "/home/airflow/.local/lib/python3.12/site-packages/airflow/operators/python.py", line 235, in execute
    return_value = self.execute_callable()
                   ^^^^^^^^^^^^^^^^^^^^^^^
  File "/home/airflow/.local/lib/python3.12/site-packages/airflow/operators/python.py", line 252, in execute_callable
    return self.python_callable(*self.op_args, **self.op_kwargs)
           ^^^^^^^^^^^^^^^^^^^^^^^^^^^^^^^^^^^^^^^^^^^^^^^^^^^^^
  File "/opt/airflow/dags/crawl_dags.py", line 370, in crawl_match_event
    _, custom_ids = ti.xcom_pull(task_ids='crawl_data')
    ^^^^^^^^^^^^^
TypeError: cannot unpack non-iterable NoneType object

During handling of the above exception, another exception occurred:

Traceback (most recent call last):
  File "/home/airflow/.local/lib/python3.12/site-packages/airflow/models/taskinstance.py", line 1063, in _email_alert
    send_email(task.email, subject, html_content)
  File "/home/airflow/.local/lib/python3.12/site-packages/airflow/utils/email.py", line 80, in send_email
    return backend(
           ^^^^^^^^
  File "/home/airflow/.local/lib/python3.12/site-packages/airflow/utils/email.py", line 154, in send_email_smtp
    send_mime_email(e_from=mail_from, e_to=recipients, mime_msg=msg, conn_id=conn_id, dryrun=dryrun)
  File "/home/airflow/.local/lib/python3.12/site-packages/airflow/utils/email.py", line 273, in send_mime_email
    smtp_conn = _get_smtp_connection(smtp_host, smtp_port, smtp_timeout, smtp_ssl)
                ^^^^^^^^^^^^^^^^^^^^^^^^^^^^^^^^^^^^^^^^^^^^^^^^^^^^^^^^^^^^^^^^^^
  File "/home/airflow/.local/lib/python3.12/site-packages/airflow/utils/email.py", line 317, in _get_smtp_connection
    return smtplib.SMTP(host=host, port=port, timeout=timeout)
           ^^^^^^^^^^^^^^^^^^^^^^^^^^^^^^^^^^^^^^^^^^^^^^^^^^^
  File "/usr/local/lib/python3.12/smtplib.py", line 255, in __init__
    (code, msg) = self.connect(host, port)
                  ^^^^^^^^^^^^^^^^^^^^^^^^
  File "/usr/local/lib/python3.12/smtplib.py", line 341, in connect
    self.sock = self._get_socket(host, port, self.timeout)
                ^^^^^^^^^^^^^^^^^^^^^^^^^^^^^^^^^^^^^^^^^^
  File "/usr/local/lib/python3.12/smtplib.py", line 312, in _get_socket
    return socket.create_connection((host, port), timeout,
           ^^^^^^^^^^^^^^^^^^^^^^^^^^^^^^^^^^^^^^^^^^^^^^^
  File "/usr/local/lib/python3.12/socket.py", line 852, in create_connection
    raise exceptions[0]
  File "/usr/local/lib/python3.12/socket.py", line 837, in create_connection
    sock.connect(sa)
ConnectionRefusedError: [Errno 111] Connection refused

During handling of the above exception, another exception occurred:

Traceback (most recent call last):
  File "/home/airflow/.local/lib/python3.12/site-packages/airflow/models/taskinstance.py", line 877, in _handle_failure
    task_instance.email_alert(error, failure_context["task"])
  File "/home/airflow/.local/lib/python3.12/site-packages/airflow/models/taskinstance.py", line 3163, in email_alert
    _email_alert(task_instance=self, exception=exception, task=task)
  File "/home/airflow/.local/lib/python3.12/site-packages/airflow/models/taskinstance.py", line 1065, in _email_alert
    send_email(task.email, subject, html_content_err)
  File "/home/airflow/.local/lib/python3.12/site-packages/airflow/utils/email.py", line 80, in send_email
    return backend(
           ^^^^^^^^
  File "/home/airflow/.local/lib/python3.12/site-packages/airflow/utils/email.py", line 154, in send_email_smtp
    send_mime_email(e_from=mail_from, e_to=recipients, mime_msg=msg, conn_id=conn_id, dryrun=dryrun)
  File "/home/airflow/.local/lib/python3.12/site-packages/airflow/utils/email.py", line 273, in send_mime_email
    smtp_conn = _get_smtp_connection(smtp_host, smtp_port, smtp_timeout, smtp_ssl)
                ^^^^^^^^^^^^^^^^^^^^^^^^^^^^^^^^^^^^^^^^^^^^^^^^^^^^^^^^^^^^^^^^^^
  File "/home/airflow/.local/lib/python3.12/site-packages/airflow/utils/email.py", line 317, in _get_smtp_connection
    return smtplib.SMTP(host=host, port=port, timeout=timeout)
           ^^^^^^^^^^^^^^^^^^^^^^^^^^^^^^^^^^^^^^^^^^^^^^^^^^^
  File "/usr/local/lib/python3.12/smtplib.py", line 255, in __init__
    (code, msg) = self.connect(host, port)
                  ^^^^^^^^^^^^^^^^^^^^^^^^
  File "/usr/local/lib/python3.12/smtplib.py", line 341, in connect
    self.sock = self._get_socket(host, port, self.timeout)
                ^^^^^^^^^^^^^^^^^^^^^^^^^^^^^^^^^^^^^^^^^^
  File "/usr/local/lib/python3.12/smtplib.py", line 312, in _get_socket
    return socket.create_connection((host, port), timeout,
           ^^^^^^^^^^^^^^^^^^^^^^^^^^^^^^^^^^^^^^^^^^^^^^^
  File "/usr/local/lib/python3.12/socket.py", line 852, in create_connection
    raise exceptions[0]
  File "/usr/local/lib/python3.12/socket.py", line 837, in create_connection
    sock.connect(sa)
ConnectionRefusedError: [Errno 111] Connection refused
[2024-07-27T15:55:03.687+0000] {standard_task_runner.py:110} ERROR - Failed to execute job 362 for task crawl_match_event (cannot unpack non-iterable NoneType object; 2307)
[2024-07-27T15:55:03.735+0000] {local_task_job_runner.py:240} INFO - Task exited with return code 1
[2024-07-27T15:55:03.748+0000] {local_task_job_runner.py:222} INFO - ::endgroup::
[2024-07-27T16:31:03.928+0000] {local_task_job_runner.py:120} INFO - ::group::Pre task execution logs
[2024-07-27T16:31:03.997+0000] {taskinstance.py:2076} INFO - Dependencies all met for dep_context=non-requeueable deps ti=<TaskInstance: ETL_SofaScore_Matchday_daily.crawl_match_event scheduled__2023-07-31T00:00:00+00:00 [queued]>
[2024-07-27T16:31:04.033+0000] {taskinstance.py:2076} INFO - Dependencies all met for dep_context=requeueable deps ti=<TaskInstance: ETL_SofaScore_Matchday_daily.crawl_match_event scheduled__2023-07-31T00:00:00+00:00 [queued]>
[2024-07-27T16:31:04.034+0000] {taskinstance.py:2306} INFO - Starting attempt 1 of 2
[2024-07-27T16:31:04.539+0000] {taskinstance.py:2330} INFO - Executing <Task(PythonOperator): crawl_match_event> on 2023-07-31 00:00:00+00:00
[2024-07-27T16:31:04.553+0000] {warnings.py:110} WARNING - /home/***/.local/lib/python3.12/site-packages/***/task/task_runner/standard_task_runner.py:61: DeprecationWarning: This process (pid=2792) is multi-threaded, use of fork() may lead to deadlocks in the child.
  pid = os.fork()

[2024-07-27T16:31:04.557+0000] {standard_task_runner.py:63} INFO - Started process 2806 to run task
[2024-07-27T16:31:04.556+0000] {standard_task_runner.py:90} INFO - Running: ['***', 'tasks', 'run', 'ETL_SofaScore_Matchday_daily', 'crawl_match_event', 'scheduled__2023-07-31T00:00:00+00:00', '--job-id', '376', '--raw', '--subdir', 'DAGS_FOLDER/crawl_dags.py', '--cfg-path', '/tmp/tmpg988_sas']
[2024-07-27T16:31:04.562+0000] {standard_task_runner.py:91} INFO - Job 376: Subtask crawl_match_event
[2024-07-27T16:31:04.651+0000] {task_command.py:426} INFO - Running <TaskInstance: ETL_SofaScore_Matchday_daily.crawl_match_event scheduled__2023-07-31T00:00:00+00:00 [running]> on host fde3e54b98e9
[2024-07-27T16:31:04.970+0000] {taskinstance.py:2648} INFO - Exporting env vars: AIRFLOW_CTX_DAG_EMAIL='nguyenmduc2407@gmail.com' AIRFLOW_CTX_DAG_OWNER='***' AIRFLOW_CTX_DAG_ID='ETL_SofaScore_Matchday_daily' AIRFLOW_CTX_TASK_ID='crawl_match_event' AIRFLOW_CTX_EXECUTION_DATE='2023-07-31T00:00:00+00:00' AIRFLOW_CTX_TRY_NUMBER='1' AIRFLOW_CTX_DAG_RUN_ID='scheduled__2023-07-31T00:00:00+00:00'
[2024-07-27T16:31:04.972+0000] {taskinstance.py:430} INFO - ::endgroup::
[2024-07-27T16:31:04.985+0000] {taskinstance.py:441} INFO - ::group::Post task execution logs
[2024-07-27T16:31:04.986+0000] {taskinstance.py:2905} ERROR - Task failed with exception
Traceback (most recent call last):
  File "/home/airflow/.local/lib/python3.12/site-packages/airflow/models/taskinstance.py", line 465, in _execute_task
    result = _execute_callable(context=context, **execute_callable_kwargs)
             ^^^^^^^^^^^^^^^^^^^^^^^^^^^^^^^^^^^^^^^^^^^^^^^^^^^^^^^^^^^^^
  File "/home/airflow/.local/lib/python3.12/site-packages/airflow/models/taskinstance.py", line 432, in _execute_callable
    return execute_callable(context=context, **execute_callable_kwargs)
           ^^^^^^^^^^^^^^^^^^^^^^^^^^^^^^^^^^^^^^^^^^^^^^^^^^^^^^^^^^^^
  File "/home/airflow/.local/lib/python3.12/site-packages/airflow/models/baseoperator.py", line 400, in wrapper
    return func(self, *args, **kwargs)
           ^^^^^^^^^^^^^^^^^^^^^^^^^^^
  File "/home/airflow/.local/lib/python3.12/site-packages/airflow/operators/python.py", line 235, in execute
    return_value = self.execute_callable()
                   ^^^^^^^^^^^^^^^^^^^^^^^
  File "/home/airflow/.local/lib/python3.12/site-packages/airflow/operators/python.py", line 252, in execute_callable
    return self.python_callable(*self.op_args, **self.op_kwargs)
           ^^^^^^^^^^^^^^^^^^^^^^^^^^^^^^^^^^^^^^^^^^^^^^^^^^^^^
TypeError: crawl_match_event() missing 1 required positional argument: 'list_customId'
[2024-07-27T16:31:04.995+0000] {taskinstance.py:1206} INFO - Marking task as UP_FOR_RETRY. dag_id=ETL_SofaScore_Matchday_daily, task_id=crawl_match_event, run_id=scheduled__2023-07-31T00:00:00+00:00, execution_date=20230731T000000, start_date=20240727T163103, end_date=20240727T163104
[2024-07-27T16:31:05.009+0000] {warnings.py:110} WARNING - /home/***/.local/lib/python3.12/site-packages/***/utils/email.py:154: RemovedInAirflow3Warning: Fetching SMTP credentials from configuration variables will be deprecated in a future release. Please set credentials using a connection instead.
  send_mime_email(e_from=mail_from, e_to=recipients, mime_msg=msg, conn_id=conn_id, dryrun=dryrun)

[2024-07-27T16:31:05.010+0000] {configuration.py:1050} WARNING - section/key [smtp/smtp_user] not found in config
[2024-07-27T16:31:05.011+0000] {email.py:271} INFO - Email alerting: attempt 1
[2024-07-27T16:31:05.018+0000] {configuration.py:1050} WARNING - section/key [smtp/smtp_user] not found in config
[2024-07-27T16:31:05.019+0000] {email.py:271} INFO - Email alerting: attempt 1
[2024-07-27T16:31:05.019+0000] {taskinstance.py:879} ERROR - Failed to send email to: nguyenmduc2407@gmail.com
Traceback (most recent call last):
  File "/home/airflow/.local/lib/python3.12/site-packages/airflow/models/taskinstance.py", line 2479, in _run_raw_task
    self._execute_task_with_callbacks(context, test_mode, session=session)
  File "/home/airflow/.local/lib/python3.12/site-packages/airflow/models/taskinstance.py", line 2676, in _execute_task_with_callbacks
    result = self._execute_task(context, task_orig)
             ^^^^^^^^^^^^^^^^^^^^^^^^^^^^^^^^^^^^^^
  File "/home/airflow/.local/lib/python3.12/site-packages/airflow/models/taskinstance.py", line 2701, in _execute_task
    return _execute_task(self, context, task_orig)
           ^^^^^^^^^^^^^^^^^^^^^^^^^^^^^^^^^^^^^^^
  File "/home/airflow/.local/lib/python3.12/site-packages/airflow/models/taskinstance.py", line 465, in _execute_task
    result = _execute_callable(context=context, **execute_callable_kwargs)
             ^^^^^^^^^^^^^^^^^^^^^^^^^^^^^^^^^^^^^^^^^^^^^^^^^^^^^^^^^^^^^
  File "/home/airflow/.local/lib/python3.12/site-packages/airflow/models/taskinstance.py", line 432, in _execute_callable
    return execute_callable(context=context, **execute_callable_kwargs)
           ^^^^^^^^^^^^^^^^^^^^^^^^^^^^^^^^^^^^^^^^^^^^^^^^^^^^^^^^^^^^
  File "/home/airflow/.local/lib/python3.12/site-packages/airflow/models/baseoperator.py", line 400, in wrapper
    return func(self, *args, **kwargs)
           ^^^^^^^^^^^^^^^^^^^^^^^^^^^
  File "/home/airflow/.local/lib/python3.12/site-packages/airflow/operators/python.py", line 235, in execute
    return_value = self.execute_callable()
                   ^^^^^^^^^^^^^^^^^^^^^^^
  File "/home/airflow/.local/lib/python3.12/site-packages/airflow/operators/python.py", line 252, in execute_callable
    return self.python_callable(*self.op_args, **self.op_kwargs)
           ^^^^^^^^^^^^^^^^^^^^^^^^^^^^^^^^^^^^^^^^^^^^^^^^^^^^^
TypeError: crawl_match_event() missing 1 required positional argument: 'list_customId'

During handling of the above exception, another exception occurred:

Traceback (most recent call last):
  File "/home/airflow/.local/lib/python3.12/site-packages/airflow/models/taskinstance.py", line 1063, in _email_alert
    send_email(task.email, subject, html_content)
  File "/home/airflow/.local/lib/python3.12/site-packages/airflow/utils/email.py", line 80, in send_email
    return backend(
           ^^^^^^^^
  File "/home/airflow/.local/lib/python3.12/site-packages/airflow/utils/email.py", line 154, in send_email_smtp
    send_mime_email(e_from=mail_from, e_to=recipients, mime_msg=msg, conn_id=conn_id, dryrun=dryrun)
  File "/home/airflow/.local/lib/python3.12/site-packages/airflow/utils/email.py", line 273, in send_mime_email
    smtp_conn = _get_smtp_connection(smtp_host, smtp_port, smtp_timeout, smtp_ssl)
                ^^^^^^^^^^^^^^^^^^^^^^^^^^^^^^^^^^^^^^^^^^^^^^^^^^^^^^^^^^^^^^^^^^
  File "/home/airflow/.local/lib/python3.12/site-packages/airflow/utils/email.py", line 317, in _get_smtp_connection
    return smtplib.SMTP(host=host, port=port, timeout=timeout)
           ^^^^^^^^^^^^^^^^^^^^^^^^^^^^^^^^^^^^^^^^^^^^^^^^^^^
  File "/usr/local/lib/python3.12/smtplib.py", line 255, in __init__
    (code, msg) = self.connect(host, port)
                  ^^^^^^^^^^^^^^^^^^^^^^^^
  File "/usr/local/lib/python3.12/smtplib.py", line 341, in connect
    self.sock = self._get_socket(host, port, self.timeout)
                ^^^^^^^^^^^^^^^^^^^^^^^^^^^^^^^^^^^^^^^^^^
  File "/usr/local/lib/python3.12/smtplib.py", line 312, in _get_socket
    return socket.create_connection((host, port), timeout,
           ^^^^^^^^^^^^^^^^^^^^^^^^^^^^^^^^^^^^^^^^^^^^^^^
  File "/usr/local/lib/python3.12/socket.py", line 852, in create_connection
    raise exceptions[0]
  File "/usr/local/lib/python3.12/socket.py", line 837, in create_connection
    sock.connect(sa)
ConnectionRefusedError: [Errno 111] Connection refused

During handling of the above exception, another exception occurred:

Traceback (most recent call last):
  File "/home/airflow/.local/lib/python3.12/site-packages/airflow/models/taskinstance.py", line 877, in _handle_failure
    task_instance.email_alert(error, failure_context["task"])
  File "/home/airflow/.local/lib/python3.12/site-packages/airflow/models/taskinstance.py", line 3163, in email_alert
    _email_alert(task_instance=self, exception=exception, task=task)
  File "/home/airflow/.local/lib/python3.12/site-packages/airflow/models/taskinstance.py", line 1065, in _email_alert
    send_email(task.email, subject, html_content_err)
  File "/home/airflow/.local/lib/python3.12/site-packages/airflow/utils/email.py", line 80, in send_email
    return backend(
           ^^^^^^^^
  File "/home/airflow/.local/lib/python3.12/site-packages/airflow/utils/email.py", line 154, in send_email_smtp
    send_mime_email(e_from=mail_from, e_to=recipients, mime_msg=msg, conn_id=conn_id, dryrun=dryrun)
  File "/home/airflow/.local/lib/python3.12/site-packages/airflow/utils/email.py", line 273, in send_mime_email
    smtp_conn = _get_smtp_connection(smtp_host, smtp_port, smtp_timeout, smtp_ssl)
                ^^^^^^^^^^^^^^^^^^^^^^^^^^^^^^^^^^^^^^^^^^^^^^^^^^^^^^^^^^^^^^^^^^
  File "/home/airflow/.local/lib/python3.12/site-packages/airflow/utils/email.py", line 317, in _get_smtp_connection
    return smtplib.SMTP(host=host, port=port, timeout=timeout)
           ^^^^^^^^^^^^^^^^^^^^^^^^^^^^^^^^^^^^^^^^^^^^^^^^^^^
  File "/usr/local/lib/python3.12/smtplib.py", line 255, in __init__
    (code, msg) = self.connect(host, port)
                  ^^^^^^^^^^^^^^^^^^^^^^^^
  File "/usr/local/lib/python3.12/smtplib.py", line 341, in connect
    self.sock = self._get_socket(host, port, self.timeout)
                ^^^^^^^^^^^^^^^^^^^^^^^^^^^^^^^^^^^^^^^^^^
  File "/usr/local/lib/python3.12/smtplib.py", line 312, in _get_socket
    return socket.create_connection((host, port), timeout,
           ^^^^^^^^^^^^^^^^^^^^^^^^^^^^^^^^^^^^^^^^^^^^^^^
  File "/usr/local/lib/python3.12/socket.py", line 852, in create_connection
    raise exceptions[0]
  File "/usr/local/lib/python3.12/socket.py", line 837, in create_connection
    sock.connect(sa)
ConnectionRefusedError: [Errno 111] Connection refused
[2024-07-27T16:31:05.035+0000] {standard_task_runner.py:110} ERROR - Failed to execute job 376 for task crawl_match_event (crawl_match_event() missing 1 required positional argument: 'list_customId'; 2806)
[2024-07-27T16:31:05.056+0000] {local_task_job_runner.py:240} INFO - Task exited with return code 1
[2024-07-27T16:31:05.079+0000] {taskinstance.py:3498} INFO - 0 downstream tasks scheduled from follow-on schedule check
[2024-07-27T16:31:05.082+0000] {local_task_job_runner.py:222} INFO - ::endgroup::
[2024-07-27T16:37:30.514+0000] {local_task_job_runner.py:120} INFO - ::group::Pre task execution logs
[2024-07-27T16:37:30.565+0000] {taskinstance.py:2076} INFO - Dependencies all met for dep_context=non-requeueable deps ti=<TaskInstance: ETL_SofaScore_Matchday_daily.crawl_match_event scheduled__2023-07-31T00:00:00+00:00 [queued]>
[2024-07-27T16:37:30.586+0000] {taskinstance.py:2076} INFO - Dependencies all met for dep_context=requeueable deps ti=<TaskInstance: ETL_SofaScore_Matchday_daily.crawl_match_event scheduled__2023-07-31T00:00:00+00:00 [queued]>
[2024-07-27T16:37:30.587+0000] {taskinstance.py:2306} INFO - Starting attempt 1 of 2
[2024-07-27T16:37:30.896+0000] {taskinstance.py:2330} INFO - Executing <Task(PythonOperator): crawl_match_event> on 2023-07-31 00:00:00+00:00
[2024-07-27T16:37:30.911+0000] {warnings.py:110} WARNING - /home/***/.local/lib/python3.12/site-packages/***/task/task_runner/standard_task_runner.py:61: DeprecationWarning: This process (pid=2906) is multi-threaded, use of fork() may lead to deadlocks in the child.
  pid = os.fork()

[2024-07-27T16:37:30.913+0000] {standard_task_runner.py:90} INFO - Running: ['***', 'tasks', 'run', 'ETL_SofaScore_Matchday_daily', 'crawl_match_event', 'scheduled__2023-07-31T00:00:00+00:00', '--job-id', '384', '--raw', '--subdir', 'DAGS_FOLDER/crawl_dags.py', '--cfg-path', '/tmp/tmp0hwa3w7v']
[2024-07-27T16:37:30.916+0000] {standard_task_runner.py:63} INFO - Started process 2921 to run task
[2024-07-27T16:37:30.924+0000] {standard_task_runner.py:91} INFO - Job 384: Subtask crawl_match_event
[2024-07-27T16:37:31.029+0000] {task_command.py:426} INFO - Running <TaskInstance: ETL_SofaScore_Matchday_daily.crawl_match_event scheduled__2023-07-31T00:00:00+00:00 [running]> on host fde3e54b98e9
[2024-07-27T16:37:31.177+0000] {taskinstance.py:2648} INFO - Exporting env vars: AIRFLOW_CTX_DAG_EMAIL='nguyenmduc2407@gmail.com' AIRFLOW_CTX_DAG_OWNER='***' AIRFLOW_CTX_DAG_ID='ETL_SofaScore_Matchday_daily' AIRFLOW_CTX_TASK_ID='crawl_match_event' AIRFLOW_CTX_EXECUTION_DATE='2023-07-31T00:00:00+00:00' AIRFLOW_CTX_TRY_NUMBER='1' AIRFLOW_CTX_DAG_RUN_ID='scheduled__2023-07-31T00:00:00+00:00'
[2024-07-27T16:37:31.180+0000] {taskinstance.py:430} INFO - ::endgroup::
[2024-07-27T16:37:31.208+0000] {taskinstance.py:441} INFO - ::group::Post task execution logs
[2024-07-27T16:37:31.210+0000] {taskinstance.py:2905} ERROR - Task failed with exception
Traceback (most recent call last):
  File "/home/airflow/.local/lib/python3.12/site-packages/airflow/models/taskinstance.py", line 465, in _execute_task
    result = _execute_callable(context=context, **execute_callable_kwargs)
             ^^^^^^^^^^^^^^^^^^^^^^^^^^^^^^^^^^^^^^^^^^^^^^^^^^^^^^^^^^^^^
  File "/home/airflow/.local/lib/python3.12/site-packages/airflow/models/taskinstance.py", line 432, in _execute_callable
    return execute_callable(context=context, **execute_callable_kwargs)
           ^^^^^^^^^^^^^^^^^^^^^^^^^^^^^^^^^^^^^^^^^^^^^^^^^^^^^^^^^^^^
  File "/home/airflow/.local/lib/python3.12/site-packages/airflow/models/baseoperator.py", line 400, in wrapper
    return func(self, *args, **kwargs)
           ^^^^^^^^^^^^^^^^^^^^^^^^^^^
  File "/home/airflow/.local/lib/python3.12/site-packages/airflow/operators/python.py", line 235, in execute
    return_value = self.execute_callable()
                   ^^^^^^^^^^^^^^^^^^^^^^^
  File "/home/airflow/.local/lib/python3.12/site-packages/airflow/operators/python.py", line 252, in execute_callable
    return self.python_callable(*self.op_args, **self.op_kwargs)
           ^^^^^^^^^^^^^^^^^^^^^^^^^^^^^^^^^^^^^^^^^^^^^^^^^^^^^
  File "/opt/airflow/dags/crawl_dags.py", line 366, in crawl_match_event
    return crawler.match_event()
           ^^^^^^^^^^^^^^^^^^^^^
TypeError: CrawlMatchInfo.match_event() missing 1 required positional argument: 'list_customId'
[2024-07-27T16:37:31.232+0000] {taskinstance.py:1206} INFO - Marking task as UP_FOR_RETRY. dag_id=ETL_SofaScore_Matchday_daily, task_id=crawl_match_event, run_id=scheduled__2023-07-31T00:00:00+00:00, execution_date=20230731T000000, start_date=20240727T163730, end_date=20240727T163731
[2024-07-27T16:37:31.256+0000] {warnings.py:110} WARNING - /home/***/.local/lib/python3.12/site-packages/***/utils/email.py:154: RemovedInAirflow3Warning: Fetching SMTP credentials from configuration variables will be deprecated in a future release. Please set credentials using a connection instead.
  send_mime_email(e_from=mail_from, e_to=recipients, mime_msg=msg, conn_id=conn_id, dryrun=dryrun)

[2024-07-27T16:37:31.257+0000] {configuration.py:1050} WARNING - section/key [smtp/smtp_user] not found in config
[2024-07-27T16:37:31.259+0000] {email.py:271} INFO - Email alerting: attempt 1
[2024-07-27T16:37:31.273+0000] {configuration.py:1050} WARNING - section/key [smtp/smtp_user] not found in config
[2024-07-27T16:37:31.276+0000] {email.py:271} INFO - Email alerting: attempt 1
[2024-07-27T16:37:31.277+0000] {taskinstance.py:879} ERROR - Failed to send email to: nguyenmduc2407@gmail.com
Traceback (most recent call last):
  File "/home/airflow/.local/lib/python3.12/site-packages/airflow/models/taskinstance.py", line 2479, in _run_raw_task
    self._execute_task_with_callbacks(context, test_mode, session=session)
  File "/home/airflow/.local/lib/python3.12/site-packages/airflow/models/taskinstance.py", line 2676, in _execute_task_with_callbacks
    result = self._execute_task(context, task_orig)
             ^^^^^^^^^^^^^^^^^^^^^^^^^^^^^^^^^^^^^^
  File "/home/airflow/.local/lib/python3.12/site-packages/airflow/models/taskinstance.py", line 2701, in _execute_task
    return _execute_task(self, context, task_orig)
           ^^^^^^^^^^^^^^^^^^^^^^^^^^^^^^^^^^^^^^^
  File "/home/airflow/.local/lib/python3.12/site-packages/airflow/models/taskinstance.py", line 465, in _execute_task
    result = _execute_callable(context=context, **execute_callable_kwargs)
             ^^^^^^^^^^^^^^^^^^^^^^^^^^^^^^^^^^^^^^^^^^^^^^^^^^^^^^^^^^^^^
  File "/home/airflow/.local/lib/python3.12/site-packages/airflow/models/taskinstance.py", line 432, in _execute_callable
    return execute_callable(context=context, **execute_callable_kwargs)
           ^^^^^^^^^^^^^^^^^^^^^^^^^^^^^^^^^^^^^^^^^^^^^^^^^^^^^^^^^^^^
  File "/home/airflow/.local/lib/python3.12/site-packages/airflow/models/baseoperator.py", line 400, in wrapper
    return func(self, *args, **kwargs)
           ^^^^^^^^^^^^^^^^^^^^^^^^^^^
  File "/home/airflow/.local/lib/python3.12/site-packages/airflow/operators/python.py", line 235, in execute
    return_value = self.execute_callable()
                   ^^^^^^^^^^^^^^^^^^^^^^^
  File "/home/airflow/.local/lib/python3.12/site-packages/airflow/operators/python.py", line 252, in execute_callable
    return self.python_callable(*self.op_args, **self.op_kwargs)
           ^^^^^^^^^^^^^^^^^^^^^^^^^^^^^^^^^^^^^^^^^^^^^^^^^^^^^
  File "/opt/airflow/dags/crawl_dags.py", line 366, in crawl_match_event
    return crawler.match_event()
           ^^^^^^^^^^^^^^^^^^^^^
TypeError: CrawlMatchInfo.match_event() missing 1 required positional argument: 'list_customId'

During handling of the above exception, another exception occurred:

Traceback (most recent call last):
  File "/home/airflow/.local/lib/python3.12/site-packages/airflow/models/taskinstance.py", line 1063, in _email_alert
    send_email(task.email, subject, html_content)
  File "/home/airflow/.local/lib/python3.12/site-packages/airflow/utils/email.py", line 80, in send_email
    return backend(
           ^^^^^^^^
  File "/home/airflow/.local/lib/python3.12/site-packages/airflow/utils/email.py", line 154, in send_email_smtp
    send_mime_email(e_from=mail_from, e_to=recipients, mime_msg=msg, conn_id=conn_id, dryrun=dryrun)
  File "/home/airflow/.local/lib/python3.12/site-packages/airflow/utils/email.py", line 273, in send_mime_email
    smtp_conn = _get_smtp_connection(smtp_host, smtp_port, smtp_timeout, smtp_ssl)
                ^^^^^^^^^^^^^^^^^^^^^^^^^^^^^^^^^^^^^^^^^^^^^^^^^^^^^^^^^^^^^^^^^^
  File "/home/airflow/.local/lib/python3.12/site-packages/airflow/utils/email.py", line 317, in _get_smtp_connection
    return smtplib.SMTP(host=host, port=port, timeout=timeout)
           ^^^^^^^^^^^^^^^^^^^^^^^^^^^^^^^^^^^^^^^^^^^^^^^^^^^
  File "/usr/local/lib/python3.12/smtplib.py", line 255, in __init__
    (code, msg) = self.connect(host, port)
                  ^^^^^^^^^^^^^^^^^^^^^^^^
  File "/usr/local/lib/python3.12/smtplib.py", line 341, in connect
    self.sock = self._get_socket(host, port, self.timeout)
                ^^^^^^^^^^^^^^^^^^^^^^^^^^^^^^^^^^^^^^^^^^
  File "/usr/local/lib/python3.12/smtplib.py", line 312, in _get_socket
    return socket.create_connection((host, port), timeout,
           ^^^^^^^^^^^^^^^^^^^^^^^^^^^^^^^^^^^^^^^^^^^^^^^
  File "/usr/local/lib/python3.12/socket.py", line 852, in create_connection
    raise exceptions[0]
  File "/usr/local/lib/python3.12/socket.py", line 837, in create_connection
    sock.connect(sa)
ConnectionRefusedError: [Errno 111] Connection refused

During handling of the above exception, another exception occurred:

Traceback (most recent call last):
  File "/home/airflow/.local/lib/python3.12/site-packages/airflow/models/taskinstance.py", line 877, in _handle_failure
    task_instance.email_alert(error, failure_context["task"])
  File "/home/airflow/.local/lib/python3.12/site-packages/airflow/models/taskinstance.py", line 3163, in email_alert
    _email_alert(task_instance=self, exception=exception, task=task)
  File "/home/airflow/.local/lib/python3.12/site-packages/airflow/models/taskinstance.py", line 1065, in _email_alert
    send_email(task.email, subject, html_content_err)
  File "/home/airflow/.local/lib/python3.12/site-packages/airflow/utils/email.py", line 80, in send_email
    return backend(
           ^^^^^^^^
  File "/home/airflow/.local/lib/python3.12/site-packages/airflow/utils/email.py", line 154, in send_email_smtp
    send_mime_email(e_from=mail_from, e_to=recipients, mime_msg=msg, conn_id=conn_id, dryrun=dryrun)
  File "/home/airflow/.local/lib/python3.12/site-packages/airflow/utils/email.py", line 273, in send_mime_email
    smtp_conn = _get_smtp_connection(smtp_host, smtp_port, smtp_timeout, smtp_ssl)
                ^^^^^^^^^^^^^^^^^^^^^^^^^^^^^^^^^^^^^^^^^^^^^^^^^^^^^^^^^^^^^^^^^^
  File "/home/airflow/.local/lib/python3.12/site-packages/airflow/utils/email.py", line 317, in _get_smtp_connection
    return smtplib.SMTP(host=host, port=port, timeout=timeout)
           ^^^^^^^^^^^^^^^^^^^^^^^^^^^^^^^^^^^^^^^^^^^^^^^^^^^
  File "/usr/local/lib/python3.12/smtplib.py", line 255, in __init__
    (code, msg) = self.connect(host, port)
                  ^^^^^^^^^^^^^^^^^^^^^^^^
  File "/usr/local/lib/python3.12/smtplib.py", line 341, in connect
    self.sock = self._get_socket(host, port, self.timeout)
                ^^^^^^^^^^^^^^^^^^^^^^^^^^^^^^^^^^^^^^^^^^
  File "/usr/local/lib/python3.12/smtplib.py", line 312, in _get_socket
    return socket.create_connection((host, port), timeout,
           ^^^^^^^^^^^^^^^^^^^^^^^^^^^^^^^^^^^^^^^^^^^^^^^
  File "/usr/local/lib/python3.12/socket.py", line 852, in create_connection
    raise exceptions[0]
  File "/usr/local/lib/python3.12/socket.py", line 837, in create_connection
    sock.connect(sa)
ConnectionRefusedError: [Errno 111] Connection refused
[2024-07-27T16:37:31.310+0000] {standard_task_runner.py:110} ERROR - Failed to execute job 384 for task crawl_match_event (CrawlMatchInfo.match_event() missing 1 required positional argument: 'list_customId'; 2921)
[2024-07-27T16:37:31.340+0000] {local_task_job_runner.py:240} INFO - Task exited with return code 1
[2024-07-27T16:37:31.354+0000] {local_task_job_runner.py:222} INFO - ::endgroup::
[2024-07-27T16:43:04.579+0000] {local_task_job_runner.py:120} INFO - ::group::Pre task execution logs
[2024-07-27T16:43:04.716+0000] {taskinstance.py:2076} INFO - Dependencies all met for dep_context=non-requeueable deps ti=<TaskInstance: ETL_SofaScore_Matchday_daily.crawl_match_event scheduled__2023-07-31T00:00:00+00:00 [queued]>
[2024-07-27T16:43:04.769+0000] {taskinstance.py:2076} INFO - Dependencies all met for dep_context=requeueable deps ti=<TaskInstance: ETL_SofaScore_Matchday_daily.crawl_match_event scheduled__2023-07-31T00:00:00+00:00 [queued]>
[2024-07-27T16:43:04.771+0000] {taskinstance.py:2306} INFO - Starting attempt 1 of 2
[2024-07-27T16:43:05.362+0000] {taskinstance.py:2330} INFO - Executing <Task(PythonOperator): crawl_match_event> on 2023-07-31 00:00:00+00:00
[2024-07-27T16:43:05.387+0000] {warnings.py:110} WARNING - /home/***/.local/lib/python3.12/site-packages/***/task/task_runner/standard_task_runner.py:61: DeprecationWarning: This process (pid=3014) is multi-threaded, use of fork() may lead to deadlocks in the child.
  pid = os.fork()

[2024-07-27T16:43:05.399+0000] {standard_task_runner.py:63} INFO - Started process 3037 to run task
[2024-07-27T16:43:05.403+0000] {standard_task_runner.py:90} INFO - Running: ['***', 'tasks', 'run', 'ETL_SofaScore_Matchday_daily', 'crawl_match_event', 'scheduled__2023-07-31T00:00:00+00:00', '--job-id', '396', '--raw', '--subdir', 'DAGS_FOLDER/crawl_dags.py', '--cfg-path', '/tmp/tmpafetc74y']
[2024-07-27T16:43:05.411+0000] {standard_task_runner.py:91} INFO - Job 396: Subtask crawl_match_event
[2024-07-27T16:43:05.638+0000] {task_command.py:426} INFO - Running <TaskInstance: ETL_SofaScore_Matchday_daily.crawl_match_event scheduled__2023-07-31T00:00:00+00:00 [running]> on host fde3e54b98e9
[2024-07-27T16:43:05.924+0000] {taskinstance.py:2648} INFO - Exporting env vars: AIRFLOW_CTX_DAG_EMAIL='nguyenmduc2407@gmail.com' AIRFLOW_CTX_DAG_OWNER='***' AIRFLOW_CTX_DAG_ID='ETL_SofaScore_Matchday_daily' AIRFLOW_CTX_TASK_ID='crawl_match_event' AIRFLOW_CTX_EXECUTION_DATE='2023-07-31T00:00:00+00:00' AIRFLOW_CTX_TRY_NUMBER='1' AIRFLOW_CTX_DAG_RUN_ID='scheduled__2023-07-31T00:00:00+00:00'
[2024-07-27T16:43:05.930+0000] {taskinstance.py:430} INFO - ::endgroup::
[2024-07-27T16:43:05.984+0000] {taskinstance.py:441} INFO - ::group::Post task execution logs
[2024-07-27T16:43:05.986+0000] {taskinstance.py:2905} ERROR - Task failed with exception
Traceback (most recent call last):
  File "/home/airflow/.local/lib/python3.12/site-packages/airflow/models/taskinstance.py", line 465, in _execute_task
    result = _execute_callable(context=context, **execute_callable_kwargs)
             ^^^^^^^^^^^^^^^^^^^^^^^^^^^^^^^^^^^^^^^^^^^^^^^^^^^^^^^^^^^^^
  File "/home/airflow/.local/lib/python3.12/site-packages/airflow/models/taskinstance.py", line 432, in _execute_callable
    return execute_callable(context=context, **execute_callable_kwargs)
           ^^^^^^^^^^^^^^^^^^^^^^^^^^^^^^^^^^^^^^^^^^^^^^^^^^^^^^^^^^^^
  File "/home/airflow/.local/lib/python3.12/site-packages/airflow/models/baseoperator.py", line 400, in wrapper
    return func(self, *args, **kwargs)
           ^^^^^^^^^^^^^^^^^^^^^^^^^^^
  File "/home/airflow/.local/lib/python3.12/site-packages/airflow/operators/python.py", line 235, in execute
    return_value = self.execute_callable()
                   ^^^^^^^^^^^^^^^^^^^^^^^
  File "/home/airflow/.local/lib/python3.12/site-packages/airflow/operators/python.py", line 252, in execute_callable
    return self.python_callable(*self.op_args, **self.op_kwargs)
           ^^^^^^^^^^^^^^^^^^^^^^^^^^^^^^^^^^^^^^^^^^^^^^^^^^^^^
  File "/opt/airflow/dags/crawl_dags.py", line 368, in crawl_match_event
    return crawler.match_event()
           ^^^^^^^^^^^^^^^^^^^^^
TypeError: CrawlMatchInfo.match_event() missing 1 required positional argument: 'list_customId'
[2024-07-27T16:43:06.023+0000] {taskinstance.py:1206} INFO - Marking task as UP_FOR_RETRY. dag_id=ETL_SofaScore_Matchday_daily, task_id=crawl_match_event, run_id=scheduled__2023-07-31T00:00:00+00:00, execution_date=20230731T000000, start_date=20240727T164304, end_date=20240727T164306
[2024-07-27T16:43:06.064+0000] {warnings.py:110} WARNING - /home/***/.local/lib/python3.12/site-packages/***/utils/email.py:154: RemovedInAirflow3Warning: Fetching SMTP credentials from configuration variables will be deprecated in a future release. Please set credentials using a connection instead.
  send_mime_email(e_from=mail_from, e_to=recipients, mime_msg=msg, conn_id=conn_id, dryrun=dryrun)

[2024-07-27T16:43:06.069+0000] {configuration.py:1050} WARNING - section/key [smtp/smtp_user] not found in config
[2024-07-27T16:43:06.071+0000] {email.py:271} INFO - Email alerting: attempt 1
[2024-07-27T16:43:06.095+0000] {configuration.py:1050} WARNING - section/key [smtp/smtp_user] not found in config
[2024-07-27T16:43:06.103+0000] {email.py:271} INFO - Email alerting: attempt 1
[2024-07-27T16:43:06.106+0000] {taskinstance.py:879} ERROR - Failed to send email to: nguyenmduc2407@gmail.com
Traceback (most recent call last):
  File "/home/airflow/.local/lib/python3.12/site-packages/airflow/models/taskinstance.py", line 2479, in _run_raw_task
    self._execute_task_with_callbacks(context, test_mode, session=session)
  File "/home/airflow/.local/lib/python3.12/site-packages/airflow/models/taskinstance.py", line 2676, in _execute_task_with_callbacks
    result = self._execute_task(context, task_orig)
             ^^^^^^^^^^^^^^^^^^^^^^^^^^^^^^^^^^^^^^
  File "/home/airflow/.local/lib/python3.12/site-packages/airflow/models/taskinstance.py", line 2701, in _execute_task
    return _execute_task(self, context, task_orig)
           ^^^^^^^^^^^^^^^^^^^^^^^^^^^^^^^^^^^^^^^
  File "/home/airflow/.local/lib/python3.12/site-packages/airflow/models/taskinstance.py", line 465, in _execute_task
    result = _execute_callable(context=context, **execute_callable_kwargs)
             ^^^^^^^^^^^^^^^^^^^^^^^^^^^^^^^^^^^^^^^^^^^^^^^^^^^^^^^^^^^^^
  File "/home/airflow/.local/lib/python3.12/site-packages/airflow/models/taskinstance.py", line 432, in _execute_callable
    return execute_callable(context=context, **execute_callable_kwargs)
           ^^^^^^^^^^^^^^^^^^^^^^^^^^^^^^^^^^^^^^^^^^^^^^^^^^^^^^^^^^^^
  File "/home/airflow/.local/lib/python3.12/site-packages/airflow/models/baseoperator.py", line 400, in wrapper
    return func(self, *args, **kwargs)
           ^^^^^^^^^^^^^^^^^^^^^^^^^^^
  File "/home/airflow/.local/lib/python3.12/site-packages/airflow/operators/python.py", line 235, in execute
    return_value = self.execute_callable()
                   ^^^^^^^^^^^^^^^^^^^^^^^
  File "/home/airflow/.local/lib/python3.12/site-packages/airflow/operators/python.py", line 252, in execute_callable
    return self.python_callable(*self.op_args, **self.op_kwargs)
           ^^^^^^^^^^^^^^^^^^^^^^^^^^^^^^^^^^^^^^^^^^^^^^^^^^^^^
  File "/opt/airflow/dags/crawl_dags.py", line 368, in crawl_match_event
    return crawler.match_event()
           ^^^^^^^^^^^^^^^^^^^^^
TypeError: CrawlMatchInfo.match_event() missing 1 required positional argument: 'list_customId'

During handling of the above exception, another exception occurred:

Traceback (most recent call last):
  File "/home/airflow/.local/lib/python3.12/site-packages/airflow/models/taskinstance.py", line 1063, in _email_alert
    send_email(task.email, subject, html_content)
  File "/home/airflow/.local/lib/python3.12/site-packages/airflow/utils/email.py", line 80, in send_email
    return backend(
           ^^^^^^^^
  File "/home/airflow/.local/lib/python3.12/site-packages/airflow/utils/email.py", line 154, in send_email_smtp
    send_mime_email(e_from=mail_from, e_to=recipients, mime_msg=msg, conn_id=conn_id, dryrun=dryrun)
  File "/home/airflow/.local/lib/python3.12/site-packages/airflow/utils/email.py", line 273, in send_mime_email
    smtp_conn = _get_smtp_connection(smtp_host, smtp_port, smtp_timeout, smtp_ssl)
                ^^^^^^^^^^^^^^^^^^^^^^^^^^^^^^^^^^^^^^^^^^^^^^^^^^^^^^^^^^^^^^^^^^
  File "/home/airflow/.local/lib/python3.12/site-packages/airflow/utils/email.py", line 317, in _get_smtp_connection
    return smtplib.SMTP(host=host, port=port, timeout=timeout)
           ^^^^^^^^^^^^^^^^^^^^^^^^^^^^^^^^^^^^^^^^^^^^^^^^^^^
  File "/usr/local/lib/python3.12/smtplib.py", line 255, in __init__
    (code, msg) = self.connect(host, port)
                  ^^^^^^^^^^^^^^^^^^^^^^^^
  File "/usr/local/lib/python3.12/smtplib.py", line 341, in connect
    self.sock = self._get_socket(host, port, self.timeout)
                ^^^^^^^^^^^^^^^^^^^^^^^^^^^^^^^^^^^^^^^^^^
  File "/usr/local/lib/python3.12/smtplib.py", line 312, in _get_socket
    return socket.create_connection((host, port), timeout,
           ^^^^^^^^^^^^^^^^^^^^^^^^^^^^^^^^^^^^^^^^^^^^^^^
  File "/usr/local/lib/python3.12/socket.py", line 852, in create_connection
    raise exceptions[0]
  File "/usr/local/lib/python3.12/socket.py", line 837, in create_connection
    sock.connect(sa)
ConnectionRefusedError: [Errno 111] Connection refused

During handling of the above exception, another exception occurred:

Traceback (most recent call last):
  File "/home/airflow/.local/lib/python3.12/site-packages/airflow/models/taskinstance.py", line 877, in _handle_failure
    task_instance.email_alert(error, failure_context["task"])
  File "/home/airflow/.local/lib/python3.12/site-packages/airflow/models/taskinstance.py", line 3163, in email_alert
    _email_alert(task_instance=self, exception=exception, task=task)
  File "/home/airflow/.local/lib/python3.12/site-packages/airflow/models/taskinstance.py", line 1065, in _email_alert
    send_email(task.email, subject, html_content_err)
  File "/home/airflow/.local/lib/python3.12/site-packages/airflow/utils/email.py", line 80, in send_email
    return backend(
           ^^^^^^^^
  File "/home/airflow/.local/lib/python3.12/site-packages/airflow/utils/email.py", line 154, in send_email_smtp
    send_mime_email(e_from=mail_from, e_to=recipients, mime_msg=msg, conn_id=conn_id, dryrun=dryrun)
  File "/home/airflow/.local/lib/python3.12/site-packages/airflow/utils/email.py", line 273, in send_mime_email
    smtp_conn = _get_smtp_connection(smtp_host, smtp_port, smtp_timeout, smtp_ssl)
                ^^^^^^^^^^^^^^^^^^^^^^^^^^^^^^^^^^^^^^^^^^^^^^^^^^^^^^^^^^^^^^^^^^
  File "/home/airflow/.local/lib/python3.12/site-packages/airflow/utils/email.py", line 317, in _get_smtp_connection
    return smtplib.SMTP(host=host, port=port, timeout=timeout)
           ^^^^^^^^^^^^^^^^^^^^^^^^^^^^^^^^^^^^^^^^^^^^^^^^^^^
  File "/usr/local/lib/python3.12/smtplib.py", line 255, in __init__
    (code, msg) = self.connect(host, port)
                  ^^^^^^^^^^^^^^^^^^^^^^^^
  File "/usr/local/lib/python3.12/smtplib.py", line 341, in connect
    self.sock = self._get_socket(host, port, self.timeout)
                ^^^^^^^^^^^^^^^^^^^^^^^^^^^^^^^^^^^^^^^^^^
  File "/usr/local/lib/python3.12/smtplib.py", line 312, in _get_socket
    return socket.create_connection((host, port), timeout,
           ^^^^^^^^^^^^^^^^^^^^^^^^^^^^^^^^^^^^^^^^^^^^^^^
  File "/usr/local/lib/python3.12/socket.py", line 852, in create_connection
    raise exceptions[0]
  File "/usr/local/lib/python3.12/socket.py", line 837, in create_connection
    sock.connect(sa)
ConnectionRefusedError: [Errno 111] Connection refused
[2024-07-27T16:43:06.168+0000] {standard_task_runner.py:110} ERROR - Failed to execute job 396 for task crawl_match_event (CrawlMatchInfo.match_event() missing 1 required positional argument: 'list_customId'; 3037)
[2024-07-27T16:43:06.235+0000] {local_task_job_runner.py:240} INFO - Task exited with return code 1
[2024-07-27T16:43:06.253+0000] {local_task_job_runner.py:222} INFO - ::endgroup::
[2024-07-27T17:26:08.038+0000] {local_task_job_runner.py:120} INFO - ::group::Pre task execution logs
[2024-07-27T17:26:08.132+0000] {taskinstance.py:2076} INFO - Dependencies all met for dep_context=non-requeueable deps ti=<TaskInstance: ETL_SofaScore_Matchday_daily.crawl_match_event scheduled__2023-07-31T00:00:00+00:00 [queued]>
[2024-07-27T17:26:08.166+0000] {taskinstance.py:2076} INFO - Dependencies all met for dep_context=requeueable deps ti=<TaskInstance: ETL_SofaScore_Matchday_daily.crawl_match_event scheduled__2023-07-31T00:00:00+00:00 [queued]>
[2024-07-27T17:26:08.167+0000] {taskinstance.py:2306} INFO - Starting attempt 1 of 2
[2024-07-27T17:26:08.206+0000] {taskinstance.py:2330} INFO - Executing <Task(PythonOperator): crawl_match_event> on 2023-07-31 00:00:00+00:00
[2024-07-27T17:26:08.222+0000] {warnings.py:110} WARNING - /home/***/.local/lib/python3.12/site-packages/***/task/task_runner/standard_task_runner.py:61: DeprecationWarning: This process (pid=3632) is multi-threaded, use of fork() may lead to deadlocks in the child.
  pid = os.fork()

[2024-07-27T17:26:08.225+0000] {standard_task_runner.py:63} INFO - Started process 3645 to run task
[2024-07-27T17:26:08.237+0000] {standard_task_runner.py:90} INFO - Running: ['***', 'tasks', 'run', 'ETL_SofaScore_Matchday_daily', 'crawl_match_event', 'scheduled__2023-07-31T00:00:00+00:00', '--job-id', '421', '--raw', '--subdir', 'DAGS_FOLDER/crawl_dags.py', '--cfg-path', '/tmp/tmper2iz6qf']
[2024-07-27T17:26:08.242+0000] {standard_task_runner.py:91} INFO - Job 421: Subtask crawl_match_event
[2024-07-27T17:26:09.209+0000] {task_command.py:426} INFO - Running <TaskInstance: ETL_SofaScore_Matchday_daily.crawl_match_event scheduled__2023-07-31T00:00:00+00:00 [running]> on host fde3e54b98e9
[2024-07-27T17:26:09.350+0000] {taskinstance.py:2648} INFO - Exporting env vars: AIRFLOW_CTX_DAG_EMAIL='nguyenmduc2407@gmail.com' AIRFLOW_CTX_DAG_OWNER='***' AIRFLOW_CTX_DAG_ID='ETL_SofaScore_Matchday_daily' AIRFLOW_CTX_TASK_ID='crawl_match_event' AIRFLOW_CTX_EXECUTION_DATE='2023-07-31T00:00:00+00:00' AIRFLOW_CTX_TRY_NUMBER='1' AIRFLOW_CTX_DAG_RUN_ID='scheduled__2023-07-31T00:00:00+00:00'
[2024-07-27T17:26:09.352+0000] {taskinstance.py:430} INFO - ::endgroup::
[2024-07-27T17:26:09.367+0000] {taskinstance.py:441} INFO - ::group::Post task execution logs
[2024-07-27T17:26:09.369+0000] {taskinstance.py:2905} ERROR - Task failed with exception
Traceback (most recent call last):
  File "/home/airflow/.local/lib/python3.12/site-packages/airflow/models/taskinstance.py", line 465, in _execute_task
    result = _execute_callable(context=context, **execute_callable_kwargs)
             ^^^^^^^^^^^^^^^^^^^^^^^^^^^^^^^^^^^^^^^^^^^^^^^^^^^^^^^^^^^^^
  File "/home/airflow/.local/lib/python3.12/site-packages/airflow/models/taskinstance.py", line 432, in _execute_callable
    return execute_callable(context=context, **execute_callable_kwargs)
           ^^^^^^^^^^^^^^^^^^^^^^^^^^^^^^^^^^^^^^^^^^^^^^^^^^^^^^^^^^^^
  File "/home/airflow/.local/lib/python3.12/site-packages/airflow/models/baseoperator.py", line 400, in wrapper
    return func(self, *args, **kwargs)
           ^^^^^^^^^^^^^^^^^^^^^^^^^^^
  File "/home/airflow/.local/lib/python3.12/site-packages/airflow/operators/python.py", line 235, in execute
    return_value = self.execute_callable()
                   ^^^^^^^^^^^^^^^^^^^^^^^
  File "/home/airflow/.local/lib/python3.12/site-packages/airflow/operators/python.py", line 252, in execute_callable
    return self.python_callable(*self.op_args, **self.op_kwargs)
           ^^^^^^^^^^^^^^^^^^^^^^^^^^^^^^^^^^^^^^^^^^^^^^^^^^^^^
  File "/opt/airflow/dags/crawl_dags.py", line 401, in crawl_match_event
    return crawler.match_event()
           ^^^^^^^^^^^^^^^^^^^^^
  File "/opt/airflow/dags/crawl_dags.py", line 74, in match_event
    matchday = pd.read_id()
               ^^^^^^^^^^
AttributeError: module 'pandas' has no attribute 'read_id'. Did you mean: 'read_hdf'?
[2024-07-27T17:26:09.389+0000] {taskinstance.py:1206} INFO - Marking task as UP_FOR_RETRY. dag_id=ETL_SofaScore_Matchday_daily, task_id=crawl_match_event, run_id=scheduled__2023-07-31T00:00:00+00:00, execution_date=20230731T000000, start_date=20240727T172608, end_date=20240727T172609
[2024-07-27T17:26:09.414+0000] {warnings.py:110} WARNING - /home/***/.local/lib/python3.12/site-packages/***/utils/email.py:154: RemovedInAirflow3Warning: Fetching SMTP credentials from configuration variables will be deprecated in a future release. Please set credentials using a connection instead.
  send_mime_email(e_from=mail_from, e_to=recipients, mime_msg=msg, conn_id=conn_id, dryrun=dryrun)

[2024-07-27T17:26:09.416+0000] {configuration.py:1050} WARNING - section/key [smtp/smtp_user] not found in config
[2024-07-27T17:26:09.417+0000] {email.py:271} INFO - Email alerting: attempt 1
[2024-07-27T17:26:09.427+0000] {configuration.py:1050} WARNING - section/key [smtp/smtp_user] not found in config
[2024-07-27T17:26:09.427+0000] {email.py:271} INFO - Email alerting: attempt 1
[2024-07-27T17:26:09.428+0000] {taskinstance.py:879} ERROR - Failed to send email to: nguyenmduc2407@gmail.com
Traceback (most recent call last):
  File "/home/airflow/.local/lib/python3.12/site-packages/airflow/models/taskinstance.py", line 2479, in _run_raw_task
    self._execute_task_with_callbacks(context, test_mode, session=session)
  File "/home/airflow/.local/lib/python3.12/site-packages/airflow/models/taskinstance.py", line 2676, in _execute_task_with_callbacks
    result = self._execute_task(context, task_orig)
             ^^^^^^^^^^^^^^^^^^^^^^^^^^^^^^^^^^^^^^
  File "/home/airflow/.local/lib/python3.12/site-packages/airflow/models/taskinstance.py", line 2701, in _execute_task
    return _execute_task(self, context, task_orig)
           ^^^^^^^^^^^^^^^^^^^^^^^^^^^^^^^^^^^^^^^
  File "/home/airflow/.local/lib/python3.12/site-packages/airflow/models/taskinstance.py", line 465, in _execute_task
    result = _execute_callable(context=context, **execute_callable_kwargs)
             ^^^^^^^^^^^^^^^^^^^^^^^^^^^^^^^^^^^^^^^^^^^^^^^^^^^^^^^^^^^^^
  File "/home/airflow/.local/lib/python3.12/site-packages/airflow/models/taskinstance.py", line 432, in _execute_callable
    return execute_callable(context=context, **execute_callable_kwargs)
           ^^^^^^^^^^^^^^^^^^^^^^^^^^^^^^^^^^^^^^^^^^^^^^^^^^^^^^^^^^^^
  File "/home/airflow/.local/lib/python3.12/site-packages/airflow/models/baseoperator.py", line 400, in wrapper
    return func(self, *args, **kwargs)
           ^^^^^^^^^^^^^^^^^^^^^^^^^^^
  File "/home/airflow/.local/lib/python3.12/site-packages/airflow/operators/python.py", line 235, in execute
    return_value = self.execute_callable()
                   ^^^^^^^^^^^^^^^^^^^^^^^
  File "/home/airflow/.local/lib/python3.12/site-packages/airflow/operators/python.py", line 252, in execute_callable
    return self.python_callable(*self.op_args, **self.op_kwargs)
           ^^^^^^^^^^^^^^^^^^^^^^^^^^^^^^^^^^^^^^^^^^^^^^^^^^^^^
  File "/opt/airflow/dags/crawl_dags.py", line 401, in crawl_match_event
    return crawler.match_event()
           ^^^^^^^^^^^^^^^^^^^^^
  File "/opt/airflow/dags/crawl_dags.py", line 74, in match_event
    matchday = pd.read_id()
               ^^^^^^^^^^
AttributeError: module 'pandas' has no attribute 'read_id'. Did you mean: 'read_hdf'?

During handling of the above exception, another exception occurred:

Traceback (most recent call last):
  File "/home/airflow/.local/lib/python3.12/site-packages/airflow/models/taskinstance.py", line 1063, in _email_alert
    send_email(task.email, subject, html_content)
  File "/home/airflow/.local/lib/python3.12/site-packages/airflow/utils/email.py", line 80, in send_email
    return backend(
           ^^^^^^^^
  File "/home/airflow/.local/lib/python3.12/site-packages/airflow/utils/email.py", line 154, in send_email_smtp
    send_mime_email(e_from=mail_from, e_to=recipients, mime_msg=msg, conn_id=conn_id, dryrun=dryrun)
  File "/home/airflow/.local/lib/python3.12/site-packages/airflow/utils/email.py", line 273, in send_mime_email
    smtp_conn = _get_smtp_connection(smtp_host, smtp_port, smtp_timeout, smtp_ssl)
                ^^^^^^^^^^^^^^^^^^^^^^^^^^^^^^^^^^^^^^^^^^^^^^^^^^^^^^^^^^^^^^^^^^
  File "/home/airflow/.local/lib/python3.12/site-packages/airflow/utils/email.py", line 317, in _get_smtp_connection
    return smtplib.SMTP(host=host, port=port, timeout=timeout)
           ^^^^^^^^^^^^^^^^^^^^^^^^^^^^^^^^^^^^^^^^^^^^^^^^^^^
  File "/usr/local/lib/python3.12/smtplib.py", line 255, in __init__
    (code, msg) = self.connect(host, port)
                  ^^^^^^^^^^^^^^^^^^^^^^^^
  File "/usr/local/lib/python3.12/smtplib.py", line 341, in connect
    self.sock = self._get_socket(host, port, self.timeout)
                ^^^^^^^^^^^^^^^^^^^^^^^^^^^^^^^^^^^^^^^^^^
  File "/usr/local/lib/python3.12/smtplib.py", line 312, in _get_socket
    return socket.create_connection((host, port), timeout,
           ^^^^^^^^^^^^^^^^^^^^^^^^^^^^^^^^^^^^^^^^^^^^^^^
  File "/usr/local/lib/python3.12/socket.py", line 852, in create_connection
    raise exceptions[0]
  File "/usr/local/lib/python3.12/socket.py", line 837, in create_connection
    sock.connect(sa)
ConnectionRefusedError: [Errno 111] Connection refused

During handling of the above exception, another exception occurred:

Traceback (most recent call last):
  File "/home/airflow/.local/lib/python3.12/site-packages/airflow/models/taskinstance.py", line 877, in _handle_failure
    task_instance.email_alert(error, failure_context["task"])
  File "/home/airflow/.local/lib/python3.12/site-packages/airflow/models/taskinstance.py", line 3163, in email_alert
    _email_alert(task_instance=self, exception=exception, task=task)
  File "/home/airflow/.local/lib/python3.12/site-packages/airflow/models/taskinstance.py", line 1065, in _email_alert
    send_email(task.email, subject, html_content_err)
  File "/home/airflow/.local/lib/python3.12/site-packages/airflow/utils/email.py", line 80, in send_email
    return backend(
           ^^^^^^^^
  File "/home/airflow/.local/lib/python3.12/site-packages/airflow/utils/email.py", line 154, in send_email_smtp
    send_mime_email(e_from=mail_from, e_to=recipients, mime_msg=msg, conn_id=conn_id, dryrun=dryrun)
  File "/home/airflow/.local/lib/python3.12/site-packages/airflow/utils/email.py", line 273, in send_mime_email
    smtp_conn = _get_smtp_connection(smtp_host, smtp_port, smtp_timeout, smtp_ssl)
                ^^^^^^^^^^^^^^^^^^^^^^^^^^^^^^^^^^^^^^^^^^^^^^^^^^^^^^^^^^^^^^^^^^
  File "/home/airflow/.local/lib/python3.12/site-packages/airflow/utils/email.py", line 317, in _get_smtp_connection
    return smtplib.SMTP(host=host, port=port, timeout=timeout)
           ^^^^^^^^^^^^^^^^^^^^^^^^^^^^^^^^^^^^^^^^^^^^^^^^^^^
  File "/usr/local/lib/python3.12/smtplib.py", line 255, in __init__
    (code, msg) = self.connect(host, port)
                  ^^^^^^^^^^^^^^^^^^^^^^^^
  File "/usr/local/lib/python3.12/smtplib.py", line 341, in connect
    self.sock = self._get_socket(host, port, self.timeout)
                ^^^^^^^^^^^^^^^^^^^^^^^^^^^^^^^^^^^^^^^^^^
  File "/usr/local/lib/python3.12/smtplib.py", line 312, in _get_socket
    return socket.create_connection((host, port), timeout,
           ^^^^^^^^^^^^^^^^^^^^^^^^^^^^^^^^^^^^^^^^^^^^^^^
  File "/usr/local/lib/python3.12/socket.py", line 852, in create_connection
    raise exceptions[0]
  File "/usr/local/lib/python3.12/socket.py", line 837, in create_connection
    sock.connect(sa)
ConnectionRefusedError: [Errno 111] Connection refused
[2024-07-27T17:26:09.449+0000] {standard_task_runner.py:110} ERROR - Failed to execute job 421 for task crawl_match_event (module 'pandas' has no attribute 'read_id'; 3645)
[2024-07-27T17:26:09.468+0000] {local_task_job_runner.py:240} INFO - Task exited with return code 1
[2024-07-27T17:26:09.711+0000] {taskinstance.py:3498} INFO - 0 downstream tasks scheduled from follow-on schedule check
[2024-07-27T17:26:09.715+0000] {local_task_job_runner.py:222} INFO - ::endgroup::
