[2024-05-21T16:02:33.424+0000] {local_task_job_runner.py:120} INFO - ::group::Pre task execution logs
[2024-05-21T16:02:33.448+0000] {taskinstance.py:2076} INFO - Dependencies all met for dep_context=non-requeueable deps ti=<TaskInstance: ETL_SofaScore_matchday_daily.crawl_data scheduled__2024-05-10T00:00:00+00:00 [queued]>
[2024-05-21T16:02:33.629+0000] {taskinstance.py:2076} INFO - Dependencies all met for dep_context=requeueable deps ti=<TaskInstance: ETL_SofaScore_matchday_daily.crawl_data scheduled__2024-05-10T00:00:00+00:00 [queued]>
[2024-05-21T16:02:33.636+0000] {taskinstance.py:2306} INFO - Starting attempt 5 of 6
[2024-05-21T16:02:33.653+0000] {taskinstance.py:2330} INFO - Executing <Task(PythonOperator): crawl_data> on 2024-05-10 00:00:00+00:00
[2024-05-21T16:02:33.663+0000] {warnings.py:110} WARNING - /home/***/.local/lib/python3.12/site-packages/***/task/task_runner/standard_task_runner.py:61: DeprecationWarning: This process (pid=1218) is multi-threaded, use of fork() may lead to deadlocks in the child.
  pid = os.fork()

[2024-05-21T16:02:33.665+0000] {standard_task_runner.py:63} INFO - Started process 1220 to run task
[2024-05-21T16:02:33.664+0000] {standard_task_runner.py:90} INFO - Running: ['***', 'tasks', 'run', 'ETL_SofaScore_matchday_daily', 'crawl_data', 'scheduled__2024-05-10T00:00:00+00:00', '--job-id', '62', '--raw', '--subdir', 'DAGS_FOLDER/crawl_dags.py', '--cfg-path', '/tmp/tmpkxvz0ihc']
[2024-05-21T16:02:33.667+0000] {standard_task_runner.py:91} INFO - Job 62: Subtask crawl_data
[2024-05-21T16:02:33.721+0000] {task_command.py:426} INFO - Running <TaskInstance: ETL_SofaScore_matchday_daily.crawl_data scheduled__2024-05-10T00:00:00+00:00 [running]> on host dbddc4e9ac3f
[2024-05-21T16:02:33.921+0000] {taskinstance.py:2648} INFO - Exporting env vars: AIRFLOW_CTX_DAG_EMAIL='nguyenmduc2407@gmail.com' AIRFLOW_CTX_DAG_OWNER='***' AIRFLOW_CTX_DAG_ID='ETL_SofaScore_matchday_daily' AIRFLOW_CTX_TASK_ID='crawl_data' AIRFLOW_CTX_EXECUTION_DATE='2024-05-10T00:00:00+00:00' AIRFLOW_CTX_TRY_NUMBER='5' AIRFLOW_CTX_DAG_RUN_ID='scheduled__2024-05-10T00:00:00+00:00'
[2024-05-21T16:02:33.923+0000] {taskinstance.py:430} INFO - ::endgroup::
[2024-05-21T16:02:35.234+0000] {logging_mixin.py:188} INFO - Dataframe is here!!!
[2024-05-21T16:02:35.299+0000] {logging_mixin.py:188} INFO -      customId  winnerCode  ...  coverage isAwarded
0         rsT         2.0  ...       NaN       NaN
1     KhbsoKj         3.0  ...       NaN       NaN
2     BgbsCGc         1.0  ...       NaN       NaN
3     Xdbsbgb         2.0  ...       NaN       NaN
4     acbsCdb         2.0  ...       NaN       NaN
..        ...         ...  ...       ...       ...
347   yobsFob         2.0  ...       NaN       NaN
348   DobslPi         1.0  ...       NaN       NaN
349  FmnsvARb         2.0  ...       NaN       NaN
350  jYbsgRqb         1.0  ...       NaN       NaN
351   tYbsKdW         2.0  ...       NaN       NaN

[352 rows x 140 columns]
[2024-05-21T16:02:35.300+0000] {taskinstance.py:441} INFO - ::group::Post task execution logs
[2024-05-21T16:02:35.300+0000] {taskinstance.py:2905} ERROR - Task failed with exception
Traceback (most recent call last):
  File "/home/airflow/.local/lib/python3.12/site-packages/airflow/models/taskinstance.py", line 465, in _execute_task
    result = _execute_callable(context=context, **execute_callable_kwargs)
             ^^^^^^^^^^^^^^^^^^^^^^^^^^^^^^^^^^^^^^^^^^^^^^^^^^^^^^^^^^^^^
  File "/home/airflow/.local/lib/python3.12/site-packages/airflow/models/taskinstance.py", line 432, in _execute_callable
    return execute_callable(context=context, **execute_callable_kwargs)
           ^^^^^^^^^^^^^^^^^^^^^^^^^^^^^^^^^^^^^^^^^^^^^^^^^^^^^^^^^^^^
  File "/home/airflow/.local/lib/python3.12/site-packages/airflow/models/baseoperator.py", line 400, in wrapper
    return func(self, *args, **kwargs)
           ^^^^^^^^^^^^^^^^^^^^^^^^^^^
  File "/home/airflow/.local/lib/python3.12/site-packages/airflow/operators/python.py", line 235, in execute
    return_value = self.execute_callable()
                   ^^^^^^^^^^^^^^^^^^^^^^^
  File "/home/airflow/.local/lib/python3.12/site-packages/airflow/operators/python.py", line 252, in execute_callable
    return self.python_callable(*self.op_args, **self.op_kwargs)
           ^^^^^^^^^^^^^^^^^^^^^^^^^^^^^^^^^^^^^^^^^^^^^^^^^^^^^
  File "/opt/airflow/dags/crawl_dags.py", line 63, in crawl_data_callable
    crawler.fetch_data()
  File "/opt/airflow/dags/crawl_dags.py", line 31, in fetch_data
    df.export()
    ^^^^^^^^^
  File "/home/airflow/.local/lib/python3.12/site-packages/pandas/core/generic.py", line 6204, in __getattr__
    return object.__getattribute__(self, name)
           ^^^^^^^^^^^^^^^^^^^^^^^^^^^^^^^^^^^
AttributeError: 'DataFrame' object has no attribute 'export'
[2024-05-21T16:02:35.331+0000] {taskinstance.py:1206} INFO - Marking task as UP_FOR_RETRY. dag_id=ETL_SofaScore_matchday_daily, task_id=crawl_data, run_id=scheduled__2024-05-10T00:00:00+00:00, execution_date=20240510T000000, start_date=20240521T160233, end_date=20240521T160235
[2024-05-21T16:02:35.347+0000] {warnings.py:110} WARNING - /home/***/.local/lib/python3.12/site-packages/***/utils/email.py:154: RemovedInAirflow3Warning: Fetching SMTP credentials from configuration variables will be deprecated in a future release. Please set credentials using a connection instead.
  send_mime_email(e_from=mail_from, e_to=recipients, mime_msg=msg, conn_id=conn_id, dryrun=dryrun)

[2024-05-21T16:02:35.348+0000] {configuration.py:1050} WARNING - section/key [smtp/smtp_user] not found in config
[2024-05-21T16:02:35.349+0000] {email.py:271} INFO - Email alerting: attempt 1
[2024-05-21T16:02:35.357+0000] {configuration.py:1050} WARNING - section/key [smtp/smtp_user] not found in config
[2024-05-21T16:02:35.357+0000] {email.py:271} INFO - Email alerting: attempt 1
[2024-05-21T16:02:35.358+0000] {taskinstance.py:879} ERROR - Failed to send email to: nguyenmduc2407@gmail.com
Traceback (most recent call last):
  File "/home/airflow/.local/lib/python3.12/site-packages/airflow/models/taskinstance.py", line 2479, in _run_raw_task
    self._execute_task_with_callbacks(context, test_mode, session=session)
  File "/home/airflow/.local/lib/python3.12/site-packages/airflow/models/taskinstance.py", line 2676, in _execute_task_with_callbacks
    result = self._execute_task(context, task_orig)
             ^^^^^^^^^^^^^^^^^^^^^^^^^^^^^^^^^^^^^^
  File "/home/airflow/.local/lib/python3.12/site-packages/airflow/models/taskinstance.py", line 2701, in _execute_task
    return _execute_task(self, context, task_orig)
           ^^^^^^^^^^^^^^^^^^^^^^^^^^^^^^^^^^^^^^^
  File "/home/airflow/.local/lib/python3.12/site-packages/airflow/models/taskinstance.py", line 465, in _execute_task
    result = _execute_callable(context=context, **execute_callable_kwargs)
             ^^^^^^^^^^^^^^^^^^^^^^^^^^^^^^^^^^^^^^^^^^^^^^^^^^^^^^^^^^^^^
  File "/home/airflow/.local/lib/python3.12/site-packages/airflow/models/taskinstance.py", line 432, in _execute_callable
    return execute_callable(context=context, **execute_callable_kwargs)
           ^^^^^^^^^^^^^^^^^^^^^^^^^^^^^^^^^^^^^^^^^^^^^^^^^^^^^^^^^^^^
  File "/home/airflow/.local/lib/python3.12/site-packages/airflow/models/baseoperator.py", line 400, in wrapper
    return func(self, *args, **kwargs)
           ^^^^^^^^^^^^^^^^^^^^^^^^^^^
  File "/home/airflow/.local/lib/python3.12/site-packages/airflow/operators/python.py", line 235, in execute
    return_value = self.execute_callable()
                   ^^^^^^^^^^^^^^^^^^^^^^^
  File "/home/airflow/.local/lib/python3.12/site-packages/airflow/operators/python.py", line 252, in execute_callable
    return self.python_callable(*self.op_args, **self.op_kwargs)
           ^^^^^^^^^^^^^^^^^^^^^^^^^^^^^^^^^^^^^^^^^^^^^^^^^^^^^
  File "/opt/airflow/dags/crawl_dags.py", line 63, in crawl_data_callable
    crawler.fetch_data()
  File "/opt/airflow/dags/crawl_dags.py", line 31, in fetch_data
    df.export()
    ^^^^^^^^^
  File "/home/airflow/.local/lib/python3.12/site-packages/pandas/core/generic.py", line 6204, in __getattr__
    return object.__getattribute__(self, name)
           ^^^^^^^^^^^^^^^^^^^^^^^^^^^^^^^^^^^
AttributeError: 'DataFrame' object has no attribute 'export'

During handling of the above exception, another exception occurred:

Traceback (most recent call last):
  File "/home/airflow/.local/lib/python3.12/site-packages/airflow/models/taskinstance.py", line 1063, in _email_alert
    send_email(task.email, subject, html_content)
  File "/home/airflow/.local/lib/python3.12/site-packages/airflow/utils/email.py", line 80, in send_email
    return backend(
           ^^^^^^^^
  File "/home/airflow/.local/lib/python3.12/site-packages/airflow/utils/email.py", line 154, in send_email_smtp
    send_mime_email(e_from=mail_from, e_to=recipients, mime_msg=msg, conn_id=conn_id, dryrun=dryrun)
  File "/home/airflow/.local/lib/python3.12/site-packages/airflow/utils/email.py", line 273, in send_mime_email
    smtp_conn = _get_smtp_connection(smtp_host, smtp_port, smtp_timeout, smtp_ssl)
                ^^^^^^^^^^^^^^^^^^^^^^^^^^^^^^^^^^^^^^^^^^^^^^^^^^^^^^^^^^^^^^^^^^
  File "/home/airflow/.local/lib/python3.12/site-packages/airflow/utils/email.py", line 317, in _get_smtp_connection
    return smtplib.SMTP(host=host, port=port, timeout=timeout)
           ^^^^^^^^^^^^^^^^^^^^^^^^^^^^^^^^^^^^^^^^^^^^^^^^^^^
  File "/usr/local/lib/python3.12/smtplib.py", line 255, in __init__
    (code, msg) = self.connect(host, port)
                  ^^^^^^^^^^^^^^^^^^^^^^^^
  File "/usr/local/lib/python3.12/smtplib.py", line 341, in connect
    self.sock = self._get_socket(host, port, self.timeout)
                ^^^^^^^^^^^^^^^^^^^^^^^^^^^^^^^^^^^^^^^^^^
  File "/usr/local/lib/python3.12/smtplib.py", line 312, in _get_socket
    return socket.create_connection((host, port), timeout,
           ^^^^^^^^^^^^^^^^^^^^^^^^^^^^^^^^^^^^^^^^^^^^^^^
  File "/usr/local/lib/python3.12/socket.py", line 852, in create_connection
    raise exceptions[0]
  File "/usr/local/lib/python3.12/socket.py", line 837, in create_connection
    sock.connect(sa)
ConnectionRefusedError: [Errno 111] Connection refused

During handling of the above exception, another exception occurred:

Traceback (most recent call last):
  File "/home/airflow/.local/lib/python3.12/site-packages/airflow/models/taskinstance.py", line 877, in _handle_failure
    task_instance.email_alert(error, failure_context["task"])
  File "/home/airflow/.local/lib/python3.12/site-packages/airflow/models/taskinstance.py", line 3163, in email_alert
    _email_alert(task_instance=self, exception=exception, task=task)
  File "/home/airflow/.local/lib/python3.12/site-packages/airflow/models/taskinstance.py", line 1065, in _email_alert
    send_email(task.email, subject, html_content_err)
  File "/home/airflow/.local/lib/python3.12/site-packages/airflow/utils/email.py", line 80, in send_email
    return backend(
           ^^^^^^^^
  File "/home/airflow/.local/lib/python3.12/site-packages/airflow/utils/email.py", line 154, in send_email_smtp
    send_mime_email(e_from=mail_from, e_to=recipients, mime_msg=msg, conn_id=conn_id, dryrun=dryrun)
  File "/home/airflow/.local/lib/python3.12/site-packages/airflow/utils/email.py", line 273, in send_mime_email
    smtp_conn = _get_smtp_connection(smtp_host, smtp_port, smtp_timeout, smtp_ssl)
                ^^^^^^^^^^^^^^^^^^^^^^^^^^^^^^^^^^^^^^^^^^^^^^^^^^^^^^^^^^^^^^^^^^
  File "/home/airflow/.local/lib/python3.12/site-packages/airflow/utils/email.py", line 317, in _get_smtp_connection
    return smtplib.SMTP(host=host, port=port, timeout=timeout)
           ^^^^^^^^^^^^^^^^^^^^^^^^^^^^^^^^^^^^^^^^^^^^^^^^^^^
  File "/usr/local/lib/python3.12/smtplib.py", line 255, in __init__
    (code, msg) = self.connect(host, port)
                  ^^^^^^^^^^^^^^^^^^^^^^^^
  File "/usr/local/lib/python3.12/smtplib.py", line 341, in connect
    self.sock = self._get_socket(host, port, self.timeout)
                ^^^^^^^^^^^^^^^^^^^^^^^^^^^^^^^^^^^^^^^^^^
  File "/usr/local/lib/python3.12/smtplib.py", line 312, in _get_socket
    return socket.create_connection((host, port), timeout,
           ^^^^^^^^^^^^^^^^^^^^^^^^^^^^^^^^^^^^^^^^^^^^^^^
  File "/usr/local/lib/python3.12/socket.py", line 852, in create_connection
    raise exceptions[0]
  File "/usr/local/lib/python3.12/socket.py", line 837, in create_connection
    sock.connect(sa)
ConnectionRefusedError: [Errno 111] Connection refused
[2024-05-21T16:02:35.378+0000] {standard_task_runner.py:110} ERROR - Failed to execute job 62 for task crawl_data ('DataFrame' object has no attribute 'export'; 1220)
[2024-05-21T16:02:35.406+0000] {local_task_job_runner.py:240} INFO - Task exited with return code 1
[2024-05-21T16:02:35.427+0000] {taskinstance.py:3498} INFO - 0 downstream tasks scheduled from follow-on schedule check
[2024-05-21T16:02:35.431+0000] {local_task_job_runner.py:222} INFO - ::endgroup::
