[2024-05-20T21:12:20.201+0000] {task_context_logger.py:104} ERROR - Executor reports task instance <TaskInstance: ETL_SofaScore_matchday_daily.start scheduled__2024-05-10T00:00:00+00:00 [queued]> finished (failed) although the task says it's queued. (Info: None) Was the task killed externally?
