[2024-07-27T13:25:49.303+0000] {local_task_job_runner.py:120} INFO - ::group::Pre task execution logs
[2024-07-27T13:25:49.567+0000] {taskinstance.py:2076} INFO - Dependencies all met for dep_context=non-requeueable deps ti=<TaskInstance: ETL_SofaScore_Matchday_daily.crawl_match_lineups scheduled__2023-07-31T00:00:00+00:00 [queued]>
[2024-07-27T13:25:49.665+0000] {taskinstance.py:2076} INFO - Dependencies all met for dep_context=requeueable deps ti=<TaskInstance: ETL_SofaScore_Matchday_daily.crawl_match_lineups scheduled__2023-07-31T00:00:00+00:00 [queued]>
[2024-07-27T13:25:49.673+0000] {taskinstance.py:2306} INFO - Starting attempt 1 of 2
[2024-07-27T13:25:55.385+0000] {taskinstance.py:2330} INFO - Executing <Task(PythonOperator): crawl_match_lineups> on 2023-07-31 00:00:00+00:00
[2024-07-27T13:25:55.474+0000] {warnings.py:110} WARNING - /home/***/.local/lib/python3.12/site-packages/***/task/task_runner/standard_task_runner.py:61: DeprecationWarning: This process (pid=160) is multi-threaded, use of fork() may lead to deadlocks in the child.
  pid = os.fork()

[2024-07-27T13:25:55.505+0000] {standard_task_runner.py:63} INFO - Started process 187 to run task
[2024-07-27T13:25:55.531+0000] {standard_task_runner.py:90} INFO - Running: ['***', 'tasks', 'run', 'ETL_SofaScore_Matchday_daily', 'crawl_match_lineups', 'scheduled__2023-07-31T00:00:00+00:00', '--job-id', '282', '--raw', '--subdir', 'DAGS_FOLDER/crawl_dags.py', '--cfg-path', '/tmp/tmpy36aa72_']
[2024-07-27T13:25:55.563+0000] {standard_task_runner.py:91} INFO - Job 282: Subtask crawl_match_lineups
[2024-07-27T13:25:56.343+0000] {task_command.py:426} INFO - Running <TaskInstance: ETL_SofaScore_Matchday_daily.crawl_match_lineups scheduled__2023-07-31T00:00:00+00:00 [running]> on host fde3e54b98e9
[2024-07-27T13:25:57.032+0000] {taskinstance.py:2648} INFO - Exporting env vars: AIRFLOW_CTX_DAG_EMAIL='nguyenmduc2407@gmail.com' AIRFLOW_CTX_DAG_OWNER='***' AIRFLOW_CTX_DAG_ID='ETL_SofaScore_Matchday_daily' AIRFLOW_CTX_TASK_ID='crawl_match_lineups' AIRFLOW_CTX_EXECUTION_DATE='2023-07-31T00:00:00+00:00' AIRFLOW_CTX_TRY_NUMBER='1' AIRFLOW_CTX_DAG_RUN_ID='scheduled__2023-07-31T00:00:00+00:00'
[2024-07-27T13:25:57.049+0000] {taskinstance.py:430} INFO - ::endgroup::
[2024-07-27T13:25:58.502+0000] {logging_mixin.py:188} INFO - Failed to fetch data for match ID 2. Status code: 404
[2024-07-27T13:26:00.733+0000] {logging_mixin.py:188} INFO - Failed to fetch data for match ID 0. Status code: 404
[2024-07-27T13:26:02.663+0000] {logging_mixin.py:188} INFO - Failed to fetch data for match ID 2. Status code: 404
[2024-07-27T13:26:04.441+0000] {logging_mixin.py:188} INFO - Failed to fetch data for match ID 3. Status code: 404
[2024-07-27T13:26:06.450+0000] {logging_mixin.py:188} INFO - Failed to fetch data for match ID -. Status code: 404
[2024-07-27T13:26:08.408+0000] {logging_mixin.py:188} INFO - Failed to fetch data for match ID 0. Status code: 404
[2024-07-27T13:26:10.387+0000] {logging_mixin.py:188} INFO - Failed to fetch data for match ID 7. Status code: 404
[2024-07-27T13:26:12.369+0000] {logging_mixin.py:188} INFO - Failed to fetch data for match ID -. Status code: 404
[2024-07-27T13:26:14.060+0000] {logging_mixin.py:188} INFO - Failed to fetch data for match ID 3. Status code: 404
[2024-07-27T13:26:16.224+0000] {logging_mixin.py:188} INFO - Failed to fetch data for match ID 1. Status code: 404
[2024-07-27T13:26:17.239+0000] {logging_mixin.py:188} INFO -   match_id  status_code
0        2          404
1        0          404
2        2          404
3        3          404
4        -          404
5        0          404
6        7          404
7        -          404
8        3          404
9        1          404
[2024-07-27T13:26:17.241+0000] {python.py:237} INFO - Done. Returned value was: None
[2024-07-27T13:26:17.242+0000] {taskinstance.py:441} INFO - ::group::Post task execution logs
[2024-07-27T13:26:17.253+0000] {taskinstance.py:1206} INFO - Marking task as SUCCESS. dag_id=ETL_SofaScore_Matchday_daily, task_id=crawl_match_lineups, run_id=scheduled__2023-07-31T00:00:00+00:00, execution_date=20230731T000000, start_date=20240727T132549, end_date=20240727T132617
[2024-07-27T13:26:17.332+0000] {local_task_job_runner.py:240} INFO - Task exited with return code 0
[2024-07-27T13:26:17.355+0000] {taskinstance.py:3498} INFO - 0 downstream tasks scheduled from follow-on schedule check
[2024-07-27T13:26:17.358+0000] {local_task_job_runner.py:222} INFO - ::endgroup::
[2024-07-27T14:18:20.803+0000] {local_task_job_runner.py:120} INFO - ::group::Pre task execution logs
[2024-07-27T14:18:20.912+0000] {taskinstance.py:2076} INFO - Dependencies all met for dep_context=non-requeueable deps ti=<TaskInstance: ETL_SofaScore_Matchday_daily.crawl_match_lineups scheduled__2023-07-31T00:00:00+00:00 [queued]>
[2024-07-27T14:18:20.945+0000] {taskinstance.py:2076} INFO - Dependencies all met for dep_context=requeueable deps ti=<TaskInstance: ETL_SofaScore_Matchday_daily.crawl_match_lineups scheduled__2023-07-31T00:00:00+00:00 [queued]>
[2024-07-27T14:18:20.946+0000] {taskinstance.py:2306} INFO - Starting attempt 1 of 2
[2024-07-27T14:18:23.910+0000] {taskinstance.py:2330} INFO - Executing <Task(PythonOperator): crawl_match_lineups> on 2023-07-31 00:00:00+00:00
[2024-07-27T14:18:23.923+0000] {warnings.py:110} WARNING - /home/***/.local/lib/python3.12/site-packages/***/task/task_runner/standard_task_runner.py:61: DeprecationWarning: This process (pid=915) is multi-threaded, use of fork() may lead to deadlocks in the child.
  pid = os.fork()

[2024-07-27T14:18:23.925+0000] {standard_task_runner.py:63} INFO - Started process 930 to run task
[2024-07-27T14:18:23.925+0000] {standard_task_runner.py:90} INFO - Running: ['***', 'tasks', 'run', 'ETL_SofaScore_Matchday_daily', 'crawl_match_lineups', 'scheduled__2023-07-31T00:00:00+00:00', '--job-id', '314', '--raw', '--subdir', 'DAGS_FOLDER/crawl_dags.py', '--cfg-path', '/tmp/tmphvwtetl1']
[2024-07-27T14:18:23.927+0000] {standard_task_runner.py:91} INFO - Job 314: Subtask crawl_match_lineups
[2024-07-27T14:18:23.996+0000] {task_command.py:426} INFO - Running <TaskInstance: ETL_SofaScore_Matchday_daily.crawl_match_lineups scheduled__2023-07-31T00:00:00+00:00 [running]> on host fde3e54b98e9
[2024-07-27T14:18:24.148+0000] {taskinstance.py:2648} INFO - Exporting env vars: AIRFLOW_CTX_DAG_EMAIL='nguyenmduc2407@gmail.com' AIRFLOW_CTX_DAG_OWNER='***' AIRFLOW_CTX_DAG_ID='ETL_SofaScore_Matchday_daily' AIRFLOW_CTX_TASK_ID='crawl_match_lineups' AIRFLOW_CTX_EXECUTION_DATE='2023-07-31T00:00:00+00:00' AIRFLOW_CTX_TRY_NUMBER='1' AIRFLOW_CTX_DAG_RUN_ID='scheduled__2023-07-31T00:00:00+00:00'
[2024-07-27T14:18:24.151+0000] {taskinstance.py:430} INFO - ::endgroup::
[2024-07-27T14:18:25.125+0000] {logging_mixin.py:188} INFO - Failed to fetch data for match ID 2. Status code: 404
[2024-07-27T14:18:27.030+0000] {logging_mixin.py:188} INFO - Failed to fetch data for match ID 0. Status code: 404
[2024-07-27T14:18:29.220+0000] {logging_mixin.py:188} INFO - Failed to fetch data for match ID 2. Status code: 404
[2024-07-27T14:18:31.390+0000] {logging_mixin.py:188} INFO - Failed to fetch data for match ID 3. Status code: 404
[2024-07-27T14:18:33.322+0000] {logging_mixin.py:188} INFO - Failed to fetch data for match ID -. Status code: 404
[2024-07-27T14:18:35.079+0000] {logging_mixin.py:188} INFO - Failed to fetch data for match ID 0. Status code: 404
[2024-07-27T14:18:36.995+0000] {logging_mixin.py:188} INFO - Failed to fetch data for match ID 7. Status code: 404
[2024-07-27T14:18:38.981+0000] {logging_mixin.py:188} INFO - Failed to fetch data for match ID -. Status code: 404
[2024-07-27T14:18:40.900+0000] {logging_mixin.py:188} INFO - Failed to fetch data for match ID 3. Status code: 404
[2024-07-27T14:18:42.616+0000] {logging_mixin.py:188} INFO - Failed to fetch data for match ID 1. Status code: 404
[2024-07-27T14:18:43.628+0000] {logging_mixin.py:188} INFO -   match_id  status_code
0        2          404
1        0          404
2        2          404
3        3          404
4        -          404
5        0          404
6        7          404
7        -          404
8        3          404
9        1          404
[2024-07-27T14:18:43.743+0000] {logging_mixin.py:188} INFO - Data has been written to the database.
[2024-07-27T14:18:43.746+0000] {python.py:237} INFO - Done. Returned value was: None
[2024-07-27T14:18:43.748+0000] {taskinstance.py:441} INFO - ::group::Post task execution logs
[2024-07-27T14:18:43.760+0000] {taskinstance.py:1206} INFO - Marking task as SUCCESS. dag_id=ETL_SofaScore_Matchday_daily, task_id=crawl_match_lineups, run_id=scheduled__2023-07-31T00:00:00+00:00, execution_date=20230731T000000, start_date=20240727T141820, end_date=20240727T141843
[2024-07-27T14:18:43.816+0000] {local_task_job_runner.py:240} INFO - Task exited with return code 0
[2024-07-27T14:18:43.840+0000] {taskinstance.py:3498} INFO - 1 downstream tasks scheduled from follow-on schedule check
[2024-07-27T14:18:43.843+0000] {local_task_job_runner.py:222} INFO - ::endgroup::
[2024-07-27T15:19:59.597+0000] {local_task_job_runner.py:120} INFO - ::group::Pre task execution logs
[2024-07-27T15:19:59.733+0000] {taskinstance.py:2076} INFO - Dependencies all met for dep_context=non-requeueable deps ti=<TaskInstance: ETL_SofaScore_Matchday_daily.crawl_match_lineups scheduled__2023-07-31T00:00:00+00:00 [queued]>
[2024-07-27T15:19:59.806+0000] {taskinstance.py:2076} INFO - Dependencies all met for dep_context=requeueable deps ti=<TaskInstance: ETL_SofaScore_Matchday_daily.crawl_match_lineups scheduled__2023-07-31T00:00:00+00:00 [queued]>
[2024-07-27T15:19:59.809+0000] {taskinstance.py:2306} INFO - Starting attempt 1 of 2
[2024-07-27T15:19:59.900+0000] {taskinstance.py:2330} INFO - Executing <Task(PythonOperator): crawl_match_lineups> on 2023-07-31 00:00:00+00:00
[2024-07-27T15:19:59.917+0000] {warnings.py:110} WARNING - /home/***/.local/lib/python3.12/site-packages/***/task/task_runner/standard_task_runner.py:61: DeprecationWarning: This process (pid=1769) is multi-threaded, use of fork() may lead to deadlocks in the child.
  pid = os.fork()

[2024-07-27T15:19:59.939+0000] {standard_task_runner.py:63} INFO - Started process 1794 to run task
[2024-07-27T15:19:59.927+0000] {standard_task_runner.py:90} INFO - Running: ['***', 'tasks', 'run', 'ETL_SofaScore_Matchday_daily', 'crawl_match_lineups', 'scheduled__2023-07-31T00:00:00+00:00', '--job-id', '338', '--raw', '--subdir', 'DAGS_FOLDER/crawl_dags.py', '--cfg-path', '/tmp/tmpjnmvc2hc']
[2024-07-27T15:19:59.969+0000] {standard_task_runner.py:91} INFO - Job 338: Subtask crawl_match_lineups
[2024-07-27T15:20:01.155+0000] {task_command.py:426} INFO - Running <TaskInstance: ETL_SofaScore_Matchday_daily.crawl_match_lineups scheduled__2023-07-31T00:00:00+00:00 [running]> on host fde3e54b98e9
[2024-07-27T15:20:01.615+0000] {taskinstance.py:2648} INFO - Exporting env vars: AIRFLOW_CTX_DAG_EMAIL='nguyenmduc2407@gmail.com' AIRFLOW_CTX_DAG_OWNER='***' AIRFLOW_CTX_DAG_ID='ETL_SofaScore_Matchday_daily' AIRFLOW_CTX_TASK_ID='crawl_match_lineups' AIRFLOW_CTX_EXECUTION_DATE='2023-07-31T00:00:00+00:00' AIRFLOW_CTX_TRY_NUMBER='1' AIRFLOW_CTX_DAG_RUN_ID='scheduled__2023-07-31T00:00:00+00:00'
[2024-07-27T15:20:01.617+0000] {taskinstance.py:430} INFO - ::endgroup::
[2024-07-27T15:20:02.902+0000] {logging_mixin.py:188} INFO - Failed to fetch data for match ID 2. Status code: 404
[2024-07-27T15:20:06.734+0000] {logging_mixin.py:188} INFO - Failed to fetch data for match ID 0. Status code: 404
[2024-07-27T15:20:08.829+0000] {logging_mixin.py:188} INFO - Failed to fetch data for match ID 2. Status code: 404
[2024-07-27T15:20:10.538+0000] {logging_mixin.py:188} INFO - Failed to fetch data for match ID 3. Status code: 404
[2024-07-27T15:20:12.521+0000] {logging_mixin.py:188} INFO - Failed to fetch data for match ID -. Status code: 404
[2024-07-27T15:20:14.208+0000] {logging_mixin.py:188} INFO - Failed to fetch data for match ID 0. Status code: 404
[2024-07-27T15:20:16.111+0000] {logging_mixin.py:188} INFO - Failed to fetch data for match ID 7. Status code: 404
[2024-07-27T15:20:18.018+0000] {logging_mixin.py:188} INFO - Failed to fetch data for match ID -. Status code: 404
[2024-07-27T15:20:19.925+0000] {logging_mixin.py:188} INFO - Failed to fetch data for match ID 3. Status code: 404
[2024-07-27T15:20:21.825+0000] {logging_mixin.py:188} INFO - Failed to fetch data for match ID 1. Status code: 404
[2024-07-27T15:20:22.834+0000] {logging_mixin.py:188} INFO -   match_id  status_code
0        2          404
1        0          404
2        2          404
3        3          404
4        -          404
5        0          404
6        7          404
7        -          404
8        3          404
9        1          404
[2024-07-27T15:20:22.945+0000] {logging_mixin.py:188} INFO - Data has been written to the database.
[2024-07-27T15:20:22.948+0000] {python.py:237} INFO - Done. Returned value was: None
[2024-07-27T15:20:22.949+0000] {taskinstance.py:441} INFO - ::group::Post task execution logs
[2024-07-27T15:20:22.959+0000] {taskinstance.py:1206} INFO - Marking task as SUCCESS. dag_id=ETL_SofaScore_Matchday_daily, task_id=crawl_match_lineups, run_id=scheduled__2023-07-31T00:00:00+00:00, execution_date=20230731T000000, start_date=20240727T151959, end_date=20240727T152022
[2024-07-27T15:20:23.017+0000] {local_task_job_runner.py:240} INFO - Task exited with return code 0
[2024-07-27T15:20:23.041+0000] {taskinstance.py:3498} INFO - 0 downstream tasks scheduled from follow-on schedule check
[2024-07-27T15:20:23.044+0000] {local_task_job_runner.py:222} INFO - ::endgroup::
[2024-07-27T15:55:02.476+0000] {local_task_job_runner.py:120} INFO - ::group::Pre task execution logs
[2024-07-27T15:55:02.549+0000] {taskinstance.py:2076} INFO - Dependencies all met for dep_context=non-requeueable deps ti=<TaskInstance: ETL_SofaScore_Matchday_daily.crawl_match_lineups scheduled__2023-07-31T00:00:00+00:00 [queued]>
[2024-07-27T15:55:02.587+0000] {taskinstance.py:2076} INFO - Dependencies all met for dep_context=requeueable deps ti=<TaskInstance: ETL_SofaScore_Matchday_daily.crawl_match_lineups scheduled__2023-07-31T00:00:00+00:00 [queued]>
[2024-07-27T15:55:02.588+0000] {taskinstance.py:2306} INFO - Starting attempt 1 of 2
[2024-07-27T15:55:03.218+0000] {taskinstance.py:2330} INFO - Executing <Task(PythonOperator): crawl_match_lineups> on 2023-07-31 00:00:00+00:00
[2024-07-27T15:55:03.232+0000] {warnings.py:110} WARNING - /home/***/.local/lib/python3.12/site-packages/***/task/task_runner/standard_task_runner.py:61: DeprecationWarning: This process (pid=2285) is multi-threaded, use of fork() may lead to deadlocks in the child.
  pid = os.fork()

[2024-07-27T15:55:03.236+0000] {standard_task_runner.py:63} INFO - Started process 2306 to run task
[2024-07-27T15:55:03.247+0000] {standard_task_runner.py:90} INFO - Running: ['***', 'tasks', 'run', 'ETL_SofaScore_Matchday_daily', 'crawl_match_lineups', 'scheduled__2023-07-31T00:00:00+00:00', '--job-id', '361', '--raw', '--subdir', 'DAGS_FOLDER/crawl_dags.py', '--cfg-path', '/tmp/tmpv6e1pmq9']
[2024-07-27T15:55:03.251+0000] {standard_task_runner.py:91} INFO - Job 361: Subtask crawl_match_lineups
[2024-07-27T15:55:03.370+0000] {task_command.py:426} INFO - Running <TaskInstance: ETL_SofaScore_Matchday_daily.crawl_match_lineups scheduled__2023-07-31T00:00:00+00:00 [running]> on host fde3e54b98e9
[2024-07-27T15:55:03.535+0000] {taskinstance.py:2648} INFO - Exporting env vars: AIRFLOW_CTX_DAG_EMAIL='nguyenmduc2407@gmail.com' AIRFLOW_CTX_DAG_OWNER='***' AIRFLOW_CTX_DAG_ID='ETL_SofaScore_Matchday_daily' AIRFLOW_CTX_TASK_ID='crawl_match_lineups' AIRFLOW_CTX_EXECUTION_DATE='2023-07-31T00:00:00+00:00' AIRFLOW_CTX_TRY_NUMBER='1' AIRFLOW_CTX_DAG_RUN_ID='scheduled__2023-07-31T00:00:00+00:00'
[2024-07-27T15:55:03.537+0000] {taskinstance.py:430} INFO - ::endgroup::
[2024-07-27T15:55:03.586+0000] {taskinstance.py:441} INFO - ::group::Post task execution logs
[2024-07-27T15:55:03.587+0000] {taskinstance.py:2905} ERROR - Task failed with exception
Traceback (most recent call last):
  File "/home/airflow/.local/lib/python3.12/site-packages/airflow/models/taskinstance.py", line 465, in _execute_task
    result = _execute_callable(context=context, **execute_callable_kwargs)
             ^^^^^^^^^^^^^^^^^^^^^^^^^^^^^^^^^^^^^^^^^^^^^^^^^^^^^^^^^^^^^
  File "/home/airflow/.local/lib/python3.12/site-packages/airflow/models/taskinstance.py", line 432, in _execute_callable
    return execute_callable(context=context, **execute_callable_kwargs)
           ^^^^^^^^^^^^^^^^^^^^^^^^^^^^^^^^^^^^^^^^^^^^^^^^^^^^^^^^^^^^
  File "/home/airflow/.local/lib/python3.12/site-packages/airflow/models/baseoperator.py", line 400, in wrapper
    return func(self, *args, **kwargs)
           ^^^^^^^^^^^^^^^^^^^^^^^^^^^
  File "/home/airflow/.local/lib/python3.12/site-packages/airflow/operators/python.py", line 235, in execute
    return_value = self.execute_callable()
                   ^^^^^^^^^^^^^^^^^^^^^^^
  File "/home/airflow/.local/lib/python3.12/site-packages/airflow/operators/python.py", line 252, in execute_callable
    return self.python_callable(*self.op_args, **self.op_kwargs)
           ^^^^^^^^^^^^^^^^^^^^^^^^^^^^^^^^^^^^^^^^^^^^^^^^^^^^^
  File "/opt/airflow/dags/crawl_dags.py", line 386, in crawl_match_lineups
    match_ids, _ = ti.xcom_pull(task_ids='crawl_data')
    ^^^^^^^^^^^^
TypeError: cannot unpack non-iterable NoneType object
[2024-07-27T15:55:03.606+0000] {taskinstance.py:1206} INFO - Marking task as UP_FOR_RETRY. dag_id=ETL_SofaScore_Matchday_daily, task_id=crawl_match_lineups, run_id=scheduled__2023-07-31T00:00:00+00:00, execution_date=20230731T000000, start_date=20240727T155502, end_date=20240727T155503
[2024-07-27T15:55:03.641+0000] {warnings.py:110} WARNING - /home/***/.local/lib/python3.12/site-packages/***/utils/email.py:154: RemovedInAirflow3Warning: Fetching SMTP credentials from configuration variables will be deprecated in a future release. Please set credentials using a connection instead.
  send_mime_email(e_from=mail_from, e_to=recipients, mime_msg=msg, conn_id=conn_id, dryrun=dryrun)

[2024-07-27T15:55:03.643+0000] {configuration.py:1050} WARNING - section/key [smtp/smtp_user] not found in config
[2024-07-27T15:55:03.644+0000] {email.py:271} INFO - Email alerting: attempt 1
[2024-07-27T15:55:03.656+0000] {configuration.py:1050} WARNING - section/key [smtp/smtp_user] not found in config
[2024-07-27T15:55:03.657+0000] {email.py:271} INFO - Email alerting: attempt 1
[2024-07-27T15:55:03.658+0000] {taskinstance.py:879} ERROR - Failed to send email to: nguyenmduc2407@gmail.com
Traceback (most recent call last):
  File "/home/airflow/.local/lib/python3.12/site-packages/airflow/models/taskinstance.py", line 2479, in _run_raw_task
    self._execute_task_with_callbacks(context, test_mode, session=session)
  File "/home/airflow/.local/lib/python3.12/site-packages/airflow/models/taskinstance.py", line 2676, in _execute_task_with_callbacks
    result = self._execute_task(context, task_orig)
             ^^^^^^^^^^^^^^^^^^^^^^^^^^^^^^^^^^^^^^
  File "/home/airflow/.local/lib/python3.12/site-packages/airflow/models/taskinstance.py", line 2701, in _execute_task
    return _execute_task(self, context, task_orig)
           ^^^^^^^^^^^^^^^^^^^^^^^^^^^^^^^^^^^^^^^
  File "/home/airflow/.local/lib/python3.12/site-packages/airflow/models/taskinstance.py", line 465, in _execute_task
    result = _execute_callable(context=context, **execute_callable_kwargs)
             ^^^^^^^^^^^^^^^^^^^^^^^^^^^^^^^^^^^^^^^^^^^^^^^^^^^^^^^^^^^^^
  File "/home/airflow/.local/lib/python3.12/site-packages/airflow/models/taskinstance.py", line 432, in _execute_callable
    return execute_callable(context=context, **execute_callable_kwargs)
           ^^^^^^^^^^^^^^^^^^^^^^^^^^^^^^^^^^^^^^^^^^^^^^^^^^^^^^^^^^^^
  File "/home/airflow/.local/lib/python3.12/site-packages/airflow/models/baseoperator.py", line 400, in wrapper
    return func(self, *args, **kwargs)
           ^^^^^^^^^^^^^^^^^^^^^^^^^^^
  File "/home/airflow/.local/lib/python3.12/site-packages/airflow/operators/python.py", line 235, in execute
    return_value = self.execute_callable()
                   ^^^^^^^^^^^^^^^^^^^^^^^
  File "/home/airflow/.local/lib/python3.12/site-packages/airflow/operators/python.py", line 252, in execute_callable
    return self.python_callable(*self.op_args, **self.op_kwargs)
           ^^^^^^^^^^^^^^^^^^^^^^^^^^^^^^^^^^^^^^^^^^^^^^^^^^^^^
  File "/opt/airflow/dags/crawl_dags.py", line 386, in crawl_match_lineups
    match_ids, _ = ti.xcom_pull(task_ids='crawl_data')
    ^^^^^^^^^^^^
TypeError: cannot unpack non-iterable NoneType object

During handling of the above exception, another exception occurred:

Traceback (most recent call last):
  File "/home/airflow/.local/lib/python3.12/site-packages/airflow/models/taskinstance.py", line 1063, in _email_alert
    send_email(task.email, subject, html_content)
  File "/home/airflow/.local/lib/python3.12/site-packages/airflow/utils/email.py", line 80, in send_email
    return backend(
           ^^^^^^^^
  File "/home/airflow/.local/lib/python3.12/site-packages/airflow/utils/email.py", line 154, in send_email_smtp
    send_mime_email(e_from=mail_from, e_to=recipients, mime_msg=msg, conn_id=conn_id, dryrun=dryrun)
  File "/home/airflow/.local/lib/python3.12/site-packages/airflow/utils/email.py", line 273, in send_mime_email
    smtp_conn = _get_smtp_connection(smtp_host, smtp_port, smtp_timeout, smtp_ssl)
                ^^^^^^^^^^^^^^^^^^^^^^^^^^^^^^^^^^^^^^^^^^^^^^^^^^^^^^^^^^^^^^^^^^
  File "/home/airflow/.local/lib/python3.12/site-packages/airflow/utils/email.py", line 317, in _get_smtp_connection
    return smtplib.SMTP(host=host, port=port, timeout=timeout)
           ^^^^^^^^^^^^^^^^^^^^^^^^^^^^^^^^^^^^^^^^^^^^^^^^^^^
  File "/usr/local/lib/python3.12/smtplib.py", line 255, in __init__
    (code, msg) = self.connect(host, port)
                  ^^^^^^^^^^^^^^^^^^^^^^^^
  File "/usr/local/lib/python3.12/smtplib.py", line 341, in connect
    self.sock = self._get_socket(host, port, self.timeout)
                ^^^^^^^^^^^^^^^^^^^^^^^^^^^^^^^^^^^^^^^^^^
  File "/usr/local/lib/python3.12/smtplib.py", line 312, in _get_socket
    return socket.create_connection((host, port), timeout,
           ^^^^^^^^^^^^^^^^^^^^^^^^^^^^^^^^^^^^^^^^^^^^^^^
  File "/usr/local/lib/python3.12/socket.py", line 852, in create_connection
    raise exceptions[0]
  File "/usr/local/lib/python3.12/socket.py", line 837, in create_connection
    sock.connect(sa)
ConnectionRefusedError: [Errno 111] Connection refused

During handling of the above exception, another exception occurred:

Traceback (most recent call last):
  File "/home/airflow/.local/lib/python3.12/site-packages/airflow/models/taskinstance.py", line 877, in _handle_failure
    task_instance.email_alert(error, failure_context["task"])
  File "/home/airflow/.local/lib/python3.12/site-packages/airflow/models/taskinstance.py", line 3163, in email_alert
    _email_alert(task_instance=self, exception=exception, task=task)
  File "/home/airflow/.local/lib/python3.12/site-packages/airflow/models/taskinstance.py", line 1065, in _email_alert
    send_email(task.email, subject, html_content_err)
  File "/home/airflow/.local/lib/python3.12/site-packages/airflow/utils/email.py", line 80, in send_email
    return backend(
           ^^^^^^^^
  File "/home/airflow/.local/lib/python3.12/site-packages/airflow/utils/email.py", line 154, in send_email_smtp
    send_mime_email(e_from=mail_from, e_to=recipients, mime_msg=msg, conn_id=conn_id, dryrun=dryrun)
  File "/home/airflow/.local/lib/python3.12/site-packages/airflow/utils/email.py", line 273, in send_mime_email
    smtp_conn = _get_smtp_connection(smtp_host, smtp_port, smtp_timeout, smtp_ssl)
                ^^^^^^^^^^^^^^^^^^^^^^^^^^^^^^^^^^^^^^^^^^^^^^^^^^^^^^^^^^^^^^^^^^
  File "/home/airflow/.local/lib/python3.12/site-packages/airflow/utils/email.py", line 317, in _get_smtp_connection
    return smtplib.SMTP(host=host, port=port, timeout=timeout)
           ^^^^^^^^^^^^^^^^^^^^^^^^^^^^^^^^^^^^^^^^^^^^^^^^^^^
  File "/usr/local/lib/python3.12/smtplib.py", line 255, in __init__
    (code, msg) = self.connect(host, port)
                  ^^^^^^^^^^^^^^^^^^^^^^^^
  File "/usr/local/lib/python3.12/smtplib.py", line 341, in connect
    self.sock = self._get_socket(host, port, self.timeout)
                ^^^^^^^^^^^^^^^^^^^^^^^^^^^^^^^^^^^^^^^^^^
  File "/usr/local/lib/python3.12/smtplib.py", line 312, in _get_socket
    return socket.create_connection((host, port), timeout,
           ^^^^^^^^^^^^^^^^^^^^^^^^^^^^^^^^^^^^^^^^^^^^^^^
  File "/usr/local/lib/python3.12/socket.py", line 852, in create_connection
    raise exceptions[0]
  File "/usr/local/lib/python3.12/socket.py", line 837, in create_connection
    sock.connect(sa)
ConnectionRefusedError: [Errno 111] Connection refused
[2024-07-27T15:55:03.690+0000] {standard_task_runner.py:110} ERROR - Failed to execute job 361 for task crawl_match_lineups (cannot unpack non-iterable NoneType object; 2306)
[2024-07-27T15:55:03.744+0000] {local_task_job_runner.py:240} INFO - Task exited with return code 1
[2024-07-27T15:55:03.760+0000] {local_task_job_runner.py:222} INFO - ::endgroup::
[2024-07-27T16:31:03.625+0000] {local_task_job_runner.py:120} INFO - ::group::Pre task execution logs
[2024-07-27T16:31:03.675+0000] {taskinstance.py:2076} INFO - Dependencies all met for dep_context=non-requeueable deps ti=<TaskInstance: ETL_SofaScore_Matchday_daily.crawl_match_lineups scheduled__2023-07-31T00:00:00+00:00 [queued]>
[2024-07-27T16:31:03.692+0000] {taskinstance.py:2076} INFO - Dependencies all met for dep_context=requeueable deps ti=<TaskInstance: ETL_SofaScore_Matchday_daily.crawl_match_lineups scheduled__2023-07-31T00:00:00+00:00 [queued]>
[2024-07-27T16:31:03.693+0000] {taskinstance.py:2306} INFO - Starting attempt 1 of 2
[2024-07-27T16:31:03.723+0000] {taskinstance.py:2330} INFO - Executing <Task(PythonOperator): crawl_match_lineups> on 2023-07-31 00:00:00+00:00
[2024-07-27T16:31:03.740+0000] {warnings.py:110} WARNING - /home/***/.local/lib/python3.12/site-packages/***/task/task_runner/standard_task_runner.py:61: DeprecationWarning: This process (pid=2787) is multi-threaded, use of fork() may lead to deadlocks in the child.
  pid = os.fork()

[2024-07-27T16:31:03.746+0000] {standard_task_runner.py:63} INFO - Started process 2800 to run task
[2024-07-27T16:31:03.746+0000] {standard_task_runner.py:90} INFO - Running: ['***', 'tasks', 'run', 'ETL_SofaScore_Matchday_daily', 'crawl_match_lineups', 'scheduled__2023-07-31T00:00:00+00:00', '--job-id', '371', '--raw', '--subdir', 'DAGS_FOLDER/crawl_dags.py', '--cfg-path', '/tmp/tmpv5e77c2q']
[2024-07-27T16:31:03.756+0000] {standard_task_runner.py:91} INFO - Job 371: Subtask crawl_match_lineups
[2024-07-27T16:31:04.319+0000] {task_command.py:426} INFO - Running <TaskInstance: ETL_SofaScore_Matchday_daily.crawl_match_lineups scheduled__2023-07-31T00:00:00+00:00 [running]> on host fde3e54b98e9
[2024-07-27T16:31:04.489+0000] {taskinstance.py:2648} INFO - Exporting env vars: AIRFLOW_CTX_DAG_EMAIL='nguyenmduc2407@gmail.com' AIRFLOW_CTX_DAG_OWNER='***' AIRFLOW_CTX_DAG_ID='ETL_SofaScore_Matchday_daily' AIRFLOW_CTX_TASK_ID='crawl_match_lineups' AIRFLOW_CTX_EXECUTION_DATE='2023-07-31T00:00:00+00:00' AIRFLOW_CTX_TRY_NUMBER='1' AIRFLOW_CTX_DAG_RUN_ID='scheduled__2023-07-31T00:00:00+00:00'
[2024-07-27T16:31:04.494+0000] {taskinstance.py:430} INFO - ::endgroup::
[2024-07-27T16:31:04.516+0000] {taskinstance.py:441} INFO - ::group::Post task execution logs
[2024-07-27T16:31:04.517+0000] {taskinstance.py:2905} ERROR - Task failed with exception
Traceback (most recent call last):
  File "/home/airflow/.local/lib/python3.12/site-packages/airflow/models/taskinstance.py", line 465, in _execute_task
    result = _execute_callable(context=context, **execute_callable_kwargs)
             ^^^^^^^^^^^^^^^^^^^^^^^^^^^^^^^^^^^^^^^^^^^^^^^^^^^^^^^^^^^^^
  File "/home/airflow/.local/lib/python3.12/site-packages/airflow/models/taskinstance.py", line 432, in _execute_callable
    return execute_callable(context=context, **execute_callable_kwargs)
           ^^^^^^^^^^^^^^^^^^^^^^^^^^^^^^^^^^^^^^^^^^^^^^^^^^^^^^^^^^^^
  File "/home/airflow/.local/lib/python3.12/site-packages/airflow/models/baseoperator.py", line 400, in wrapper
    return func(self, *args, **kwargs)
           ^^^^^^^^^^^^^^^^^^^^^^^^^^^
  File "/home/airflow/.local/lib/python3.12/site-packages/airflow/operators/python.py", line 235, in execute
    return_value = self.execute_callable()
                   ^^^^^^^^^^^^^^^^^^^^^^^
  File "/home/airflow/.local/lib/python3.12/site-packages/airflow/operators/python.py", line 252, in execute_callable
    return self.python_callable(*self.op_args, **self.op_kwargs)
           ^^^^^^^^^^^^^^^^^^^^^^^^^^^^^^^^^^^^^^^^^^^^^^^^^^^^^
TypeError: crawl_match_lineups() missing 1 required positional argument: 'list_match_id'
[2024-07-27T16:31:04.537+0000] {taskinstance.py:1206} INFO - Marking task as UP_FOR_RETRY. dag_id=ETL_SofaScore_Matchday_daily, task_id=crawl_match_lineups, run_id=scheduled__2023-07-31T00:00:00+00:00, execution_date=20230731T000000, start_date=20240727T163103, end_date=20240727T163104
[2024-07-27T16:31:04.564+0000] {warnings.py:110} WARNING - /home/***/.local/lib/python3.12/site-packages/***/utils/email.py:154: RemovedInAirflow3Warning: Fetching SMTP credentials from configuration variables will be deprecated in a future release. Please set credentials using a connection instead.
  send_mime_email(e_from=mail_from, e_to=recipients, mime_msg=msg, conn_id=conn_id, dryrun=dryrun)

[2024-07-27T16:31:04.565+0000] {configuration.py:1050} WARNING - section/key [smtp/smtp_user] not found in config
[2024-07-27T16:31:04.566+0000] {email.py:271} INFO - Email alerting: attempt 1
[2024-07-27T16:31:04.582+0000] {configuration.py:1050} WARNING - section/key [smtp/smtp_user] not found in config
[2024-07-27T16:31:04.583+0000] {email.py:271} INFO - Email alerting: attempt 1
[2024-07-27T16:31:04.587+0000] {taskinstance.py:879} ERROR - Failed to send email to: nguyenmduc2407@gmail.com
Traceback (most recent call last):
  File "/home/airflow/.local/lib/python3.12/site-packages/airflow/models/taskinstance.py", line 2479, in _run_raw_task
    self._execute_task_with_callbacks(context, test_mode, session=session)
  File "/home/airflow/.local/lib/python3.12/site-packages/airflow/models/taskinstance.py", line 2676, in _execute_task_with_callbacks
    result = self._execute_task(context, task_orig)
             ^^^^^^^^^^^^^^^^^^^^^^^^^^^^^^^^^^^^^^
  File "/home/airflow/.local/lib/python3.12/site-packages/airflow/models/taskinstance.py", line 2701, in _execute_task
    return _execute_task(self, context, task_orig)
           ^^^^^^^^^^^^^^^^^^^^^^^^^^^^^^^^^^^^^^^
  File "/home/airflow/.local/lib/python3.12/site-packages/airflow/models/taskinstance.py", line 465, in _execute_task
    result = _execute_callable(context=context, **execute_callable_kwargs)
             ^^^^^^^^^^^^^^^^^^^^^^^^^^^^^^^^^^^^^^^^^^^^^^^^^^^^^^^^^^^^^
  File "/home/airflow/.local/lib/python3.12/site-packages/airflow/models/taskinstance.py", line 432, in _execute_callable
    return execute_callable(context=context, **execute_callable_kwargs)
           ^^^^^^^^^^^^^^^^^^^^^^^^^^^^^^^^^^^^^^^^^^^^^^^^^^^^^^^^^^^^
  File "/home/airflow/.local/lib/python3.12/site-packages/airflow/models/baseoperator.py", line 400, in wrapper
    return func(self, *args, **kwargs)
           ^^^^^^^^^^^^^^^^^^^^^^^^^^^
  File "/home/airflow/.local/lib/python3.12/site-packages/airflow/operators/python.py", line 235, in execute
    return_value = self.execute_callable()
                   ^^^^^^^^^^^^^^^^^^^^^^^
  File "/home/airflow/.local/lib/python3.12/site-packages/airflow/operators/python.py", line 252, in execute_callable
    return self.python_callable(*self.op_args, **self.op_kwargs)
           ^^^^^^^^^^^^^^^^^^^^^^^^^^^^^^^^^^^^^^^^^^^^^^^^^^^^^
TypeError: crawl_match_lineups() missing 1 required positional argument: 'list_match_id'

During handling of the above exception, another exception occurred:

Traceback (most recent call last):
  File "/home/airflow/.local/lib/python3.12/site-packages/airflow/models/taskinstance.py", line 1063, in _email_alert
    send_email(task.email, subject, html_content)
  File "/home/airflow/.local/lib/python3.12/site-packages/airflow/utils/email.py", line 80, in send_email
    return backend(
           ^^^^^^^^
  File "/home/airflow/.local/lib/python3.12/site-packages/airflow/utils/email.py", line 154, in send_email_smtp
    send_mime_email(e_from=mail_from, e_to=recipients, mime_msg=msg, conn_id=conn_id, dryrun=dryrun)
  File "/home/airflow/.local/lib/python3.12/site-packages/airflow/utils/email.py", line 273, in send_mime_email
    smtp_conn = _get_smtp_connection(smtp_host, smtp_port, smtp_timeout, smtp_ssl)
                ^^^^^^^^^^^^^^^^^^^^^^^^^^^^^^^^^^^^^^^^^^^^^^^^^^^^^^^^^^^^^^^^^^
  File "/home/airflow/.local/lib/python3.12/site-packages/airflow/utils/email.py", line 317, in _get_smtp_connection
    return smtplib.SMTP(host=host, port=port, timeout=timeout)
           ^^^^^^^^^^^^^^^^^^^^^^^^^^^^^^^^^^^^^^^^^^^^^^^^^^^
  File "/usr/local/lib/python3.12/smtplib.py", line 255, in __init__
    (code, msg) = self.connect(host, port)
                  ^^^^^^^^^^^^^^^^^^^^^^^^
  File "/usr/local/lib/python3.12/smtplib.py", line 341, in connect
    self.sock = self._get_socket(host, port, self.timeout)
                ^^^^^^^^^^^^^^^^^^^^^^^^^^^^^^^^^^^^^^^^^^
  File "/usr/local/lib/python3.12/smtplib.py", line 312, in _get_socket
    return socket.create_connection((host, port), timeout,
           ^^^^^^^^^^^^^^^^^^^^^^^^^^^^^^^^^^^^^^^^^^^^^^^
  File "/usr/local/lib/python3.12/socket.py", line 852, in create_connection
    raise exceptions[0]
  File "/usr/local/lib/python3.12/socket.py", line 837, in create_connection
    sock.connect(sa)
ConnectionRefusedError: [Errno 111] Connection refused

During handling of the above exception, another exception occurred:

Traceback (most recent call last):
  File "/home/airflow/.local/lib/python3.12/site-packages/airflow/models/taskinstance.py", line 877, in _handle_failure
    task_instance.email_alert(error, failure_context["task"])
  File "/home/airflow/.local/lib/python3.12/site-packages/airflow/models/taskinstance.py", line 3163, in email_alert
    _email_alert(task_instance=self, exception=exception, task=task)
  File "/home/airflow/.local/lib/python3.12/site-packages/airflow/models/taskinstance.py", line 1065, in _email_alert
    send_email(task.email, subject, html_content_err)
  File "/home/airflow/.local/lib/python3.12/site-packages/airflow/utils/email.py", line 80, in send_email
    return backend(
           ^^^^^^^^
  File "/home/airflow/.local/lib/python3.12/site-packages/airflow/utils/email.py", line 154, in send_email_smtp
    send_mime_email(e_from=mail_from, e_to=recipients, mime_msg=msg, conn_id=conn_id, dryrun=dryrun)
  File "/home/airflow/.local/lib/python3.12/site-packages/airflow/utils/email.py", line 273, in send_mime_email
    smtp_conn = _get_smtp_connection(smtp_host, smtp_port, smtp_timeout, smtp_ssl)
                ^^^^^^^^^^^^^^^^^^^^^^^^^^^^^^^^^^^^^^^^^^^^^^^^^^^^^^^^^^^^^^^^^^
  File "/home/airflow/.local/lib/python3.12/site-packages/airflow/utils/email.py", line 317, in _get_smtp_connection
    return smtplib.SMTP(host=host, port=port, timeout=timeout)
           ^^^^^^^^^^^^^^^^^^^^^^^^^^^^^^^^^^^^^^^^^^^^^^^^^^^
  File "/usr/local/lib/python3.12/smtplib.py", line 255, in __init__
    (code, msg) = self.connect(host, port)
                  ^^^^^^^^^^^^^^^^^^^^^^^^
  File "/usr/local/lib/python3.12/smtplib.py", line 341, in connect
    self.sock = self._get_socket(host, port, self.timeout)
                ^^^^^^^^^^^^^^^^^^^^^^^^^^^^^^^^^^^^^^^^^^
  File "/usr/local/lib/python3.12/smtplib.py", line 312, in _get_socket
    return socket.create_connection((host, port), timeout,
           ^^^^^^^^^^^^^^^^^^^^^^^^^^^^^^^^^^^^^^^^^^^^^^^
  File "/usr/local/lib/python3.12/socket.py", line 852, in create_connection
    raise exceptions[0]
  File "/usr/local/lib/python3.12/socket.py", line 837, in create_connection
    sock.connect(sa)
ConnectionRefusedError: [Errno 111] Connection refused
[2024-07-27T16:31:04.618+0000] {standard_task_runner.py:110} ERROR - Failed to execute job 371 for task crawl_match_lineups (crawl_match_lineups() missing 1 required positional argument: 'list_match_id'; 2800)
[2024-07-27T16:31:04.654+0000] {local_task_job_runner.py:240} INFO - Task exited with return code 1
[2024-07-27T16:31:04.909+0000] {taskinstance.py:3498} INFO - 0 downstream tasks scheduled from follow-on schedule check
[2024-07-27T16:31:04.912+0000] {local_task_job_runner.py:222} INFO - ::endgroup::
[2024-07-27T16:37:30.545+0000] {local_task_job_runner.py:120} INFO - ::group::Pre task execution logs
[2024-07-27T16:37:30.603+0000] {taskinstance.py:2076} INFO - Dependencies all met for dep_context=non-requeueable deps ti=<TaskInstance: ETL_SofaScore_Matchday_daily.crawl_match_lineups scheduled__2023-07-31T00:00:00+00:00 [queued]>
[2024-07-27T16:37:30.624+0000] {taskinstance.py:2076} INFO - Dependencies all met for dep_context=requeueable deps ti=<TaskInstance: ETL_SofaScore_Matchday_daily.crawl_match_lineups scheduled__2023-07-31T00:00:00+00:00 [queued]>
[2024-07-27T16:37:30.625+0000] {taskinstance.py:2306} INFO - Starting attempt 1 of 2
[2024-07-27T16:37:30.942+0000] {taskinstance.py:2330} INFO - Executing <Task(PythonOperator): crawl_match_lineups> on 2023-07-31 00:00:00+00:00
[2024-07-27T16:37:30.961+0000] {warnings.py:110} WARNING - /home/***/.local/lib/python3.12/site-packages/***/task/task_runner/standard_task_runner.py:61: DeprecationWarning: This process (pid=2908) is multi-threaded, use of fork() may lead to deadlocks in the child.
  pid = os.fork()

[2024-07-27T16:37:30.961+0000] {standard_task_runner.py:90} INFO - Running: ['***', 'tasks', 'run', 'ETL_SofaScore_Matchday_daily', 'crawl_match_lineups', 'scheduled__2023-07-31T00:00:00+00:00', '--job-id', '387', '--raw', '--subdir', 'DAGS_FOLDER/crawl_dags.py', '--cfg-path', '/tmp/tmpe4d5eeu4']
[2024-07-27T16:37:30.968+0000] {standard_task_runner.py:63} INFO - Started process 2925 to run task
[2024-07-27T16:37:30.970+0000] {standard_task_runner.py:91} INFO - Job 387: Subtask crawl_match_lineups
[2024-07-27T16:37:31.064+0000] {task_command.py:426} INFO - Running <TaskInstance: ETL_SofaScore_Matchday_daily.crawl_match_lineups scheduled__2023-07-31T00:00:00+00:00 [running]> on host fde3e54b98e9
[2024-07-27T16:37:31.223+0000] {taskinstance.py:2648} INFO - Exporting env vars: AIRFLOW_CTX_DAG_EMAIL='nguyenmduc2407@gmail.com' AIRFLOW_CTX_DAG_OWNER='***' AIRFLOW_CTX_DAG_ID='ETL_SofaScore_Matchday_daily' AIRFLOW_CTX_TASK_ID='crawl_match_lineups' AIRFLOW_CTX_EXECUTION_DATE='2023-07-31T00:00:00+00:00' AIRFLOW_CTX_TRY_NUMBER='1' AIRFLOW_CTX_DAG_RUN_ID='scheduled__2023-07-31T00:00:00+00:00'
[2024-07-27T16:37:31.228+0000] {taskinstance.py:430} INFO - ::endgroup::
[2024-07-27T16:37:31.253+0000] {taskinstance.py:441} INFO - ::group::Post task execution logs
[2024-07-27T16:37:31.254+0000] {taskinstance.py:2905} ERROR - Task failed with exception
Traceback (most recent call last):
  File "/home/airflow/.local/lib/python3.12/site-packages/airflow/models/taskinstance.py", line 465, in _execute_task
    result = _execute_callable(context=context, **execute_callable_kwargs)
             ^^^^^^^^^^^^^^^^^^^^^^^^^^^^^^^^^^^^^^^^^^^^^^^^^^^^^^^^^^^^^
  File "/home/airflow/.local/lib/python3.12/site-packages/airflow/models/taskinstance.py", line 432, in _execute_callable
    return execute_callable(context=context, **execute_callable_kwargs)
           ^^^^^^^^^^^^^^^^^^^^^^^^^^^^^^^^^^^^^^^^^^^^^^^^^^^^^^^^^^^^
  File "/home/airflow/.local/lib/python3.12/site-packages/airflow/models/baseoperator.py", line 400, in wrapper
    return func(self, *args, **kwargs)
           ^^^^^^^^^^^^^^^^^^^^^^^^^^^
  File "/home/airflow/.local/lib/python3.12/site-packages/airflow/operators/python.py", line 235, in execute
    return_value = self.execute_callable()
                   ^^^^^^^^^^^^^^^^^^^^^^^
  File "/home/airflow/.local/lib/python3.12/site-packages/airflow/operators/python.py", line 252, in execute_callable
    return self.python_callable(*self.op_args, **self.op_kwargs)
           ^^^^^^^^^^^^^^^^^^^^^^^^^^^^^^^^^^^^^^^^^^^^^^^^^^^^^
  File "/opt/airflow/dags/crawl_dags.py", line 374, in crawl_match_lineups
    return crawler.match_lineups()
           ^^^^^^^^^^^^^^^^^^^^^^^
TypeError: CrawlMatchInfo.match_lineups() missing 1 required positional argument: 'list_match_id'
[2024-07-27T16:37:31.288+0000] {taskinstance.py:1206} INFO - Marking task as UP_FOR_RETRY. dag_id=ETL_SofaScore_Matchday_daily, task_id=crawl_match_lineups, run_id=scheduled__2023-07-31T00:00:00+00:00, execution_date=20230731T000000, start_date=20240727T163730, end_date=20240727T163731
[2024-07-27T16:37:31.308+0000] {warnings.py:110} WARNING - /home/***/.local/lib/python3.12/site-packages/***/utils/email.py:154: RemovedInAirflow3Warning: Fetching SMTP credentials from configuration variables will be deprecated in a future release. Please set credentials using a connection instead.
  send_mime_email(e_from=mail_from, e_to=recipients, mime_msg=msg, conn_id=conn_id, dryrun=dryrun)

[2024-07-27T16:37:31.309+0000] {configuration.py:1050} WARNING - section/key [smtp/smtp_user] not found in config
[2024-07-27T16:37:31.310+0000] {email.py:271} INFO - Email alerting: attempt 1
[2024-07-27T16:37:31.321+0000] {configuration.py:1050} WARNING - section/key [smtp/smtp_user] not found in config
[2024-07-27T16:37:31.322+0000] {email.py:271} INFO - Email alerting: attempt 1
[2024-07-27T16:37:31.323+0000] {taskinstance.py:879} ERROR - Failed to send email to: nguyenmduc2407@gmail.com
Traceback (most recent call last):
  File "/home/airflow/.local/lib/python3.12/site-packages/airflow/models/taskinstance.py", line 2479, in _run_raw_task
    self._execute_task_with_callbacks(context, test_mode, session=session)
  File "/home/airflow/.local/lib/python3.12/site-packages/airflow/models/taskinstance.py", line 2676, in _execute_task_with_callbacks
    result = self._execute_task(context, task_orig)
             ^^^^^^^^^^^^^^^^^^^^^^^^^^^^^^^^^^^^^^
  File "/home/airflow/.local/lib/python3.12/site-packages/airflow/models/taskinstance.py", line 2701, in _execute_task
    return _execute_task(self, context, task_orig)
           ^^^^^^^^^^^^^^^^^^^^^^^^^^^^^^^^^^^^^^^
  File "/home/airflow/.local/lib/python3.12/site-packages/airflow/models/taskinstance.py", line 465, in _execute_task
    result = _execute_callable(context=context, **execute_callable_kwargs)
             ^^^^^^^^^^^^^^^^^^^^^^^^^^^^^^^^^^^^^^^^^^^^^^^^^^^^^^^^^^^^^
  File "/home/airflow/.local/lib/python3.12/site-packages/airflow/models/taskinstance.py", line 432, in _execute_callable
    return execute_callable(context=context, **execute_callable_kwargs)
           ^^^^^^^^^^^^^^^^^^^^^^^^^^^^^^^^^^^^^^^^^^^^^^^^^^^^^^^^^^^^
  File "/home/airflow/.local/lib/python3.12/site-packages/airflow/models/baseoperator.py", line 400, in wrapper
    return func(self, *args, **kwargs)
           ^^^^^^^^^^^^^^^^^^^^^^^^^^^
  File "/home/airflow/.local/lib/python3.12/site-packages/airflow/operators/python.py", line 235, in execute
    return_value = self.execute_callable()
                   ^^^^^^^^^^^^^^^^^^^^^^^
  File "/home/airflow/.local/lib/python3.12/site-packages/airflow/operators/python.py", line 252, in execute_callable
    return self.python_callable(*self.op_args, **self.op_kwargs)
           ^^^^^^^^^^^^^^^^^^^^^^^^^^^^^^^^^^^^^^^^^^^^^^^^^^^^^
  File "/opt/airflow/dags/crawl_dags.py", line 374, in crawl_match_lineups
    return crawler.match_lineups()
           ^^^^^^^^^^^^^^^^^^^^^^^
TypeError: CrawlMatchInfo.match_lineups() missing 1 required positional argument: 'list_match_id'

During handling of the above exception, another exception occurred:

Traceback (most recent call last):
  File "/home/airflow/.local/lib/python3.12/site-packages/airflow/models/taskinstance.py", line 1063, in _email_alert
    send_email(task.email, subject, html_content)
  File "/home/airflow/.local/lib/python3.12/site-packages/airflow/utils/email.py", line 80, in send_email
    return backend(
           ^^^^^^^^
  File "/home/airflow/.local/lib/python3.12/site-packages/airflow/utils/email.py", line 154, in send_email_smtp
    send_mime_email(e_from=mail_from, e_to=recipients, mime_msg=msg, conn_id=conn_id, dryrun=dryrun)
  File "/home/airflow/.local/lib/python3.12/site-packages/airflow/utils/email.py", line 273, in send_mime_email
    smtp_conn = _get_smtp_connection(smtp_host, smtp_port, smtp_timeout, smtp_ssl)
                ^^^^^^^^^^^^^^^^^^^^^^^^^^^^^^^^^^^^^^^^^^^^^^^^^^^^^^^^^^^^^^^^^^
  File "/home/airflow/.local/lib/python3.12/site-packages/airflow/utils/email.py", line 317, in _get_smtp_connection
    return smtplib.SMTP(host=host, port=port, timeout=timeout)
           ^^^^^^^^^^^^^^^^^^^^^^^^^^^^^^^^^^^^^^^^^^^^^^^^^^^
  File "/usr/local/lib/python3.12/smtplib.py", line 255, in __init__
    (code, msg) = self.connect(host, port)
                  ^^^^^^^^^^^^^^^^^^^^^^^^
  File "/usr/local/lib/python3.12/smtplib.py", line 341, in connect
    self.sock = self._get_socket(host, port, self.timeout)
                ^^^^^^^^^^^^^^^^^^^^^^^^^^^^^^^^^^^^^^^^^^
  File "/usr/local/lib/python3.12/smtplib.py", line 312, in _get_socket
    return socket.create_connection((host, port), timeout,
           ^^^^^^^^^^^^^^^^^^^^^^^^^^^^^^^^^^^^^^^^^^^^^^^
  File "/usr/local/lib/python3.12/socket.py", line 852, in create_connection
    raise exceptions[0]
  File "/usr/local/lib/python3.12/socket.py", line 837, in create_connection
    sock.connect(sa)
ConnectionRefusedError: [Errno 111] Connection refused

During handling of the above exception, another exception occurred:

Traceback (most recent call last):
  File "/home/airflow/.local/lib/python3.12/site-packages/airflow/models/taskinstance.py", line 877, in _handle_failure
    task_instance.email_alert(error, failure_context["task"])
  File "/home/airflow/.local/lib/python3.12/site-packages/airflow/models/taskinstance.py", line 3163, in email_alert
    _email_alert(task_instance=self, exception=exception, task=task)
  File "/home/airflow/.local/lib/python3.12/site-packages/airflow/models/taskinstance.py", line 1065, in _email_alert
    send_email(task.email, subject, html_content_err)
  File "/home/airflow/.local/lib/python3.12/site-packages/airflow/utils/email.py", line 80, in send_email
    return backend(
           ^^^^^^^^
  File "/home/airflow/.local/lib/python3.12/site-packages/airflow/utils/email.py", line 154, in send_email_smtp
    send_mime_email(e_from=mail_from, e_to=recipients, mime_msg=msg, conn_id=conn_id, dryrun=dryrun)
  File "/home/airflow/.local/lib/python3.12/site-packages/airflow/utils/email.py", line 273, in send_mime_email
    smtp_conn = _get_smtp_connection(smtp_host, smtp_port, smtp_timeout, smtp_ssl)
                ^^^^^^^^^^^^^^^^^^^^^^^^^^^^^^^^^^^^^^^^^^^^^^^^^^^^^^^^^^^^^^^^^^
  File "/home/airflow/.local/lib/python3.12/site-packages/airflow/utils/email.py", line 317, in _get_smtp_connection
    return smtplib.SMTP(host=host, port=port, timeout=timeout)
           ^^^^^^^^^^^^^^^^^^^^^^^^^^^^^^^^^^^^^^^^^^^^^^^^^^^
  File "/usr/local/lib/python3.12/smtplib.py", line 255, in __init__
    (code, msg) = self.connect(host, port)
                  ^^^^^^^^^^^^^^^^^^^^^^^^
  File "/usr/local/lib/python3.12/smtplib.py", line 341, in connect
    self.sock = self._get_socket(host, port, self.timeout)
                ^^^^^^^^^^^^^^^^^^^^^^^^^^^^^^^^^^^^^^^^^^
  File "/usr/local/lib/python3.12/smtplib.py", line 312, in _get_socket
    return socket.create_connection((host, port), timeout,
           ^^^^^^^^^^^^^^^^^^^^^^^^^^^^^^^^^^^^^^^^^^^^^^^
  File "/usr/local/lib/python3.12/socket.py", line 852, in create_connection
    raise exceptions[0]
  File "/usr/local/lib/python3.12/socket.py", line 837, in create_connection
    sock.connect(sa)
ConnectionRefusedError: [Errno 111] Connection refused
[2024-07-27T16:37:31.344+0000] {standard_task_runner.py:110} ERROR - Failed to execute job 387 for task crawl_match_lineups (CrawlMatchInfo.match_lineups() missing 1 required positional argument: 'list_match_id'; 2925)
[2024-07-27T16:37:31.394+0000] {local_task_job_runner.py:240} INFO - Task exited with return code 1
[2024-07-27T16:37:31.409+0000] {local_task_job_runner.py:222} INFO - ::endgroup::
[2024-07-27T16:43:04.035+0000] {local_task_job_runner.py:120} INFO - ::group::Pre task execution logs
[2024-07-27T16:43:04.124+0000] {taskinstance.py:2076} INFO - Dependencies all met for dep_context=non-requeueable deps ti=<TaskInstance: ETL_SofaScore_Matchday_daily.crawl_match_lineups scheduled__2023-07-31T00:00:00+00:00 [queued]>
[2024-07-27T16:43:04.200+0000] {taskinstance.py:2076} INFO - Dependencies all met for dep_context=requeueable deps ti=<TaskInstance: ETL_SofaScore_Matchday_daily.crawl_match_lineups scheduled__2023-07-31T00:00:00+00:00 [queued]>
[2024-07-27T16:43:04.206+0000] {taskinstance.py:2306} INFO - Starting attempt 1 of 2
[2024-07-27T16:43:04.834+0000] {taskinstance.py:2330} INFO - Executing <Task(PythonOperator): crawl_match_lineups> on 2023-07-31 00:00:00+00:00
[2024-07-27T16:43:04.849+0000] {warnings.py:110} WARNING - /home/***/.local/lib/python3.12/site-packages/***/task/task_runner/standard_task_runner.py:61: DeprecationWarning: This process (pid=3011) is multi-threaded, use of fork() may lead to deadlocks in the child.
  pid = os.fork()

[2024-07-27T16:43:04.853+0000] {standard_task_runner.py:63} INFO - Started process 3033 to run task
[2024-07-27T16:43:04.865+0000] {standard_task_runner.py:90} INFO - Running: ['***', 'tasks', 'run', 'ETL_SofaScore_Matchday_daily', 'crawl_match_lineups', 'scheduled__2023-07-31T00:00:00+00:00', '--job-id', '392', '--raw', '--subdir', 'DAGS_FOLDER/crawl_dags.py', '--cfg-path', '/tmp/tmpa0spwpkz']
[2024-07-27T16:43:04.870+0000] {standard_task_runner.py:91} INFO - Job 392: Subtask crawl_match_lineups
[2024-07-27T16:43:05.069+0000] {task_command.py:426} INFO - Running <TaskInstance: ETL_SofaScore_Matchday_daily.crawl_match_lineups scheduled__2023-07-31T00:00:00+00:00 [running]> on host fde3e54b98e9
[2024-07-27T16:43:05.410+0000] {taskinstance.py:2648} INFO - Exporting env vars: AIRFLOW_CTX_DAG_EMAIL='nguyenmduc2407@gmail.com' AIRFLOW_CTX_DAG_OWNER='***' AIRFLOW_CTX_DAG_ID='ETL_SofaScore_Matchday_daily' AIRFLOW_CTX_TASK_ID='crawl_match_lineups' AIRFLOW_CTX_EXECUTION_DATE='2023-07-31T00:00:00+00:00' AIRFLOW_CTX_TRY_NUMBER='1' AIRFLOW_CTX_DAG_RUN_ID='scheduled__2023-07-31T00:00:00+00:00'
[2024-07-27T16:43:05.416+0000] {taskinstance.py:430} INFO - ::endgroup::
[2024-07-27T16:43:05.478+0000] {taskinstance.py:441} INFO - ::group::Post task execution logs
[2024-07-27T16:43:05.498+0000] {taskinstance.py:2905} ERROR - Task failed with exception
Traceback (most recent call last):
  File "/home/airflow/.local/lib/python3.12/site-packages/airflow/models/taskinstance.py", line 465, in _execute_task
    result = _execute_callable(context=context, **execute_callable_kwargs)
             ^^^^^^^^^^^^^^^^^^^^^^^^^^^^^^^^^^^^^^^^^^^^^^^^^^^^^^^^^^^^^
  File "/home/airflow/.local/lib/python3.12/site-packages/airflow/models/taskinstance.py", line 432, in _execute_callable
    return execute_callable(context=context, **execute_callable_kwargs)
           ^^^^^^^^^^^^^^^^^^^^^^^^^^^^^^^^^^^^^^^^^^^^^^^^^^^^^^^^^^^^
  File "/home/airflow/.local/lib/python3.12/site-packages/airflow/models/baseoperator.py", line 400, in wrapper
    return func(self, *args, **kwargs)
           ^^^^^^^^^^^^^^^^^^^^^^^^^^^
  File "/home/airflow/.local/lib/python3.12/site-packages/airflow/operators/python.py", line 235, in execute
    return_value = self.execute_callable()
                   ^^^^^^^^^^^^^^^^^^^^^^^
  File "/home/airflow/.local/lib/python3.12/site-packages/airflow/operators/python.py", line 252, in execute_callable
    return self.python_callable(*self.op_args, **self.op_kwargs)
           ^^^^^^^^^^^^^^^^^^^^^^^^^^^^^^^^^^^^^^^^^^^^^^^^^^^^^
  File "/opt/airflow/dags/crawl_dags.py", line 376, in crawl_match_lineups
    date = kwargs['date']
           ~~~~~~^^^^^^^^
TypeError: tuple indices must be integers or slices, not str
[2024-07-27T16:43:05.553+0000] {taskinstance.py:1206} INFO - Marking task as UP_FOR_RETRY. dag_id=ETL_SofaScore_Matchday_daily, task_id=crawl_match_lineups, run_id=scheduled__2023-07-31T00:00:00+00:00, execution_date=20230731T000000, start_date=20240727T164304, end_date=20240727T164305
[2024-07-27T16:43:05.600+0000] {warnings.py:110} WARNING - /home/***/.local/lib/python3.12/site-packages/***/utils/email.py:154: RemovedInAirflow3Warning: Fetching SMTP credentials from configuration variables will be deprecated in a future release. Please set credentials using a connection instead.
  send_mime_email(e_from=mail_from, e_to=recipients, mime_msg=msg, conn_id=conn_id, dryrun=dryrun)

[2024-07-27T16:43:05.603+0000] {configuration.py:1050} WARNING - section/key [smtp/smtp_user] not found in config
[2024-07-27T16:43:05.604+0000] {email.py:271} INFO - Email alerting: attempt 1
[2024-07-27T16:43:05.633+0000] {configuration.py:1050} WARNING - section/key [smtp/smtp_user] not found in config
[2024-07-27T16:43:05.639+0000] {email.py:271} INFO - Email alerting: attempt 1
[2024-07-27T16:43:05.646+0000] {taskinstance.py:879} ERROR - Failed to send email to: nguyenmduc2407@gmail.com
Traceback (most recent call last):
  File "/home/airflow/.local/lib/python3.12/site-packages/airflow/models/taskinstance.py", line 2479, in _run_raw_task
    self._execute_task_with_callbacks(context, test_mode, session=session)
  File "/home/airflow/.local/lib/python3.12/site-packages/airflow/models/taskinstance.py", line 2676, in _execute_task_with_callbacks
    result = self._execute_task(context, task_orig)
             ^^^^^^^^^^^^^^^^^^^^^^^^^^^^^^^^^^^^^^
  File "/home/airflow/.local/lib/python3.12/site-packages/airflow/models/taskinstance.py", line 2701, in _execute_task
    return _execute_task(self, context, task_orig)
           ^^^^^^^^^^^^^^^^^^^^^^^^^^^^^^^^^^^^^^^
  File "/home/airflow/.local/lib/python3.12/site-packages/airflow/models/taskinstance.py", line 465, in _execute_task
    result = _execute_callable(context=context, **execute_callable_kwargs)
             ^^^^^^^^^^^^^^^^^^^^^^^^^^^^^^^^^^^^^^^^^^^^^^^^^^^^^^^^^^^^^
  File "/home/airflow/.local/lib/python3.12/site-packages/airflow/models/taskinstance.py", line 432, in _execute_callable
    return execute_callable(context=context, **execute_callable_kwargs)
           ^^^^^^^^^^^^^^^^^^^^^^^^^^^^^^^^^^^^^^^^^^^^^^^^^^^^^^^^^^^^
  File "/home/airflow/.local/lib/python3.12/site-packages/airflow/models/baseoperator.py", line 400, in wrapper
    return func(self, *args, **kwargs)
           ^^^^^^^^^^^^^^^^^^^^^^^^^^^
  File "/home/airflow/.local/lib/python3.12/site-packages/airflow/operators/python.py", line 235, in execute
    return_value = self.execute_callable()
                   ^^^^^^^^^^^^^^^^^^^^^^^
  File "/home/airflow/.local/lib/python3.12/site-packages/airflow/operators/python.py", line 252, in execute_callable
    return self.python_callable(*self.op_args, **self.op_kwargs)
           ^^^^^^^^^^^^^^^^^^^^^^^^^^^^^^^^^^^^^^^^^^^^^^^^^^^^^
  File "/opt/airflow/dags/crawl_dags.py", line 376, in crawl_match_lineups
    date = kwargs['date']
           ~~~~~~^^^^^^^^
TypeError: tuple indices must be integers or slices, not str

During handling of the above exception, another exception occurred:

Traceback (most recent call last):
  File "/home/airflow/.local/lib/python3.12/site-packages/airflow/models/taskinstance.py", line 1063, in _email_alert
    send_email(task.email, subject, html_content)
  File "/home/airflow/.local/lib/python3.12/site-packages/airflow/utils/email.py", line 80, in send_email
    return backend(
           ^^^^^^^^
  File "/home/airflow/.local/lib/python3.12/site-packages/airflow/utils/email.py", line 154, in send_email_smtp
    send_mime_email(e_from=mail_from, e_to=recipients, mime_msg=msg, conn_id=conn_id, dryrun=dryrun)
  File "/home/airflow/.local/lib/python3.12/site-packages/airflow/utils/email.py", line 273, in send_mime_email
    smtp_conn = _get_smtp_connection(smtp_host, smtp_port, smtp_timeout, smtp_ssl)
                ^^^^^^^^^^^^^^^^^^^^^^^^^^^^^^^^^^^^^^^^^^^^^^^^^^^^^^^^^^^^^^^^^^
  File "/home/airflow/.local/lib/python3.12/site-packages/airflow/utils/email.py", line 317, in _get_smtp_connection
    return smtplib.SMTP(host=host, port=port, timeout=timeout)
           ^^^^^^^^^^^^^^^^^^^^^^^^^^^^^^^^^^^^^^^^^^^^^^^^^^^
  File "/usr/local/lib/python3.12/smtplib.py", line 255, in __init__
    (code, msg) = self.connect(host, port)
                  ^^^^^^^^^^^^^^^^^^^^^^^^
  File "/usr/local/lib/python3.12/smtplib.py", line 341, in connect
    self.sock = self._get_socket(host, port, self.timeout)
                ^^^^^^^^^^^^^^^^^^^^^^^^^^^^^^^^^^^^^^^^^^
  File "/usr/local/lib/python3.12/smtplib.py", line 312, in _get_socket
    return socket.create_connection((host, port), timeout,
           ^^^^^^^^^^^^^^^^^^^^^^^^^^^^^^^^^^^^^^^^^^^^^^^
  File "/usr/local/lib/python3.12/socket.py", line 852, in create_connection
    raise exceptions[0]
  File "/usr/local/lib/python3.12/socket.py", line 837, in create_connection
    sock.connect(sa)
ConnectionRefusedError: [Errno 111] Connection refused

During handling of the above exception, another exception occurred:

Traceback (most recent call last):
  File "/home/airflow/.local/lib/python3.12/site-packages/airflow/models/taskinstance.py", line 877, in _handle_failure
    task_instance.email_alert(error, failure_context["task"])
  File "/home/airflow/.local/lib/python3.12/site-packages/airflow/models/taskinstance.py", line 3163, in email_alert
    _email_alert(task_instance=self, exception=exception, task=task)
  File "/home/airflow/.local/lib/python3.12/site-packages/airflow/models/taskinstance.py", line 1065, in _email_alert
    send_email(task.email, subject, html_content_err)
  File "/home/airflow/.local/lib/python3.12/site-packages/airflow/utils/email.py", line 80, in send_email
    return backend(
           ^^^^^^^^
  File "/home/airflow/.local/lib/python3.12/site-packages/airflow/utils/email.py", line 154, in send_email_smtp
    send_mime_email(e_from=mail_from, e_to=recipients, mime_msg=msg, conn_id=conn_id, dryrun=dryrun)
  File "/home/airflow/.local/lib/python3.12/site-packages/airflow/utils/email.py", line 273, in send_mime_email
    smtp_conn = _get_smtp_connection(smtp_host, smtp_port, smtp_timeout, smtp_ssl)
                ^^^^^^^^^^^^^^^^^^^^^^^^^^^^^^^^^^^^^^^^^^^^^^^^^^^^^^^^^^^^^^^^^^
  File "/home/airflow/.local/lib/python3.12/site-packages/airflow/utils/email.py", line 317, in _get_smtp_connection
    return smtplib.SMTP(host=host, port=port, timeout=timeout)
           ^^^^^^^^^^^^^^^^^^^^^^^^^^^^^^^^^^^^^^^^^^^^^^^^^^^
  File "/usr/local/lib/python3.12/smtplib.py", line 255, in __init__
    (code, msg) = self.connect(host, port)
                  ^^^^^^^^^^^^^^^^^^^^^^^^
  File "/usr/local/lib/python3.12/smtplib.py", line 341, in connect
    self.sock = self._get_socket(host, port, self.timeout)
                ^^^^^^^^^^^^^^^^^^^^^^^^^^^^^^^^^^^^^^^^^^
  File "/usr/local/lib/python3.12/smtplib.py", line 312, in _get_socket
    return socket.create_connection((host, port), timeout,
           ^^^^^^^^^^^^^^^^^^^^^^^^^^^^^^^^^^^^^^^^^^^^^^^
  File "/usr/local/lib/python3.12/socket.py", line 852, in create_connection
    raise exceptions[0]
  File "/usr/local/lib/python3.12/socket.py", line 837, in create_connection
    sock.connect(sa)
ConnectionRefusedError: [Errno 111] Connection refused
[2024-07-27T16:43:05.689+0000] {standard_task_runner.py:110} ERROR - Failed to execute job 392 for task crawl_match_lineups (tuple indices must be integers or slices, not str; 3033)
[2024-07-27T16:43:05.744+0000] {local_task_job_runner.py:240} INFO - Task exited with return code 1
[2024-07-27T16:43:05.812+0000] {taskinstance.py:3498} INFO - 0 downstream tasks scheduled from follow-on schedule check
[2024-07-27T16:43:05.843+0000] {local_task_job_runner.py:222} INFO - ::endgroup::
[2024-07-27T17:26:07.701+0000] {local_task_job_runner.py:120} INFO - ::group::Pre task execution logs
[2024-07-27T17:26:07.791+0000] {taskinstance.py:2076} INFO - Dependencies all met for dep_context=non-requeueable deps ti=<TaskInstance: ETL_SofaScore_Matchday_daily.crawl_match_lineups scheduled__2023-07-31T00:00:00+00:00 [queued]>
[2024-07-27T17:26:07.824+0000] {taskinstance.py:2076} INFO - Dependencies all met for dep_context=requeueable deps ti=<TaskInstance: ETL_SofaScore_Matchday_daily.crawl_match_lineups scheduled__2023-07-31T00:00:00+00:00 [queued]>
[2024-07-27T17:26:07.826+0000] {taskinstance.py:2306} INFO - Starting attempt 1 of 2
[2024-07-27T17:26:08.628+0000] {taskinstance.py:2330} INFO - Executing <Task(PythonOperator): crawl_match_lineups> on 2023-07-31 00:00:00+00:00
[2024-07-27T17:26:08.647+0000] {warnings.py:110} WARNING - /home/***/.local/lib/python3.12/site-packages/***/task/task_runner/standard_task_runner.py:61: DeprecationWarning: This process (pid=3634) is multi-threaded, use of fork() may lead to deadlocks in the child.
  pid = os.fork()

[2024-07-27T17:26:08.650+0000] {standard_task_runner.py:63} INFO - Started process 3646 to run task
[2024-07-27T17:26:08.649+0000] {standard_task_runner.py:90} INFO - Running: ['***', 'tasks', 'run', 'ETL_SofaScore_Matchday_daily', 'crawl_match_lineups', 'scheduled__2023-07-31T00:00:00+00:00', '--job-id', '417', '--raw', '--subdir', 'DAGS_FOLDER/crawl_dags.py', '--cfg-path', '/tmp/tmpzucrnut4']
[2024-07-27T17:26:08.652+0000] {standard_task_runner.py:91} INFO - Job 417: Subtask crawl_match_lineups
[2024-07-27T17:26:08.744+0000] {task_command.py:426} INFO - Running <TaskInstance: ETL_SofaScore_Matchday_daily.crawl_match_lineups scheduled__2023-07-31T00:00:00+00:00 [running]> on host fde3e54b98e9
[2024-07-27T17:26:08.920+0000] {taskinstance.py:2648} INFO - Exporting env vars: AIRFLOW_CTX_DAG_EMAIL='nguyenmduc2407@gmail.com' AIRFLOW_CTX_DAG_OWNER='***' AIRFLOW_CTX_DAG_ID='ETL_SofaScore_Matchday_daily' AIRFLOW_CTX_TASK_ID='crawl_match_lineups' AIRFLOW_CTX_EXECUTION_DATE='2023-07-31T00:00:00+00:00' AIRFLOW_CTX_TRY_NUMBER='1' AIRFLOW_CTX_DAG_RUN_ID='scheduled__2023-07-31T00:00:00+00:00'
[2024-07-27T17:26:08.923+0000] {taskinstance.py:430} INFO - ::endgroup::
[2024-07-27T17:26:08.956+0000] {taskinstance.py:441} INFO - ::group::Post task execution logs
[2024-07-27T17:26:08.957+0000] {taskinstance.py:2905} ERROR - Task failed with exception
Traceback (most recent call last):
  File "/home/airflow/.local/lib/python3.12/site-packages/airflow/models/taskinstance.py", line 465, in _execute_task
    result = _execute_callable(context=context, **execute_callable_kwargs)
             ^^^^^^^^^^^^^^^^^^^^^^^^^^^^^^^^^^^^^^^^^^^^^^^^^^^^^^^^^^^^^
  File "/home/airflow/.local/lib/python3.12/site-packages/airflow/models/taskinstance.py", line 432, in _execute_callable
    return execute_callable(context=context, **execute_callable_kwargs)
           ^^^^^^^^^^^^^^^^^^^^^^^^^^^^^^^^^^^^^^^^^^^^^^^^^^^^^^^^^^^^
  File "/home/airflow/.local/lib/python3.12/site-packages/airflow/models/baseoperator.py", line 400, in wrapper
    return func(self, *args, **kwargs)
           ^^^^^^^^^^^^^^^^^^^^^^^^^^^
  File "/home/airflow/.local/lib/python3.12/site-packages/airflow/operators/python.py", line 235, in execute
    return_value = self.execute_callable()
                   ^^^^^^^^^^^^^^^^^^^^^^^
  File "/home/airflow/.local/lib/python3.12/site-packages/airflow/operators/python.py", line 252, in execute_callable
    return self.python_callable(*self.op_args, **self.op_kwargs)
           ^^^^^^^^^^^^^^^^^^^^^^^^^^^^^^^^^^^^^^^^^^^^^^^^^^^^^
  File "/opt/airflow/dags/crawl_dags.py", line 409, in crawl_match_lineups
    date = kwargs['date']
           ~~~~~~^^^^^^^^
TypeError: tuple indices must be integers or slices, not str
[2024-07-27T17:26:08.979+0000] {taskinstance.py:1206} INFO - Marking task as UP_FOR_RETRY. dag_id=ETL_SofaScore_Matchday_daily, task_id=crawl_match_lineups, run_id=scheduled__2023-07-31T00:00:00+00:00, execution_date=20230731T000000, start_date=20240727T172607, end_date=20240727T172608
[2024-07-27T17:26:09.011+0000] {warnings.py:110} WARNING - /home/***/.local/lib/python3.12/site-packages/***/utils/email.py:154: RemovedInAirflow3Warning: Fetching SMTP credentials from configuration variables will be deprecated in a future release. Please set credentials using a connection instead.
  send_mime_email(e_from=mail_from, e_to=recipients, mime_msg=msg, conn_id=conn_id, dryrun=dryrun)

[2024-07-27T17:26:09.013+0000] {configuration.py:1050} WARNING - section/key [smtp/smtp_user] not found in config
[2024-07-27T17:26:09.017+0000] {email.py:271} INFO - Email alerting: attempt 1
[2024-07-27T17:26:09.034+0000] {configuration.py:1050} WARNING - section/key [smtp/smtp_user] not found in config
[2024-07-27T17:26:09.035+0000] {email.py:271} INFO - Email alerting: attempt 1
[2024-07-27T17:26:09.036+0000] {taskinstance.py:879} ERROR - Failed to send email to: nguyenmduc2407@gmail.com
Traceback (most recent call last):
  File "/home/airflow/.local/lib/python3.12/site-packages/airflow/models/taskinstance.py", line 2479, in _run_raw_task
    self._execute_task_with_callbacks(context, test_mode, session=session)
  File "/home/airflow/.local/lib/python3.12/site-packages/airflow/models/taskinstance.py", line 2676, in _execute_task_with_callbacks
    result = self._execute_task(context, task_orig)
             ^^^^^^^^^^^^^^^^^^^^^^^^^^^^^^^^^^^^^^
  File "/home/airflow/.local/lib/python3.12/site-packages/airflow/models/taskinstance.py", line 2701, in _execute_task
    return _execute_task(self, context, task_orig)
           ^^^^^^^^^^^^^^^^^^^^^^^^^^^^^^^^^^^^^^^
  File "/home/airflow/.local/lib/python3.12/site-packages/airflow/models/taskinstance.py", line 465, in _execute_task
    result = _execute_callable(context=context, **execute_callable_kwargs)
             ^^^^^^^^^^^^^^^^^^^^^^^^^^^^^^^^^^^^^^^^^^^^^^^^^^^^^^^^^^^^^
  File "/home/airflow/.local/lib/python3.12/site-packages/airflow/models/taskinstance.py", line 432, in _execute_callable
    return execute_callable(context=context, **execute_callable_kwargs)
           ^^^^^^^^^^^^^^^^^^^^^^^^^^^^^^^^^^^^^^^^^^^^^^^^^^^^^^^^^^^^
  File "/home/airflow/.local/lib/python3.12/site-packages/airflow/models/baseoperator.py", line 400, in wrapper
    return func(self, *args, **kwargs)
           ^^^^^^^^^^^^^^^^^^^^^^^^^^^
  File "/home/airflow/.local/lib/python3.12/site-packages/airflow/operators/python.py", line 235, in execute
    return_value = self.execute_callable()
                   ^^^^^^^^^^^^^^^^^^^^^^^
  File "/home/airflow/.local/lib/python3.12/site-packages/airflow/operators/python.py", line 252, in execute_callable
    return self.python_callable(*self.op_args, **self.op_kwargs)
           ^^^^^^^^^^^^^^^^^^^^^^^^^^^^^^^^^^^^^^^^^^^^^^^^^^^^^
  File "/opt/airflow/dags/crawl_dags.py", line 409, in crawl_match_lineups
    date = kwargs['date']
           ~~~~~~^^^^^^^^
TypeError: tuple indices must be integers or slices, not str

During handling of the above exception, another exception occurred:

Traceback (most recent call last):
  File "/home/airflow/.local/lib/python3.12/site-packages/airflow/models/taskinstance.py", line 1063, in _email_alert
    send_email(task.email, subject, html_content)
  File "/home/airflow/.local/lib/python3.12/site-packages/airflow/utils/email.py", line 80, in send_email
    return backend(
           ^^^^^^^^
  File "/home/airflow/.local/lib/python3.12/site-packages/airflow/utils/email.py", line 154, in send_email_smtp
    send_mime_email(e_from=mail_from, e_to=recipients, mime_msg=msg, conn_id=conn_id, dryrun=dryrun)
  File "/home/airflow/.local/lib/python3.12/site-packages/airflow/utils/email.py", line 273, in send_mime_email
    smtp_conn = _get_smtp_connection(smtp_host, smtp_port, smtp_timeout, smtp_ssl)
                ^^^^^^^^^^^^^^^^^^^^^^^^^^^^^^^^^^^^^^^^^^^^^^^^^^^^^^^^^^^^^^^^^^
  File "/home/airflow/.local/lib/python3.12/site-packages/airflow/utils/email.py", line 317, in _get_smtp_connection
    return smtplib.SMTP(host=host, port=port, timeout=timeout)
           ^^^^^^^^^^^^^^^^^^^^^^^^^^^^^^^^^^^^^^^^^^^^^^^^^^^
  File "/usr/local/lib/python3.12/smtplib.py", line 255, in __init__
    (code, msg) = self.connect(host, port)
                  ^^^^^^^^^^^^^^^^^^^^^^^^
  File "/usr/local/lib/python3.12/smtplib.py", line 341, in connect
    self.sock = self._get_socket(host, port, self.timeout)
                ^^^^^^^^^^^^^^^^^^^^^^^^^^^^^^^^^^^^^^^^^^
  File "/usr/local/lib/python3.12/smtplib.py", line 312, in _get_socket
    return socket.create_connection((host, port), timeout,
           ^^^^^^^^^^^^^^^^^^^^^^^^^^^^^^^^^^^^^^^^^^^^^^^
  File "/usr/local/lib/python3.12/socket.py", line 852, in create_connection
    raise exceptions[0]
  File "/usr/local/lib/python3.12/socket.py", line 837, in create_connection
    sock.connect(sa)
ConnectionRefusedError: [Errno 111] Connection refused

During handling of the above exception, another exception occurred:

Traceback (most recent call last):
  File "/home/airflow/.local/lib/python3.12/site-packages/airflow/models/taskinstance.py", line 877, in _handle_failure
    task_instance.email_alert(error, failure_context["task"])
  File "/home/airflow/.local/lib/python3.12/site-packages/airflow/models/taskinstance.py", line 3163, in email_alert
    _email_alert(task_instance=self, exception=exception, task=task)
  File "/home/airflow/.local/lib/python3.12/site-packages/airflow/models/taskinstance.py", line 1065, in _email_alert
    send_email(task.email, subject, html_content_err)
  File "/home/airflow/.local/lib/python3.12/site-packages/airflow/utils/email.py", line 80, in send_email
    return backend(
           ^^^^^^^^
  File "/home/airflow/.local/lib/python3.12/site-packages/airflow/utils/email.py", line 154, in send_email_smtp
    send_mime_email(e_from=mail_from, e_to=recipients, mime_msg=msg, conn_id=conn_id, dryrun=dryrun)
  File "/home/airflow/.local/lib/python3.12/site-packages/airflow/utils/email.py", line 273, in send_mime_email
    smtp_conn = _get_smtp_connection(smtp_host, smtp_port, smtp_timeout, smtp_ssl)
                ^^^^^^^^^^^^^^^^^^^^^^^^^^^^^^^^^^^^^^^^^^^^^^^^^^^^^^^^^^^^^^^^^^
  File "/home/airflow/.local/lib/python3.12/site-packages/airflow/utils/email.py", line 317, in _get_smtp_connection
    return smtplib.SMTP(host=host, port=port, timeout=timeout)
           ^^^^^^^^^^^^^^^^^^^^^^^^^^^^^^^^^^^^^^^^^^^^^^^^^^^
  File "/usr/local/lib/python3.12/smtplib.py", line 255, in __init__
    (code, msg) = self.connect(host, port)
                  ^^^^^^^^^^^^^^^^^^^^^^^^
  File "/usr/local/lib/python3.12/smtplib.py", line 341, in connect
    self.sock = self._get_socket(host, port, self.timeout)
                ^^^^^^^^^^^^^^^^^^^^^^^^^^^^^^^^^^^^^^^^^^
  File "/usr/local/lib/python3.12/smtplib.py", line 312, in _get_socket
    return socket.create_connection((host, port), timeout,
           ^^^^^^^^^^^^^^^^^^^^^^^^^^^^^^^^^^^^^^^^^^^^^^^
  File "/usr/local/lib/python3.12/socket.py", line 852, in create_connection
    raise exceptions[0]
  File "/usr/local/lib/python3.12/socket.py", line 837, in create_connection
    sock.connect(sa)
ConnectionRefusedError: [Errno 111] Connection refused
[2024-07-27T17:26:09.060+0000] {standard_task_runner.py:110} ERROR - Failed to execute job 417 for task crawl_match_lineups (tuple indices must be integers or slices, not str; 3646)
[2024-07-27T17:26:09.113+0000] {local_task_job_runner.py:240} INFO - Task exited with return code 1
[2024-07-27T17:26:09.159+0000] {taskinstance.py:3498} INFO - 0 downstream tasks scheduled from follow-on schedule check
[2024-07-27T17:26:09.162+0000] {local_task_job_runner.py:222} INFO - ::endgroup::
