[2024-07-27T13:25:49.962+0000] {local_task_job_runner.py:120} INFO - ::group::Pre task execution logs
[2024-07-27T13:25:50.212+0000] {taskinstance.py:2076} INFO - Dependencies all met for dep_context=non-requeueable deps ti=<TaskInstance: ETL_SofaScore_Matchday_daily.crawl_match_manager scheduled__2023-08-01T00:00:00+00:00 [queued]>
[2024-07-27T13:25:50.332+0000] {taskinstance.py:2076} INFO - Dependencies all met for dep_context=requeueable deps ti=<TaskInstance: ETL_SofaScore_Matchday_daily.crawl_match_manager scheduled__2023-08-01T00:00:00+00:00 [queued]>
[2024-07-27T13:25:50.341+0000] {taskinstance.py:2306} INFO - Starting attempt 1 of 2
[2024-07-27T13:25:55.913+0000] {taskinstance.py:2330} INFO - Executing <Task(PythonOperator): crawl_match_manager> on 2023-08-01 00:00:00+00:00
[2024-07-27T13:25:55.966+0000] {warnings.py:110} WARNING - /home/***/.local/lib/python3.12/site-packages/***/task/task_runner/standard_task_runner.py:61: DeprecationWarning: This process (pid=153) is multi-threaded, use of fork() may lead to deadlocks in the child.
  pid = os.fork()

[2024-07-27T13:25:55.997+0000] {standard_task_runner.py:63} INFO - Started process 189 to run task
[2024-07-27T13:25:56.099+0000] {standard_task_runner.py:90} INFO - Running: ['***', 'tasks', 'run', 'ETL_SofaScore_Matchday_daily', 'crawl_match_manager', 'scheduled__2023-08-01T00:00:00+00:00', '--job-id', '288', '--raw', '--subdir', 'DAGS_FOLDER/crawl_dags.py', '--cfg-path', '/tmp/tmpq76r491q']
[2024-07-27T13:25:56.153+0000] {standard_task_runner.py:91} INFO - Job 288: Subtask crawl_match_manager
[2024-07-27T13:25:56.706+0000] {task_command.py:426} INFO - Running <TaskInstance: ETL_SofaScore_Matchday_daily.crawl_match_manager scheduled__2023-08-01T00:00:00+00:00 [running]> on host fde3e54b98e9
[2024-07-27T13:25:57.263+0000] {taskinstance.py:2648} INFO - Exporting env vars: AIRFLOW_CTX_DAG_EMAIL='nguyenmduc2407@gmail.com' AIRFLOW_CTX_DAG_OWNER='***' AIRFLOW_CTX_DAG_ID='ETL_SofaScore_Matchday_daily' AIRFLOW_CTX_TASK_ID='crawl_match_manager' AIRFLOW_CTX_EXECUTION_DATE='2023-08-01T00:00:00+00:00' AIRFLOW_CTX_TRY_NUMBER='1' AIRFLOW_CTX_DAG_RUN_ID='scheduled__2023-08-01T00:00:00+00:00'
[2024-07-27T13:25:57.270+0000] {taskinstance.py:430} INFO - ::endgroup::
[2024-07-27T13:25:58.284+0000] {logging_mixin.py:188} INFO - Failed to fetch data for match ID 2, status code: 404
[2024-07-27T13:26:00.050+0000] {logging_mixin.py:188} INFO - Failed to fetch data for match ID 0, status code: 404
[2024-07-27T13:26:01.851+0000] {logging_mixin.py:188} INFO - Failed to fetch data for match ID 2, status code: 404
[2024-07-27T13:26:03.976+0000] {logging_mixin.py:188} INFO - Failed to fetch data for match ID 3, status code: 404
[2024-07-27T13:26:06.019+0000] {logging_mixin.py:188} INFO - Failed to fetch data for match ID -, status code: 404
[2024-07-27T13:26:08.189+0000] {logging_mixin.py:188} INFO - Failed to fetch data for match ID 0, status code: 404
[2024-07-27T13:26:10.233+0000] {logging_mixin.py:188} INFO - Failed to fetch data for match ID 8, status code: 404
[2024-07-27T13:26:12.151+0000] {logging_mixin.py:188} INFO - Failed to fetch data for match ID -, status code: 404
[2024-07-27T13:26:14.077+0000] {logging_mixin.py:188} INFO - Failed to fetch data for match ID 0, status code: 404
[2024-07-27T13:26:16.016+0000] {logging_mixin.py:188} INFO - Failed to fetch data for match ID 1, status code: 404
[2024-07-27T13:26:17.025+0000] {logging_mixin.py:188} INFO -    status_code match_id
0          404        2
1          404        0
2          404        2
3          404        3
4          404        -
5          404        0
6          404        8
7          404        -
8          404        0
9          404        1
[2024-07-27T13:26:17.027+0000] {python.py:237} INFO - Done. Returned value was: None
[2024-07-27T13:26:17.029+0000] {taskinstance.py:441} INFO - ::group::Post task execution logs
[2024-07-27T13:26:17.038+0000] {taskinstance.py:1206} INFO - Marking task as SUCCESS. dag_id=ETL_SofaScore_Matchday_daily, task_id=crawl_match_manager, run_id=scheduled__2023-08-01T00:00:00+00:00, execution_date=20230801T000000, start_date=20240727T132550, end_date=20240727T132617
[2024-07-27T13:26:17.138+0000] {local_task_job_runner.py:240} INFO - Task exited with return code 0
[2024-07-27T13:26:17.163+0000] {taskinstance.py:3498} INFO - 0 downstream tasks scheduled from follow-on schedule check
[2024-07-27T13:26:17.182+0000] {local_task_job_runner.py:222} INFO - ::endgroup::
[2024-07-27T15:20:02.306+0000] {local_task_job_runner.py:120} INFO - ::group::Pre task execution logs
[2024-07-27T15:20:02.443+0000] {taskinstance.py:2076} INFO - Dependencies all met for dep_context=non-requeueable deps ti=<TaskInstance: ETL_SofaScore_Matchday_daily.crawl_match_manager scheduled__2023-08-01T00:00:00+00:00 [queued]>
[2024-07-27T15:20:02.480+0000] {taskinstance.py:2076} INFO - Dependencies all met for dep_context=requeueable deps ti=<TaskInstance: ETL_SofaScore_Matchday_daily.crawl_match_manager scheduled__2023-08-01T00:00:00+00:00 [queued]>
[2024-07-27T15:20:02.485+0000] {taskinstance.py:2306} INFO - Starting attempt 1 of 2
[2024-07-27T15:20:03.909+0000] {taskinstance.py:2330} INFO - Executing <Task(PythonOperator): crawl_match_manager> on 2023-08-01 00:00:00+00:00
[2024-07-27T15:20:04.081+0000] {warnings.py:110} WARNING - /home/***/.local/lib/python3.12/site-packages/***/task/task_runner/standard_task_runner.py:61: DeprecationWarning: This process (pid=1776) is multi-threaded, use of fork() may lead to deadlocks in the child.
  pid = os.fork()

[2024-07-27T15:20:04.462+0000] {standard_task_runner.py:63} INFO - Started process 1807 to run task
[2024-07-27T15:20:04.497+0000] {standard_task_runner.py:90} INFO - Running: ['***', 'tasks', 'run', 'ETL_SofaScore_Matchday_daily', 'crawl_match_manager', 'scheduled__2023-08-01T00:00:00+00:00', '--job-id', '345', '--raw', '--subdir', 'DAGS_FOLDER/crawl_dags.py', '--cfg-path', '/tmp/tmpz4jmujae']
[2024-07-27T15:20:04.558+0000] {standard_task_runner.py:91} INFO - Job 345: Subtask crawl_match_manager
[2024-07-27T15:20:07.283+0000] {task_command.py:426} INFO - Running <TaskInstance: ETL_SofaScore_Matchday_daily.crawl_match_manager scheduled__2023-08-01T00:00:00+00:00 [running]> on host fde3e54b98e9
[2024-07-27T15:20:07.746+0000] {taskinstance.py:2648} INFO - Exporting env vars: AIRFLOW_CTX_DAG_EMAIL='nguyenmduc2407@gmail.com' AIRFLOW_CTX_DAG_OWNER='***' AIRFLOW_CTX_DAG_ID='ETL_SofaScore_Matchday_daily' AIRFLOW_CTX_TASK_ID='crawl_match_manager' AIRFLOW_CTX_EXECUTION_DATE='2023-08-01T00:00:00+00:00' AIRFLOW_CTX_TRY_NUMBER='1' AIRFLOW_CTX_DAG_RUN_ID='scheduled__2023-08-01T00:00:00+00:00'
[2024-07-27T15:20:07.758+0000] {taskinstance.py:430} INFO - ::endgroup::
[2024-07-27T15:20:08.949+0000] {logging_mixin.py:188} INFO - Failed to fetch data for match ID 2, status code: 404
[2024-07-27T15:20:10.957+0000] {logging_mixin.py:188} INFO - Failed to fetch data for match ID 0, status code: 404
[2024-07-27T15:20:12.911+0000] {logging_mixin.py:188} INFO - Failed to fetch data for match ID 2, status code: 404
[2024-07-27T15:20:14.817+0000] {logging_mixin.py:188} INFO - Failed to fetch data for match ID 3, status code: 404
[2024-07-27T15:20:16.985+0000] {logging_mixin.py:188} INFO - Failed to fetch data for match ID -, status code: 404
[2024-07-27T15:20:18.886+0000] {logging_mixin.py:188} INFO - Failed to fetch data for match ID 0, status code: 404
[2024-07-27T15:20:21.115+0000] {logging_mixin.py:188} INFO - Failed to fetch data for match ID 8, status code: 404
[2024-07-27T15:20:23.054+0000] {logging_mixin.py:188} INFO - Failed to fetch data for match ID -, status code: 404
[2024-07-27T15:20:24.956+0000] {logging_mixin.py:188} INFO - Failed to fetch data for match ID 0, status code: 404
[2024-07-27T15:20:26.889+0000] {logging_mixin.py:188} INFO - Failed to fetch data for match ID 1, status code: 404
[2024-07-27T15:20:27.899+0000] {logging_mixin.py:188} INFO -    status_code match_id
0          404        2
1          404        0
2          404        2
3          404        3
4          404        -
5          404        0
6          404        8
7          404        -
8          404        0
9          404        1
[2024-07-27T15:20:27.993+0000] {logging_mixin.py:188} INFO - Data has been written to the database.
[2024-07-27T15:20:27.995+0000] {python.py:237} INFO - Done. Returned value was: None
[2024-07-27T15:20:27.997+0000] {taskinstance.py:441} INFO - ::group::Post task execution logs
[2024-07-27T15:20:28.007+0000] {taskinstance.py:1206} INFO - Marking task as SUCCESS. dag_id=ETL_SofaScore_Matchday_daily, task_id=crawl_match_manager, run_id=scheduled__2023-08-01T00:00:00+00:00, execution_date=20230801T000000, start_date=20240727T152002, end_date=20240727T152028
[2024-07-27T15:20:28.052+0000] {local_task_job_runner.py:240} INFO - Task exited with return code 0
[2024-07-27T15:20:28.075+0000] {taskinstance.py:3498} INFO - 0 downstream tasks scheduled from follow-on schedule check
[2024-07-27T15:20:28.078+0000] {local_task_job_runner.py:222} INFO - ::endgroup::
[2024-07-27T16:43:04.815+0000] {local_task_job_runner.py:120} INFO - ::group::Pre task execution logs
[2024-07-27T16:43:04.900+0000] {taskinstance.py:2076} INFO - Dependencies all met for dep_context=non-requeueable deps ti=<TaskInstance: ETL_SofaScore_Matchday_daily.crawl_match_manager scheduled__2023-08-01T00:00:00+00:00 [queued]>
[2024-07-27T16:43:04.965+0000] {taskinstance.py:2076} INFO - Dependencies all met for dep_context=requeueable deps ti=<TaskInstance: ETL_SofaScore_Matchday_daily.crawl_match_manager scheduled__2023-08-01T00:00:00+00:00 [queued]>
[2024-07-27T16:43:04.967+0000] {taskinstance.py:2306} INFO - Starting attempt 1 of 2
[2024-07-27T16:43:05.555+0000] {taskinstance.py:2330} INFO - Executing <Task(PythonOperator): crawl_match_manager> on 2023-08-01 00:00:00+00:00
[2024-07-27T16:43:05.573+0000] {warnings.py:110} WARNING - /home/***/.local/lib/python3.12/site-packages/***/task/task_runner/standard_task_runner.py:61: DeprecationWarning: This process (pid=3016) is multi-threaded, use of fork() may lead to deadlocks in the child.
  pid = os.fork()

[2024-07-27T16:43:05.581+0000] {standard_task_runner.py:63} INFO - Started process 3041 to run task
[2024-07-27T16:43:05.580+0000] {standard_task_runner.py:90} INFO - Running: ['***', 'tasks', 'run', 'ETL_SofaScore_Matchday_daily', 'crawl_match_manager', 'scheduled__2023-08-01T00:00:00+00:00', '--job-id', '397', '--raw', '--subdir', 'DAGS_FOLDER/crawl_dags.py', '--cfg-path', '/tmp/tmp8tz8kkeu']
[2024-07-27T16:43:05.597+0000] {standard_task_runner.py:91} INFO - Job 397: Subtask crawl_match_manager
[2024-07-27T16:43:05.778+0000] {task_command.py:426} INFO - Running <TaskInstance: ETL_SofaScore_Matchday_daily.crawl_match_manager scheduled__2023-08-01T00:00:00+00:00 [running]> on host fde3e54b98e9
[2024-07-27T16:43:06.039+0000] {taskinstance.py:2648} INFO - Exporting env vars: AIRFLOW_CTX_DAG_EMAIL='nguyenmduc2407@gmail.com' AIRFLOW_CTX_DAG_OWNER='***' AIRFLOW_CTX_DAG_ID='ETL_SofaScore_Matchday_daily' AIRFLOW_CTX_TASK_ID='crawl_match_manager' AIRFLOW_CTX_EXECUTION_DATE='2023-08-01T00:00:00+00:00' AIRFLOW_CTX_TRY_NUMBER='1' AIRFLOW_CTX_DAG_RUN_ID='scheduled__2023-08-01T00:00:00+00:00'
[2024-07-27T16:43:06.042+0000] {taskinstance.py:430} INFO - ::endgroup::
[2024-07-27T16:43:06.102+0000] {taskinstance.py:441} INFO - ::group::Post task execution logs
[2024-07-27T16:43:06.106+0000] {taskinstance.py:2905} ERROR - Task failed with exception
Traceback (most recent call last):
  File "/home/airflow/.local/lib/python3.12/site-packages/airflow/models/taskinstance.py", line 465, in _execute_task
    result = _execute_callable(context=context, **execute_callable_kwargs)
             ^^^^^^^^^^^^^^^^^^^^^^^^^^^^^^^^^^^^^^^^^^^^^^^^^^^^^^^^^^^^^
  File "/home/airflow/.local/lib/python3.12/site-packages/airflow/models/taskinstance.py", line 432, in _execute_callable
    return execute_callable(context=context, **execute_callable_kwargs)
           ^^^^^^^^^^^^^^^^^^^^^^^^^^^^^^^^^^^^^^^^^^^^^^^^^^^^^^^^^^^^
  File "/home/airflow/.local/lib/python3.12/site-packages/airflow/models/baseoperator.py", line 400, in wrapper
    return func(self, *args, **kwargs)
           ^^^^^^^^^^^^^^^^^^^^^^^^^^^
  File "/home/airflow/.local/lib/python3.12/site-packages/airflow/operators/python.py", line 235, in execute
    return_value = self.execute_callable()
                   ^^^^^^^^^^^^^^^^^^^^^^^
  File "/home/airflow/.local/lib/python3.12/site-packages/airflow/operators/python.py", line 252, in execute_callable
    return self.python_callable(*self.op_args, **self.op_kwargs)
           ^^^^^^^^^^^^^^^^^^^^^^^^^^^^^^^^^^^^^^^^^^^^^^^^^^^^^
  File "/opt/airflow/dags/crawl_dags.py", line 386, in crawl_match_manager
    date = kwargs['date']
           ~~~~~~^^^^^^^^
TypeError: tuple indices must be integers or slices, not str
[2024-07-27T16:43:06.138+0000] {taskinstance.py:1206} INFO - Marking task as UP_FOR_RETRY. dag_id=ETL_SofaScore_Matchday_daily, task_id=crawl_match_manager, run_id=scheduled__2023-08-01T00:00:00+00:00, execution_date=20230801T000000, start_date=20240727T164304, end_date=20240727T164306
[2024-07-27T16:43:06.177+0000] {warnings.py:110} WARNING - /home/***/.local/lib/python3.12/site-packages/***/utils/email.py:154: RemovedInAirflow3Warning: Fetching SMTP credentials from configuration variables will be deprecated in a future release. Please set credentials using a connection instead.
  send_mime_email(e_from=mail_from, e_to=recipients, mime_msg=msg, conn_id=conn_id, dryrun=dryrun)

[2024-07-27T16:43:06.179+0000] {configuration.py:1050} WARNING - section/key [smtp/smtp_user] not found in config
[2024-07-27T16:43:06.182+0000] {email.py:271} INFO - Email alerting: attempt 1
[2024-07-27T16:43:06.214+0000] {configuration.py:1050} WARNING - section/key [smtp/smtp_user] not found in config
[2024-07-27T16:43:06.216+0000] {email.py:271} INFO - Email alerting: attempt 1
[2024-07-27T16:43:06.220+0000] {taskinstance.py:879} ERROR - Failed to send email to: nguyenmduc2407@gmail.com
Traceback (most recent call last):
  File "/home/airflow/.local/lib/python3.12/site-packages/airflow/models/taskinstance.py", line 2479, in _run_raw_task
    self._execute_task_with_callbacks(context, test_mode, session=session)
  File "/home/airflow/.local/lib/python3.12/site-packages/airflow/models/taskinstance.py", line 2676, in _execute_task_with_callbacks
    result = self._execute_task(context, task_orig)
             ^^^^^^^^^^^^^^^^^^^^^^^^^^^^^^^^^^^^^^
  File "/home/airflow/.local/lib/python3.12/site-packages/airflow/models/taskinstance.py", line 2701, in _execute_task
    return _execute_task(self, context, task_orig)
           ^^^^^^^^^^^^^^^^^^^^^^^^^^^^^^^^^^^^^^^
  File "/home/airflow/.local/lib/python3.12/site-packages/airflow/models/taskinstance.py", line 465, in _execute_task
    result = _execute_callable(context=context, **execute_callable_kwargs)
             ^^^^^^^^^^^^^^^^^^^^^^^^^^^^^^^^^^^^^^^^^^^^^^^^^^^^^^^^^^^^^
  File "/home/airflow/.local/lib/python3.12/site-packages/airflow/models/taskinstance.py", line 432, in _execute_callable
    return execute_callable(context=context, **execute_callable_kwargs)
           ^^^^^^^^^^^^^^^^^^^^^^^^^^^^^^^^^^^^^^^^^^^^^^^^^^^^^^^^^^^^
  File "/home/airflow/.local/lib/python3.12/site-packages/airflow/models/baseoperator.py", line 400, in wrapper
    return func(self, *args, **kwargs)
           ^^^^^^^^^^^^^^^^^^^^^^^^^^^
  File "/home/airflow/.local/lib/python3.12/site-packages/airflow/operators/python.py", line 235, in execute
    return_value = self.execute_callable()
                   ^^^^^^^^^^^^^^^^^^^^^^^
  File "/home/airflow/.local/lib/python3.12/site-packages/airflow/operators/python.py", line 252, in execute_callable
    return self.python_callable(*self.op_args, **self.op_kwargs)
           ^^^^^^^^^^^^^^^^^^^^^^^^^^^^^^^^^^^^^^^^^^^^^^^^^^^^^
  File "/opt/airflow/dags/crawl_dags.py", line 386, in crawl_match_manager
    date = kwargs['date']
           ~~~~~~^^^^^^^^
TypeError: tuple indices must be integers or slices, not str

During handling of the above exception, another exception occurred:

Traceback (most recent call last):
  File "/home/airflow/.local/lib/python3.12/site-packages/airflow/models/taskinstance.py", line 1063, in _email_alert
    send_email(task.email, subject, html_content)
  File "/home/airflow/.local/lib/python3.12/site-packages/airflow/utils/email.py", line 80, in send_email
    return backend(
           ^^^^^^^^
  File "/home/airflow/.local/lib/python3.12/site-packages/airflow/utils/email.py", line 154, in send_email_smtp
    send_mime_email(e_from=mail_from, e_to=recipients, mime_msg=msg, conn_id=conn_id, dryrun=dryrun)
  File "/home/airflow/.local/lib/python3.12/site-packages/airflow/utils/email.py", line 273, in send_mime_email
    smtp_conn = _get_smtp_connection(smtp_host, smtp_port, smtp_timeout, smtp_ssl)
                ^^^^^^^^^^^^^^^^^^^^^^^^^^^^^^^^^^^^^^^^^^^^^^^^^^^^^^^^^^^^^^^^^^
  File "/home/airflow/.local/lib/python3.12/site-packages/airflow/utils/email.py", line 317, in _get_smtp_connection
    return smtplib.SMTP(host=host, port=port, timeout=timeout)
           ^^^^^^^^^^^^^^^^^^^^^^^^^^^^^^^^^^^^^^^^^^^^^^^^^^^
  File "/usr/local/lib/python3.12/smtplib.py", line 255, in __init__
    (code, msg) = self.connect(host, port)
                  ^^^^^^^^^^^^^^^^^^^^^^^^
  File "/usr/local/lib/python3.12/smtplib.py", line 341, in connect
    self.sock = self._get_socket(host, port, self.timeout)
                ^^^^^^^^^^^^^^^^^^^^^^^^^^^^^^^^^^^^^^^^^^
  File "/usr/local/lib/python3.12/smtplib.py", line 312, in _get_socket
    return socket.create_connection((host, port), timeout,
           ^^^^^^^^^^^^^^^^^^^^^^^^^^^^^^^^^^^^^^^^^^^^^^^
  File "/usr/local/lib/python3.12/socket.py", line 852, in create_connection
    raise exceptions[0]
  File "/usr/local/lib/python3.12/socket.py", line 837, in create_connection
    sock.connect(sa)
ConnectionRefusedError: [Errno 111] Connection refused

During handling of the above exception, another exception occurred:

Traceback (most recent call last):
  File "/home/airflow/.local/lib/python3.12/site-packages/airflow/models/taskinstance.py", line 877, in _handle_failure
    task_instance.email_alert(error, failure_context["task"])
  File "/home/airflow/.local/lib/python3.12/site-packages/airflow/models/taskinstance.py", line 3163, in email_alert
    _email_alert(task_instance=self, exception=exception, task=task)
  File "/home/airflow/.local/lib/python3.12/site-packages/airflow/models/taskinstance.py", line 1065, in _email_alert
    send_email(task.email, subject, html_content_err)
  File "/home/airflow/.local/lib/python3.12/site-packages/airflow/utils/email.py", line 80, in send_email
    return backend(
           ^^^^^^^^
  File "/home/airflow/.local/lib/python3.12/site-packages/airflow/utils/email.py", line 154, in send_email_smtp
    send_mime_email(e_from=mail_from, e_to=recipients, mime_msg=msg, conn_id=conn_id, dryrun=dryrun)
  File "/home/airflow/.local/lib/python3.12/site-packages/airflow/utils/email.py", line 273, in send_mime_email
    smtp_conn = _get_smtp_connection(smtp_host, smtp_port, smtp_timeout, smtp_ssl)
                ^^^^^^^^^^^^^^^^^^^^^^^^^^^^^^^^^^^^^^^^^^^^^^^^^^^^^^^^^^^^^^^^^^
  File "/home/airflow/.local/lib/python3.12/site-packages/airflow/utils/email.py", line 317, in _get_smtp_connection
    return smtplib.SMTP(host=host, port=port, timeout=timeout)
           ^^^^^^^^^^^^^^^^^^^^^^^^^^^^^^^^^^^^^^^^^^^^^^^^^^^
  File "/usr/local/lib/python3.12/smtplib.py", line 255, in __init__
    (code, msg) = self.connect(host, port)
                  ^^^^^^^^^^^^^^^^^^^^^^^^
  File "/usr/local/lib/python3.12/smtplib.py", line 341, in connect
    self.sock = self._get_socket(host, port, self.timeout)
                ^^^^^^^^^^^^^^^^^^^^^^^^^^^^^^^^^^^^^^^^^^
  File "/usr/local/lib/python3.12/smtplib.py", line 312, in _get_socket
    return socket.create_connection((host, port), timeout,
           ^^^^^^^^^^^^^^^^^^^^^^^^^^^^^^^^^^^^^^^^^^^^^^^
  File "/usr/local/lib/python3.12/socket.py", line 852, in create_connection
    raise exceptions[0]
  File "/usr/local/lib/python3.12/socket.py", line 837, in create_connection
    sock.connect(sa)
ConnectionRefusedError: [Errno 111] Connection refused
[2024-07-27T16:43:06.269+0000] {standard_task_runner.py:110} ERROR - Failed to execute job 397 for task crawl_match_manager (tuple indices must be integers or slices, not str; 3041)
[2024-07-27T16:43:06.336+0000] {local_task_job_runner.py:240} INFO - Task exited with return code 1
[2024-07-27T16:43:06.386+0000] {taskinstance.py:3498} INFO - 0 downstream tasks scheduled from follow-on schedule check
[2024-07-27T16:43:06.396+0000] {local_task_job_runner.py:222} INFO - ::endgroup::
