[2024-07-27T13:25:50.553+0000] {local_task_job_runner.py:120} INFO - ::group::Pre task execution logs
[2024-07-27T13:25:50.858+0000] {taskinstance.py:2076} INFO - Dependencies all met for dep_context=non-requeueable deps ti=<TaskInstance: ETL_SofaScore_Matchday_daily.crawl_match_incident scheduled__2023-08-01T00:00:00+00:00 [queued]>
[2024-07-27T13:25:50.968+0000] {taskinstance.py:2076} INFO - Dependencies all met for dep_context=requeueable deps ti=<TaskInstance: ETL_SofaScore_Matchday_daily.crawl_match_incident scheduled__2023-08-01T00:00:00+00:00 [queued]>
[2024-07-27T13:25:50.970+0000] {taskinstance.py:2306} INFO - Starting attempt 1 of 2
[2024-07-27T13:25:56.087+0000] {taskinstance.py:2330} INFO - Executing <Task(PythonOperator): crawl_match_incident> on 2023-08-01 00:00:00+00:00
[2024-07-27T13:25:56.206+0000] {standard_task_runner.py:90} INFO - Running: ['***', 'tasks', 'run', 'ETL_SofaScore_Matchday_daily', 'crawl_match_incident', 'scheduled__2023-08-01T00:00:00+00:00', '--job-id', '291', '--raw', '--subdir', 'DAGS_FOLDER/crawl_dags.py', '--cfg-path', '/tmp/tmpxf3b2jou']
[2024-07-27T13:25:56.226+0000] {standard_task_runner.py:91} INFO - Job 291: Subtask crawl_match_incident
[2024-07-27T13:25:56.138+0000] {warnings.py:110} WARNING - /home/***/.local/lib/python3.12/site-packages/***/task/task_runner/standard_task_runner.py:61: DeprecationWarning: This process (pid=162) is multi-threaded, use of fork() may lead to deadlocks in the child.
  pid = os.fork()

[2024-07-27T13:25:56.254+0000] {standard_task_runner.py:63} INFO - Started process 190 to run task
[2024-07-27T13:25:56.838+0000] {task_command.py:426} INFO - Running <TaskInstance: ETL_SofaScore_Matchday_daily.crawl_match_incident scheduled__2023-08-01T00:00:00+00:00 [running]> on host fde3e54b98e9
[2024-07-27T13:25:57.559+0000] {taskinstance.py:2648} INFO - Exporting env vars: AIRFLOW_CTX_DAG_EMAIL='nguyenmduc2407@gmail.com' AIRFLOW_CTX_DAG_OWNER='***' AIRFLOW_CTX_DAG_ID='ETL_SofaScore_Matchday_daily' AIRFLOW_CTX_TASK_ID='crawl_match_incident' AIRFLOW_CTX_EXECUTION_DATE='2023-08-01T00:00:00+00:00' AIRFLOW_CTX_TRY_NUMBER='1' AIRFLOW_CTX_DAG_RUN_ID='scheduled__2023-08-01T00:00:00+00:00'
[2024-07-27T13:25:57.563+0000] {taskinstance.py:430} INFO - ::endgroup::
[2024-07-27T13:25:58.778+0000] {logging_mixin.py:188} INFO - Failed to fetch data for match ID 2. Status code: 404
[2024-07-27T13:26:00.809+0000] {logging_mixin.py:188} INFO - Failed to fetch data for match ID 0. Status code: 404
[2024-07-27T13:26:02.774+0000] {logging_mixin.py:188} INFO - Failed to fetch data for match ID 2. Status code: 404
[2024-07-27T13:26:04.719+0000] {logging_mixin.py:188} INFO - Failed to fetch data for match ID 3. Status code: 404
[2024-07-27T13:26:06.687+0000] {logging_mixin.py:188} INFO - Failed to fetch data for match ID -. Status code: 404
[2024-07-27T13:26:08.393+0000] {logging_mixin.py:188} INFO - Failed to fetch data for match ID 0. Status code: 404
[2024-07-27T13:26:10.644+0000] {logging_mixin.py:188} INFO - Failed to fetch data for match ID 8. Status code: 404
[2024-07-27T13:26:12.572+0000] {logging_mixin.py:188} INFO - Failed to fetch data for match ID -. Status code: 404
[2024-07-27T13:26:14.734+0000] {logging_mixin.py:188} INFO - Failed to fetch data for match ID 0. Status code: 404
[2024-07-27T13:26:16.699+0000] {logging_mixin.py:188} INFO - Failed to fetch data for match ID 1. Status code: 404
[2024-07-27T13:26:17.707+0000] {logging_mixin.py:188} INFO -   match_id  status_code
0        2          404
1        0          404
2        2          404
3        3          404
4        -          404
5        0          404
6        8          404
7        -          404
8        0          404
9        1          404
[2024-07-27T13:26:17.709+0000] {python.py:237} INFO - Done. Returned value was: None
[2024-07-27T13:26:17.711+0000] {taskinstance.py:441} INFO - ::group::Post task execution logs
[2024-07-27T13:26:17.722+0000] {taskinstance.py:1206} INFO - Marking task as SUCCESS. dag_id=ETL_SofaScore_Matchday_daily, task_id=crawl_match_incident, run_id=scheduled__2023-08-01T00:00:00+00:00, execution_date=20230801T000000, start_date=20240727T132550, end_date=20240727T132617
[2024-07-27T13:26:17.817+0000] {local_task_job_runner.py:240} INFO - Task exited with return code 0
[2024-07-27T13:26:17.839+0000] {taskinstance.py:3498} INFO - 0 downstream tasks scheduled from follow-on schedule check
[2024-07-27T13:26:17.902+0000] {local_task_job_runner.py:222} INFO - ::endgroup::
[2024-07-27T15:20:00.224+0000] {local_task_job_runner.py:120} INFO - ::group::Pre task execution logs
[2024-07-27T15:20:00.436+0000] {taskinstance.py:2076} INFO - Dependencies all met for dep_context=non-requeueable deps ti=<TaskInstance: ETL_SofaScore_Matchday_daily.crawl_match_incident scheduled__2023-08-01T00:00:00+00:00 [queued]>
[2024-07-27T15:20:00.541+0000] {taskinstance.py:2076} INFO - Dependencies all met for dep_context=requeueable deps ti=<TaskInstance: ETL_SofaScore_Matchday_daily.crawl_match_incident scheduled__2023-08-01T00:00:00+00:00 [queued]>
[2024-07-27T15:20:00.553+0000] {taskinstance.py:2306} INFO - Starting attempt 1 of 2
[2024-07-27T15:20:01.730+0000] {taskinstance.py:2330} INFO - Executing <Task(PythonOperator): crawl_match_incident> on 2023-08-01 00:00:00+00:00
[2024-07-27T15:20:01.750+0000] {warnings.py:110} WARNING - /home/***/.local/lib/python3.12/site-packages/***/task/task_runner/standard_task_runner.py:61: DeprecationWarning: This process (pid=1780) is multi-threaded, use of fork() may lead to deadlocks in the child.
  pid = os.fork()

[2024-07-27T15:20:01.763+0000] {standard_task_runner.py:90} INFO - Running: ['***', 'tasks', 'run', 'ETL_SofaScore_Matchday_daily', 'crawl_match_incident', 'scheduled__2023-08-01T00:00:00+00:00', '--job-id', '340', '--raw', '--subdir', 'DAGS_FOLDER/crawl_dags.py', '--cfg-path', '/tmp/tmps6yrsmsc']
[2024-07-27T15:20:01.771+0000] {standard_task_runner.py:91} INFO - Job 340: Subtask crawl_match_incident
[2024-07-27T15:20:01.768+0000] {standard_task_runner.py:63} INFO - Started process 1802 to run task
[2024-07-27T15:20:01.915+0000] {task_command.py:426} INFO - Running <TaskInstance: ETL_SofaScore_Matchday_daily.crawl_match_incident scheduled__2023-08-01T00:00:00+00:00 [running]> on host fde3e54b98e9
[2024-07-27T15:20:02.339+0000] {taskinstance.py:2648} INFO - Exporting env vars: AIRFLOW_CTX_DAG_EMAIL='nguyenmduc2407@gmail.com' AIRFLOW_CTX_DAG_OWNER='***' AIRFLOW_CTX_DAG_ID='ETL_SofaScore_Matchday_daily' AIRFLOW_CTX_TASK_ID='crawl_match_incident' AIRFLOW_CTX_EXECUTION_DATE='2023-08-01T00:00:00+00:00' AIRFLOW_CTX_TRY_NUMBER='1' AIRFLOW_CTX_DAG_RUN_ID='scheduled__2023-08-01T00:00:00+00:00'
[2024-07-27T15:20:02.349+0000] {taskinstance.py:430} INFO - ::endgroup::
[2024-07-27T15:20:03.280+0000] {logging_mixin.py:188} INFO - Failed to fetch data for match ID 2. Status code: 404
[2024-07-27T15:20:07.139+0000] {logging_mixin.py:188} INFO - Failed to fetch data for match ID 0. Status code: 404
[2024-07-27T15:20:09.223+0000] {logging_mixin.py:188} INFO - Failed to fetch data for match ID 2. Status code: 404
[2024-07-27T15:20:10.923+0000] {logging_mixin.py:188} INFO - Failed to fetch data for match ID 3. Status code: 404
[2024-07-27T15:20:13.169+0000] {logging_mixin.py:188} INFO - Failed to fetch data for match ID -. Status code: 404
[2024-07-27T15:20:15.095+0000] {logging_mixin.py:188} INFO - Failed to fetch data for match ID 0. Status code: 404
[2024-07-27T15:20:17.323+0000] {logging_mixin.py:188} INFO - Failed to fetch data for match ID 8. Status code: 404
[2024-07-27T15:20:19.537+0000] {logging_mixin.py:188} INFO - Failed to fetch data for match ID -. Status code: 404
[2024-07-27T15:20:21.684+0000] {logging_mixin.py:188} INFO - Failed to fetch data for match ID 0. Status code: 404
[2024-07-27T15:20:23.617+0000] {logging_mixin.py:188} INFO - Failed to fetch data for match ID 1. Status code: 404
[2024-07-27T15:20:24.629+0000] {logging_mixin.py:188} INFO -   match_id  status_code
0        2          404
1        0          404
2        2          404
3        3          404
4        -          404
5        0          404
6        8          404
7        -          404
8        0          404
9        1          404
[2024-07-27T15:20:24.824+0000] {logging_mixin.py:188} INFO - Data has been written to the database.
[2024-07-27T15:20:24.826+0000] {python.py:237} INFO - Done. Returned value was: None
[2024-07-27T15:20:24.827+0000] {taskinstance.py:441} INFO - ::group::Post task execution logs
[2024-07-27T15:20:24.837+0000] {taskinstance.py:1206} INFO - Marking task as SUCCESS. dag_id=ETL_SofaScore_Matchday_daily, task_id=crawl_match_incident, run_id=scheduled__2023-08-01T00:00:00+00:00, execution_date=20230801T000000, start_date=20240727T152000, end_date=20240727T152024
[2024-07-27T15:20:24.865+0000] {local_task_job_runner.py:240} INFO - Task exited with return code 0
[2024-07-27T15:20:24.887+0000] {taskinstance.py:3498} INFO - 0 downstream tasks scheduled from follow-on schedule check
[2024-07-27T15:20:24.890+0000] {local_task_job_runner.py:222} INFO - ::endgroup::
[2024-07-27T16:43:05.014+0000] {local_task_job_runner.py:120} INFO - ::group::Pre task execution logs
[2024-07-27T16:43:05.124+0000] {taskinstance.py:2076} INFO - Dependencies all met for dep_context=non-requeueable deps ti=<TaskInstance: ETL_SofaScore_Matchday_daily.crawl_match_incident scheduled__2023-08-01T00:00:00+00:00 [queued]>
[2024-07-27T16:43:05.166+0000] {taskinstance.py:2076} INFO - Dependencies all met for dep_context=requeueable deps ti=<TaskInstance: ETL_SofaScore_Matchday_daily.crawl_match_incident scheduled__2023-08-01T00:00:00+00:00 [queued]>
[2024-07-27T16:43:05.168+0000] {taskinstance.py:2306} INFO - Starting attempt 1 of 2
[2024-07-27T16:43:05.223+0000] {taskinstance.py:2330} INFO - Executing <Task(PythonOperator): crawl_match_incident> on 2023-08-01 00:00:00+00:00
[2024-07-27T16:43:05.241+0000] {warnings.py:110} WARNING - /home/***/.local/lib/python3.12/site-packages/***/task/task_runner/standard_task_runner.py:61: DeprecationWarning: This process (pid=3012) is multi-threaded, use of fork() may lead to deadlocks in the child.
  pid = os.fork()

[2024-07-27T16:43:05.251+0000] {standard_task_runner.py:63} INFO - Started process 3035 to run task
[2024-07-27T16:43:05.250+0000] {standard_task_runner.py:90} INFO - Running: ['***', 'tasks', 'run', 'ETL_SofaScore_Matchday_daily', 'crawl_match_incident', 'scheduled__2023-08-01T00:00:00+00:00', '--job-id', '398', '--raw', '--subdir', 'DAGS_FOLDER/crawl_dags.py', '--cfg-path', '/tmp/tmpd71ytmft']
[2024-07-27T16:43:05.258+0000] {standard_task_runner.py:91} INFO - Job 398: Subtask crawl_match_incident
[2024-07-27T16:43:05.895+0000] {task_command.py:426} INFO - Running <TaskInstance: ETL_SofaScore_Matchday_daily.crawl_match_incident scheduled__2023-08-01T00:00:00+00:00 [running]> on host fde3e54b98e9
[2024-07-27T16:43:06.168+0000] {taskinstance.py:2648} INFO - Exporting env vars: AIRFLOW_CTX_DAG_EMAIL='nguyenmduc2407@gmail.com' AIRFLOW_CTX_DAG_OWNER='***' AIRFLOW_CTX_DAG_ID='ETL_SofaScore_Matchday_daily' AIRFLOW_CTX_TASK_ID='crawl_match_incident' AIRFLOW_CTX_EXECUTION_DATE='2023-08-01T00:00:00+00:00' AIRFLOW_CTX_TRY_NUMBER='1' AIRFLOW_CTX_DAG_RUN_ID='scheduled__2023-08-01T00:00:00+00:00'
[2024-07-27T16:43:06.173+0000] {taskinstance.py:430} INFO - ::endgroup::
[2024-07-27T16:43:06.223+0000] {taskinstance.py:441} INFO - ::group::Post task execution logs
[2024-07-27T16:43:06.230+0000] {taskinstance.py:2905} ERROR - Task failed with exception
Traceback (most recent call last):
  File "/home/airflow/.local/lib/python3.12/site-packages/airflow/models/taskinstance.py", line 465, in _execute_task
    result = _execute_callable(context=context, **execute_callable_kwargs)
             ^^^^^^^^^^^^^^^^^^^^^^^^^^^^^^^^^^^^^^^^^^^^^^^^^^^^^^^^^^^^^
  File "/home/airflow/.local/lib/python3.12/site-packages/airflow/models/taskinstance.py", line 432, in _execute_callable
    return execute_callable(context=context, **execute_callable_kwargs)
           ^^^^^^^^^^^^^^^^^^^^^^^^^^^^^^^^^^^^^^^^^^^^^^^^^^^^^^^^^^^^
  File "/home/airflow/.local/lib/python3.12/site-packages/airflow/models/baseoperator.py", line 400, in wrapper
    return func(self, *args, **kwargs)
           ^^^^^^^^^^^^^^^^^^^^^^^^^^^
  File "/home/airflow/.local/lib/python3.12/site-packages/airflow/operators/python.py", line 235, in execute
    return_value = self.execute_callable()
                   ^^^^^^^^^^^^^^^^^^^^^^^
  File "/home/airflow/.local/lib/python3.12/site-packages/airflow/operators/python.py", line 252, in execute_callable
    return self.python_callable(*self.op_args, **self.op_kwargs)
           ^^^^^^^^^^^^^^^^^^^^^^^^^^^^^^^^^^^^^^^^^^^^^^^^^^^^^
  File "/opt/airflow/dags/crawl_dags.py", line 381, in crawl_match_incident
    date = kwargs['date']
           ~~~~~~^^^^^^^^
TypeError: tuple indices must be integers or slices, not str
[2024-07-27T16:43:06.280+0000] {taskinstance.py:1206} INFO - Marking task as UP_FOR_RETRY. dag_id=ETL_SofaScore_Matchday_daily, task_id=crawl_match_incident, run_id=scheduled__2023-08-01T00:00:00+00:00, execution_date=20230801T000000, start_date=20240727T164305, end_date=20240727T164306
[2024-07-27T16:43:06.314+0000] {warnings.py:110} WARNING - /home/***/.local/lib/python3.12/site-packages/***/utils/email.py:154: RemovedInAirflow3Warning: Fetching SMTP credentials from configuration variables will be deprecated in a future release. Please set credentials using a connection instead.
  send_mime_email(e_from=mail_from, e_to=recipients, mime_msg=msg, conn_id=conn_id, dryrun=dryrun)

[2024-07-27T16:43:06.317+0000] {configuration.py:1050} WARNING - section/key [smtp/smtp_user] not found in config
[2024-07-27T16:43:06.318+0000] {email.py:271} INFO - Email alerting: attempt 1
[2024-07-27T16:43:06.335+0000] {configuration.py:1050} WARNING - section/key [smtp/smtp_user] not found in config
[2024-07-27T16:43:06.335+0000] {email.py:271} INFO - Email alerting: attempt 1
[2024-07-27T16:43:06.337+0000] {taskinstance.py:879} ERROR - Failed to send email to: nguyenmduc2407@gmail.com
Traceback (most recent call last):
  File "/home/airflow/.local/lib/python3.12/site-packages/airflow/models/taskinstance.py", line 2479, in _run_raw_task
    self._execute_task_with_callbacks(context, test_mode, session=session)
  File "/home/airflow/.local/lib/python3.12/site-packages/airflow/models/taskinstance.py", line 2676, in _execute_task_with_callbacks
    result = self._execute_task(context, task_orig)
             ^^^^^^^^^^^^^^^^^^^^^^^^^^^^^^^^^^^^^^
  File "/home/airflow/.local/lib/python3.12/site-packages/airflow/models/taskinstance.py", line 2701, in _execute_task
    return _execute_task(self, context, task_orig)
           ^^^^^^^^^^^^^^^^^^^^^^^^^^^^^^^^^^^^^^^
  File "/home/airflow/.local/lib/python3.12/site-packages/airflow/models/taskinstance.py", line 465, in _execute_task
    result = _execute_callable(context=context, **execute_callable_kwargs)
             ^^^^^^^^^^^^^^^^^^^^^^^^^^^^^^^^^^^^^^^^^^^^^^^^^^^^^^^^^^^^^
  File "/home/airflow/.local/lib/python3.12/site-packages/airflow/models/taskinstance.py", line 432, in _execute_callable
    return execute_callable(context=context, **execute_callable_kwargs)
           ^^^^^^^^^^^^^^^^^^^^^^^^^^^^^^^^^^^^^^^^^^^^^^^^^^^^^^^^^^^^
  File "/home/airflow/.local/lib/python3.12/site-packages/airflow/models/baseoperator.py", line 400, in wrapper
    return func(self, *args, **kwargs)
           ^^^^^^^^^^^^^^^^^^^^^^^^^^^
  File "/home/airflow/.local/lib/python3.12/site-packages/airflow/operators/python.py", line 235, in execute
    return_value = self.execute_callable()
                   ^^^^^^^^^^^^^^^^^^^^^^^
  File "/home/airflow/.local/lib/python3.12/site-packages/airflow/operators/python.py", line 252, in execute_callable
    return self.python_callable(*self.op_args, **self.op_kwargs)
           ^^^^^^^^^^^^^^^^^^^^^^^^^^^^^^^^^^^^^^^^^^^^^^^^^^^^^
  File "/opt/airflow/dags/crawl_dags.py", line 381, in crawl_match_incident
    date = kwargs['date']
           ~~~~~~^^^^^^^^
TypeError: tuple indices must be integers or slices, not str

During handling of the above exception, another exception occurred:

Traceback (most recent call last):
  File "/home/airflow/.local/lib/python3.12/site-packages/airflow/models/taskinstance.py", line 1063, in _email_alert
    send_email(task.email, subject, html_content)
  File "/home/airflow/.local/lib/python3.12/site-packages/airflow/utils/email.py", line 80, in send_email
    return backend(
           ^^^^^^^^
  File "/home/airflow/.local/lib/python3.12/site-packages/airflow/utils/email.py", line 154, in send_email_smtp
    send_mime_email(e_from=mail_from, e_to=recipients, mime_msg=msg, conn_id=conn_id, dryrun=dryrun)
  File "/home/airflow/.local/lib/python3.12/site-packages/airflow/utils/email.py", line 273, in send_mime_email
    smtp_conn = _get_smtp_connection(smtp_host, smtp_port, smtp_timeout, smtp_ssl)
                ^^^^^^^^^^^^^^^^^^^^^^^^^^^^^^^^^^^^^^^^^^^^^^^^^^^^^^^^^^^^^^^^^^
  File "/home/airflow/.local/lib/python3.12/site-packages/airflow/utils/email.py", line 317, in _get_smtp_connection
    return smtplib.SMTP(host=host, port=port, timeout=timeout)
           ^^^^^^^^^^^^^^^^^^^^^^^^^^^^^^^^^^^^^^^^^^^^^^^^^^^
  File "/usr/local/lib/python3.12/smtplib.py", line 255, in __init__
    (code, msg) = self.connect(host, port)
                  ^^^^^^^^^^^^^^^^^^^^^^^^
  File "/usr/local/lib/python3.12/smtplib.py", line 341, in connect
    self.sock = self._get_socket(host, port, self.timeout)
                ^^^^^^^^^^^^^^^^^^^^^^^^^^^^^^^^^^^^^^^^^^
  File "/usr/local/lib/python3.12/smtplib.py", line 312, in _get_socket
    return socket.create_connection((host, port), timeout,
           ^^^^^^^^^^^^^^^^^^^^^^^^^^^^^^^^^^^^^^^^^^^^^^^
  File "/usr/local/lib/python3.12/socket.py", line 852, in create_connection
    raise exceptions[0]
  File "/usr/local/lib/python3.12/socket.py", line 837, in create_connection
    sock.connect(sa)
ConnectionRefusedError: [Errno 111] Connection refused

During handling of the above exception, another exception occurred:

Traceback (most recent call last):
  File "/home/airflow/.local/lib/python3.12/site-packages/airflow/models/taskinstance.py", line 877, in _handle_failure
    task_instance.email_alert(error, failure_context["task"])
  File "/home/airflow/.local/lib/python3.12/site-packages/airflow/models/taskinstance.py", line 3163, in email_alert
    _email_alert(task_instance=self, exception=exception, task=task)
  File "/home/airflow/.local/lib/python3.12/site-packages/airflow/models/taskinstance.py", line 1065, in _email_alert
    send_email(task.email, subject, html_content_err)
  File "/home/airflow/.local/lib/python3.12/site-packages/airflow/utils/email.py", line 80, in send_email
    return backend(
           ^^^^^^^^
  File "/home/airflow/.local/lib/python3.12/site-packages/airflow/utils/email.py", line 154, in send_email_smtp
    send_mime_email(e_from=mail_from, e_to=recipients, mime_msg=msg, conn_id=conn_id, dryrun=dryrun)
  File "/home/airflow/.local/lib/python3.12/site-packages/airflow/utils/email.py", line 273, in send_mime_email
    smtp_conn = _get_smtp_connection(smtp_host, smtp_port, smtp_timeout, smtp_ssl)
                ^^^^^^^^^^^^^^^^^^^^^^^^^^^^^^^^^^^^^^^^^^^^^^^^^^^^^^^^^^^^^^^^^^
  File "/home/airflow/.local/lib/python3.12/site-packages/airflow/utils/email.py", line 317, in _get_smtp_connection
    return smtplib.SMTP(host=host, port=port, timeout=timeout)
           ^^^^^^^^^^^^^^^^^^^^^^^^^^^^^^^^^^^^^^^^^^^^^^^^^^^
  File "/usr/local/lib/python3.12/smtplib.py", line 255, in __init__
    (code, msg) = self.connect(host, port)
                  ^^^^^^^^^^^^^^^^^^^^^^^^
  File "/usr/local/lib/python3.12/smtplib.py", line 341, in connect
    self.sock = self._get_socket(host, port, self.timeout)
                ^^^^^^^^^^^^^^^^^^^^^^^^^^^^^^^^^^^^^^^^^^
  File "/usr/local/lib/python3.12/smtplib.py", line 312, in _get_socket
    return socket.create_connection((host, port), timeout,
           ^^^^^^^^^^^^^^^^^^^^^^^^^^^^^^^^^^^^^^^^^^^^^^^
  File "/usr/local/lib/python3.12/socket.py", line 852, in create_connection
    raise exceptions[0]
  File "/usr/local/lib/python3.12/socket.py", line 837, in create_connection
    sock.connect(sa)
ConnectionRefusedError: [Errno 111] Connection refused
[2024-07-27T16:43:06.401+0000] {standard_task_runner.py:110} ERROR - Failed to execute job 398 for task crawl_match_incident (tuple indices must be integers or slices, not str; 3035)
[2024-07-27T16:43:06.440+0000] {local_task_job_runner.py:240} INFO - Task exited with return code 1
[2024-07-27T16:43:06.792+0000] {taskinstance.py:3498} INFO - 0 downstream tasks scheduled from follow-on schedule check
[2024-07-27T16:43:06.799+0000] {local_task_job_runner.py:222} INFO - ::endgroup::
